Workbook

Sheet 預測IC
A1: NN1
B2: Time | C2: 2013/12 | D2: 2014/01 | E2: 2014/02 | F2: 2014/03 | G2: 2014/04 | H2: 2014/05 | I2: 2014/06 | J2: 2014/07 | K2: 2014/08 | L2: 2014/09 | M2: 2014/10 | N2: 2014/11 | O2: 2014/12 | P2: 2015/01 | Q2: 2015/02 | R2: 2015/03 | S2: 2015/04 | T2: 2015/05 | U2: 2015/06 | V2: 2015/07 | W2: 2015/08 | X2: 2015/09 | Y2: 2015/10 | Z2: 2015/11 | AA2: 2015/12 | AB2: 2016/01 | AC2: 2016/02 | AD2: 2016/03 | AE2: 2016/04 | AF2: 2016/05 | AG2: 2016/06 | AH2: 2016/07 | AI2: 2016/08 | AJ2: 2016/09 | AK2: 2016/10 | AL2: 2016/11 | AM2: 2016/12 | AN2: 2017/01 | AO2: 2017/02 | AP2: 2017/03 | AQ2: 2017/04 | AR2: 2017/05 | AS2: 2017/06 | AT2: 2017/07 | AU2: 2017/08 | AV2: 2017/09 | AW2: 2017/10 | AX2: 2017/11 | AY2: 2017/12 | AZ2: 2018/01 | BA2: 2018/02 | BB2: 2018/03 | BC2: 2018/04 | BD2: 2018/05 | BE2: 2018/06 | BF2: 2018/07 | BG2: 2018/08 | BH2: 2018/09 | BI2: 2018/10 | BJ2: 2018/11 | BK2: 2018/12 | BL2: 2019/01 | BM2: 2019/02 | BN2: 2019/03 | BO2: 2019/04 | BP2: 2019/05 | BQ2: 2019/06 | BR2: 2019/07 | BS2: 2019/08 | BT2: 2019/09 | BU2: 2019/10 | BV2: 2019/11 | BW2: 2019/12 | BX2: 2020/01 | BY2: 2020/02 | BZ2: 2020/03 | CA2: 2020/04 | CB2: 2020/05 | CC2: 2020/06 | CD2: 2020/07 | CE2: 2020/08 | CF2: 2020/09 | CG2: 2020/10 | CH2: 2020/11 | CI2: 2020/12 | CJ2: 2021/01 | CK2: 2021/02 | CL2: 2021/03 | CM2: 2021/04 | CN2: 2021/05 | CO2: 2021/06 | CP2: 2021/07 | CQ2: 2021/08 | CR2: 2021/09 | CS2: 2021/10 | CT2: 2021/11 | CU2: 2021/12 | CV2: 2022/01 | CW2: 2022/02 | CX2: 2022/03 | CY2: 2022/04 | CZ2: 2022/05 | DA2: 2022/06 | DB2: 2022/07 | DC2: 2022/08 | DD2: 2022/09 | DE2: 2022/10 | DF2: 2022/11 | DG2: 2022/12 | DH2: 2023/01 | DI2: 2023/02 | DJ2: 2023/03 | DK2: 2023/04 | DL2: 2023/05 | DM2: 2023/06 | DN2: 2023/07 | DO2: 2023/08 | DP2: 2023/09 | DQ2: 2023/10 | DR2: 2023/11 | DS2: 2023/12 | DT2: 2024/01 | DU2: 2024/02 | DV2: 2024/03 | DW2: 2024/04 | DX2: 2024/05 | DY2: 2024/06 | DZ2: 2024/07 | EA2: 2024/08 | EB2: 2024/09 | EC2: 2024/10 | ED2: 2024/11 | EE2: 2024/12 | EF2: 2025/01
B3: bm | C3: -0.091369018 | D3: -0.11085416 | E3: 0.0010956228 | F3: -0.13442956 | G3: -0.17466807 | H3: 0.0054118875 | I3: -0.035852931 | J3: -0.077711277 | K3: -0.014497202 | L3: -0.047656506 | M3: -0.057244118 | N3: 2.6820228e-05 | O3: -0.030116424 | P3: -0.040258028 | Q3: 0.0037178267 | R3: 0.02920155 | S3: 0.0077254642 | T3: -0.058597654 | U3: 0.00065108575 | V3: -0.10709821 | W3: -0.19089989 | X3: -0.071200095 | Y3: -0.10008328 | Z3: -0.049232095 | AA3: -0.020465598 | AB3: -0.069066942 | AC3: -0.05033315 | AD3: -0.019147269 | AE3: -0.010799496 | AF3: 0.010335859 | AG3: 0.0060158502 | AH3: -0.26610976 | AI3: -0.14365202 | AJ3: -0.2545194 | AK3: 0.028104119 | AL3: -0.051742584 | AM3: -0.082977191 | AN3: -0.07035096 | AO3: -0.19681084 | AP3: -0.25679255 | AQ3: -0.059776843 | AR3: -0.041728809 | AS3: -0.08194682 | AT3: -0.13346004 | AU3: 0.0036019981 | AV3: 0.0079997703 | AW3: 0.0024315715 | AX3: 0.01277367 | AY3: 0.0027071089 | AZ3: 0.014640374 | BA3: 0.036530185 | BB3: 0.033319384 | BC3: 0.011332087 | BD3: -0.00077839196 | BE3: -0.017046392 | BF3: -0.028747007 | BG3: -0.0037359297 | BH3: 0.030615002 | BI3: -0.0013157427 | BJ3: -0.065720931 | BK3: -0.040063486 | BL3: -0.08897166 | BM3: -0.021720856 | BN3: -0.068609193 | BO3: -0.055181742 | BP3: -0.085352331 | BQ3: -0.036593899 | BR3: 0.035782557 | BS3: 0.033818975 | BT3: 0.037881386 | BU3: 0.033238206 | BV3: 0.046295919 | BW3: 0.035180662 | BX3: 0.02476749 | BY3: 0.033294946 | BZ3: 0.052433897 | CA3: 0.0048576407 | CB3: 0.037053939 | CC3: 0.026344806 | CD3: 0.036022436 | CE3: 0.026176233 | CF3: 0.018041616 | CG3: 0.014337597 | CH3: 0.010813093 | CI3: 0.0093775922 | CJ3: 0.03141886 | CK3: 0.029902643 | CL3: 0.028130077 | CM3: 0.017964363 | CN3: 0.0068069855 | CO3: 0.042052153 | CP3: 0.033009041 | CQ3: 0.023710907 | CR3: 0.026173286 | CS3: 0.019619772 | CT3: 0.014876774 | CU3: 0.040978026 | CV3: 0.0395329 | CW3: 0.024221046 | CX3: 0.042955689 | CY3: 0.028871555 | CZ3: 0.047397841 | DA3: 0.028573086 | DB3: 0.025090832 | DC3: 0.020950638 | DD3: 0.020789521 | DE3: 0.033207852 | DF3: 0.029750263 | DG3: 0.019087659 | DH3: 0.023787431 | DI3: 0.019194495 | DJ3: 0.035664935 | DK3: 0.037067931 | DL3: 0.024737032 | DM3: 0.031437267 | DN3: 0.025900939 | DO3: 0.022398051 | DP3: 0.019147078 | DQ3: 0.024746008 | DR3: 0.038861591 | DS3: 0.029537344 | DT3: 0.036585744 | DU3: 0.010436187 | DV3: 0.013549604 | DW3: 0.030600432 | DX3: 0.030763229 | DY3: 0.026879475 | DZ3: 0.038272426 | EA3: 0.037800625 | EB3: 0.0092485007 | EC3: 0.010824578 | ED3: 0.031915292 | EE3: 0.019924693 | EF3: 0.036655359
B4: size | C4: 0.045735888 | D4: 0.14219648 | E4: 0.12357825 | F4: 0.10848226 | G4: 0.095342577 | H4: 0.090842672 | I4: 0.07617455 | J4: 0.059771746 | K4: 0.06868922 | L4: 0.060447685 | M4: 0.027975643 | N4: 0.0097275795 | O4: 0.0093574636 | P4: -0.0017969056 | Q4: -0.0025195966 | R4: -0.003085715 | S4: -0.0031058353 | T4: -0.0042619519 | U4: -0.0093749613 | V4: -0.011537377 | W4: -0.011927816 | X4: -0.012192427 | Y4: -0.015751872 | Z4: -0.017309032 | AA4: -0.01748802 | AB4: -0.018466573 | AC4: -0.018643722 | AD4: -0.01895369 | AE4: -0.019215077 | AF4: -0.020113235 | AG4: -0.020260951 | AH4: -0.020400111 | AI4: -0.022575289 | AJ4: -0.022869756 | AK4: -0.023673112 | AL4: -0.050100833 | AM4: -0.029040024 | AN4: -0.029105987 | AO4: -0.030611878 | AP4: -0.030782696 | AQ4: -0.027796578 | AR4: -0.027182344 | AS4: -0.024847416 | AT4: -0.025312619 | AU4: -0.02542959 | AV4: -0.025587805 | AW4: -0.025955684 | AX4: -0.026252424 | AY4: -0.033910792 | AZ4: -0.028038723 | BA4: -0.027945993 | BB4: -0.032719225 | BC4: -0.032609779 | BD4: -0.03206097 | BE4: -0.032296058 | BF4: -0.032346584 | BG4: -0.032194518 | BH4: -0.019704346 | BI4: -0.027803266 | BJ4: -0.028010786 | BK4: -0.030229433 | BL4: -0.029914387 | BM4: -0.031547844 | BN4: -0.038578428 | BO4: -0.029772218 | BP4: -0.036932468 | BQ4: -0.03365827 | BR4: -0.011724529 | BS4: -0.015890749 | BT4: -0.020781642 | BU4: -0.020965751 | BV4: -0.017983368 | BW4: -0.022088327 | BX4: -0.030406095 | BY4: -0.03080483 | BZ4: -0.030603508 | CA4: -0.030999789 | CB4: -0.026412753 | CC4: -0.028904116 | CD4: -0.028219866 | CE4: -0.028157502 | CF4: -0.030116478 | CG4: -0.030005787 | CH4: -0.030040558 | CI4: -0.031394515 | CJ4: -0.031854711 | CK4: -0.031971924 | CL4: -0.035468247 | CM4: -0.031219956 | CN4: -0.035869151 | CO4: -0.031749379 | CP4: -0.031618152 | CQ4: -0.027020266 | CR4: -0.025449879 | CS4: -0.029090226 | CT4: -0.025807582 | CU4: -0.026407244 | CV4: -0.02782541 | CW4: -0.034329791 | CX4: -0.027993789 | CY4: -0.026280265 | CZ4: -0.027791232 | DA4: -0.029591462 | DB4: -0.034101341 | DC4: -0.03484321 | DD4: -0.032262605 | DE4: -0.028815899 | DF4: -0.02832257 | DG4: -0.026369631 | DH4: -0.031315241 | DI4: -0.029898226 | DJ4: -0.029556438 | DK4: -0.028653093 | DL4: -0.02926722 | DM4: -0.029532833 | DN4: -0.031904288 | DO4: -0.027400294 | DP4: -0.033020105 | DQ4: -0.026945302 | DR4: -0.028060446 | DS4: -0.027914209 | DT4: -0.027555149 | DU4: -0.025405545 | DV4: -0.026828792 | DW4: -0.037095267 | DX4: -0.027448662 | DY4: -0.031317905 | DZ4: -0.0242904 | EA4: -0.083518818 | EB4: -0.077344619 | EC4: -0.070242889 | ED4: -0.063896284 | EE4: -0.097872823 | EF4: -0.07682889
B5: mom | C5: 0.50836325 | D5: 0.76913774 | E5: 0.54195535 | F5: 1.1543282 | G5: 0.54750556 | H5: 0.91896617 | I5: 0.66497213 | J5: 0.96098614 | K5: 1.0693189 | L5: 0.58301491 | M5: 0.48336148 | N5: 0.43350995 | O5: 0.063416295 | P5: 0.033898823 | Q5: -0.63935673 | R5: -0.050250471 | S5: 0.066091195 | T5: -0.060526483 | U5: -0.05088184 | V5: 0.12953432 | W5: 0.1782714 | X5: 0.22364642 | Y5: 0.26079547 | Z5: 0.17032516 | AA5: 0.14871091 | AB5: 0.13639477 | AC5: 0.10649753 | AD5: 0.10512894 | AE5: 0.098157518 | AF5: 0.080513276 | AG5: 0.058855694 | AH5: 0.030879952 | AI5: -0.01261719 | AJ5: 0.041990966 | AK5: 0.075650394 | AL5: 0.066236444 | AM5: 0.032869942 | AN5: 0.036517307 | AO5: 0.068531297 | AP5: 0.065215103 | AQ5: 0.14007755 | AR5: 0.16342324 | AS5: 0.18792152 | AT5: 0.19995156 | AU5: 0.19402838 | AV5: 0.15869357 | AW5: -0.035683066 | AX5: 0.03622634 | AY5: 0.11327735 | AZ5: 0.10470727 | BA5: 0.068495058 | BB5: -0.0073811114 | BC5: -0.037875481 | BD5: -0.023798844 | BE5: 0.001822005 | BF5: -0.023551453 | BG5: 0.00052555325 | BH5: 0.059344802 | BI5: 0.01402873 | BJ5: 0.0082117841 | BK5: 0.05560239 | BL5: -0.031602059 | BM5: 0.065659098 | BN5: -0.050475221 | BO5: -0.054688156 | BP5: -0.0030284571 | BQ5: 0.0079566333 | BR5: -0.027654411 | BS5: -0.0060201874 | BT5: 0.043329164 | BU5: 0.048520129 | BV5: 0.1427042 | BW5: 0.13052307 | BX5: 0.05240079 | BY5: 0.060546339 | BZ5: 0.0057873824 | CA5: -0.029747102 | CB5: -0.039389633 | CC5: 0.013708961 | CD5: 0.01496346 | CE5: 0.019200653 | CF5: 0.043813094 | CG5: 0.03011325 | CH5: 0.043025322 | CI5: 0.029372282 | CJ5: 0.041782275 | CK5: 0.03730081 | CL5: 0.060941599 | CM5: -0.038412053 | CN5: 0.023074511 | CO5: 0.15895571 | CP5: -0.036965128 | CQ5: 0.069797367 | CR5: -0.033767849 | CS5: 0.026915153 | CT5: 0.053638488 | CU5: 0.063532986 | CV5: 0.055906884 | CW5: 0.048717335 | CX5: 0.03190903 | CY5: 0.029662585 | CZ5: 0.036755949 | DA5: 0.026317593 | DB5: 0.02768035 | DC5: 0.037085291 | DD5: 0.019733299 | DE5: 0.041370407 | DF5: 0.040565908 | DG5: 0.033224057 | DH5: 0.024580572 | DI5: -0.028816845 | DJ5: 0.029332105 | DK5: 0.03270904 | DL5: 0.035447288 | DM5: 0.049034216 | DN5: -0.11219849 | DO5: 0.053319719 | DP5: 0.053090192 | DQ5: 0.067249388 | DR5: 0.038297854 | DS5: 0.045268748 | DT5: 0.0085754991 | DU5: 0.0015342087 | DV5: 0.038169108 | DW5: 0.030193541 | DX5: 0.034144994 | DY5: 0.054498199 | DZ5: 0.043653317 | EA5: 0.021745306 | EB5: 0.0062471032 | EC5: 0.021422952 | ED5: 0.017024625 | EE5: 0.053500138 | EF5: 0.057897598
A6: 選絕對值最大 | C6: {=MATCH(MAX(ABS(C3:C5)),ABS(C3:C5),0)} -> 3 | D6: {=MATCH(MAX(ABS(D3:D5)),ABS(D3:D5),0)} -> 3 | E6: {=MATCH(MAX(ABS(E3:E5)),ABS(E3:E5),0)} -> 3 | F6: {=MATCH(MAX(ABS(F3:F5)),ABS(F3:F5),0)} -> 3 | G6: {=MATCH(MAX(ABS(G3:G5)),ABS(G3:G5),0)} -> 3 | H6: {=MATCH(MAX(ABS(H3:H5)),ABS(H3:H5),0)} -> 3 | I6: {=MATCH(MAX(ABS(I3:I5)),ABS(I3:I5),0)} -> 3 | J6: {=MATCH(MAX(ABS(J3:J5)),ABS(J3:J5),0)} -> 3 | ... EF6: {=MATCH(MAX(ABS(EF3:EF5)),ABS(EF3:EF5),0)} -> 2
C7: =IF(C6=1,"bm",IF(C6=2,"size",IF(C6=3,"mom"))) -> mom | D7: =IF(D6=1,"bm",IF(D6=2,"size",IF(D6=3,"mom"))) -> mom | E7: =IF(E6=1,"bm",IF(E6=2,"size",IF(E6=3,"mom"))) -> mom | F7: =IF(F6=1,"bm",IF(F6=2,"size",IF(F6=3,"mom"))) -> mom | G7: =IF(G6=1,"bm",IF(G6=2,"size",IF(G6=3,"mom"))) -> mom | H7: =IF(H6=1,"bm",IF(H6=2,"size",IF(H6=3,"mom"))) -> mom | I7: =IF(I6=1,"bm",IF(I6=2,"size",IF(I6=3,"mom"))) -> mom | J7: =IF(J6=1,"bm",IF(J6=2,"size",IF(J6=3,"mom"))) -> mom | ... EF7: =IF(EF6=1,"bm",IF(EF6=2,"size",IF(EF6=3,"mom"))) -> size
C8: =IF(C6=1,C3,IF(C6=2,C4,IF(C6=3,C5))) -> 0.50836325 | D8: =IF(D6=1,D3,IF(D6=2,D4,IF(D6=3,D5))) -> 0.76913774 | E8: =IF(E6=1,E3,IF(E6=2,E4,IF(E6=3,E5))) -> 0.54195535 | F8: =IF(F6=1,F3,IF(F6=2,F4,IF(F6=3,F5))) -> 1.1543282 | G8: =IF(G6=1,G3,IF(G6=2,G4,IF(G6=3,G5))) -> 0.54750556 | H8: =IF(H6=1,H3,IF(H6=2,H4,IF(H6=3,H5))) -> 0.91896617 | I8: =IF(I6=1,I3,IF(I6=2,I4,IF(I6=3,I5))) -> 0.66497213 | J8: =IF(J6=1,J3,IF(J6=2,J4,IF(J6=3,J5))) -> 0.96098614 | ... EF8: =IF(EF6=1,EF3,IF(EF6=2,EF4,IF(EF6=3,EF5))) -> -0.07682889
A10: 投資組合 | C10: 公司數 | D10: 964
A11: 等分 | B11: 分數 | C11: 2014/01 | D11: 2014/02 | E11: 2014/03 | F11: 2014/04 | G11: 2014/05 | H11: 2014/06 | I11: 2014/07 | J11: 2014/08 | K11: 2014/09 | L11: 2014/10 | M11: 2014/11 | N11: 2014/12 | O11: 2015/01 | P11: 2015/02 | Q11: 2015/03 | R11: 2015/04 | S11: 2015/05 | T11: 2015/06 | U11: 2015/07 | V11: 2015/08 | W11: 2015/09 | X11: 2015/10 | Y11: 2015/11 | Z11: 2015/12 | AA11: 2016/01 | AB11: 2016/02 | AC11: 2016/03 | AD11: 2016/04 | AE11: 2016/05 | AF11: 2016/06 | AG11: 2016/07 | AH11: 2016/08 | AI11: 2016/09 | AJ11: 2016/10 | AK11: 2016/11 | AL11: 2016/12 | AM11: 2017/01 | AN11: 2017/02 | AO11: 2017/03 | AP11: 2017/04 | AQ11: 2017/05 | AR11: 2017/06 | AS11: 2017/07 | AT11: 2017/08 | AU11: 2017/09 | AV11: 2017/10 | AW11: 2017/11 | AX11: 2017/12 | AY11: 2018/01 | AZ11: 2018/02 | BA11: 2018/03 | BB11: 2018/04 | BC11: 2018/05 | BD11: 2018/06 | BE11: 2018/07 | BF11: 2018/08 | BG11: 2018/09 | BH11: 2018/10 | BI11: 2018/11 | BJ11: 2018/12 | BK11: 2019/01 | BL11: 2019/02 | BM11: 2019/03 | BN11: 2019/04 | BO11: 2019/05 | BP11: 2019/06 | BQ11: 2019/07 | BR11: 2019/08 | BS11: 2019/09 | BT11: 2019/10 | BU11: 2019/11 | BV11: 2019/12 | BW11: 2020/01 | BX11: 2020/02 | BY11: 2020/03 | BZ11: 2020/04 | CA11: 2020/05 | CB11: 2020/06 | CC11: 2020/07 | CD11: 2020/08 | CE11: 2020/09 | CF11: 2020/10 | CG11: 2020/11 | CH11: 2020/12 | CI11: 2021/01 | CJ11: 2021/02 | CK11: 2021/03 | CL11: 2021/04 | CM11: 2021/05 | CN11: 2021/06 | CO11: 2021/07 | CP11: 2021/08 | CQ11: 2021/09 | CR11: 2021/10 | CS11: 2021/11 | CT11: 2021/12 | CU11: 2022/01 | CV11: 2022/02 | CW11: 2022/03 | CX11: 2022/04 | CY11: 2022/05 | CZ11: 2022/06 | DA11: 2022/07 | DB11: 2022/08 | DC11: 2022/09 | DD11: 2022/10 | DE11: 2022/11 | DF11: 2022/12 | DG11: 2023/01 | DH11: 2023/02 | DI11: 2023/03 | DJ11: 2023/04 | DK11: 2023/05 | DL11: 2023/06 | DM11: 2023/07 | DN11: 2023/08 | DO11: 2023/09 | DP11: 2023/10 | DQ11: 2023/11 | DR11: 2023/12 | DS11: 2024/01 | DT11: 2024/02 | DU11: 2024/03 | DV11: 2024/04 | DW11: 2024/05 | DX11: 2024/06 | DY11: 2024/07 | DZ11: 2024/08 | EA11: 2024/09 | EB11: 2024/10 | EC11: 2024/11 | ED11: 2024/12 | EE11: 2025/01 | EF11: 2025/02
A12: 10 | B12: 96 | C12: -0.014499247 | D12: 0.014678551 | E12: -0.0013937245 | F12: -0.055959385 | G12: 0.031947449 | H12: 0.0095992584 | I12: -0.0086581523 | J12: 0.0073897937 | K12: 0.029187998 | L12: 0.008758556 | M12: 0.026889174 | N12: -0.034703354 | O12: 0.027914759 | P12: 0.021420421 | Q12: -0.0051156834 | R12: -0.013153489 | S12: 0.01105503 | T12: -0.047867716 | U12: 0.0013565231 | V12: 0.0095109537 | W12: -0.022278442 | X12: -0.10964075 | Y12: 0.020598394 | Z12: -0.053152087 | AA12: 0.026918479 | AB12: 0.01073333 | AC12: -0.046772946 | AD12: -0.0025304298 | AE12: 0.046437717 | AF12: -0.052012103 | AG12: -0.0038149304 | AH12: -0.013405805 | AI12: -0.019506051 | AJ12: -0.012983748 | AK12: -0.016475368 | AL12: -0.04780049 | AM12: -0.030086116 | AN12: -0.069233234 | AO12: -0.002228793 | AP12: 0.033718345 | AQ12: -0.0016969306 | AR12: 0.022223026 | AS12: 0.019976273 | AT12: 0.072195382 | AU12: 0.0037135364 | AV12: 0.053715631 | AW12: -0.017169705 | AX12: -0.044696012 | AY12: 0.017491322 | AZ12: -0.023614553 | BA12: -0.02643433 | BB12: 0.015274605 | BC12: -0.026690966 | BD12: 0.049233948 | BE12: -0.045598219 | BF12: -0.023600698 | BG12: 0.010003802 | BH12: -0.035079589 | BI12: 0.020838031 | BJ12: 0.00079599332 | BK12: -0.0006573835 | BL12: -0.024709246 | BM12: 0.050305685 | BN12: -0.011516536 | BO12: -0.02424631 | BP12: 0.010508985 | BQ12: -0.01389675 | BR12: -0.0022610085 | BS12: 0.018863293 | BT12: 0.016364783 | BU12: 0.016915017 | BV12: -0.042282389 | BW12: -0.044477004 | BX12: -0.0069851539 | BY12: 0.058929916 | BZ12: 0.045356946 | CA12: 0.014580583 | CB12: 0.027173863 | CC12: 0.065566042 | CD12: 0.11093363 | CE12: 0.15400716 | CF12: 0.0080212745 | CG12: -0.04927796 | CH12: -0.016463112 | CI12: -0.024341229 | CJ12: 0.054120067 | CK12: 0.056101441 | CL12: 0.07844028 | CM12: 0.026353951 | CN12: -0.02330725 | CO12: -0.024819785 | CP12: 0.001005022 | CQ12: -0.062684347 | CR12: 0.057159987 | CS12: -0.014509312 | CT12: -0.0093290632 | CU12: -0.074779529 | CV12: 0.065033306 | CW12: 0.013036669 | CX12: 0.060989883 | CY12: 0.016420596 | CZ12: 0.077792327 | DA12: 0.036978521 | DB12: 0.088981854 | DC12: -0.0045013638 | DD12: -0.039091417 | DE12: -0.024737644 | DF12: 0.01162432 | DG12: -0.047394422 | DH12: 0.061195427 | DI12: 0.05974901 | DJ12: 0.0080625983 | DK12: -0.015945953 | DL12: 0.018669833 | DM12: 0.0091434933 | DN12: 0.018541443 | DO12: -0.019030728 | DP12: -0.059408695 | DQ12: 0.074540647 | DR12: 0.018778943 | DS12: 0.046024279 | DT12: -0.045297883 | DU12: -0.057230229 | DV12: -0.016751442 | DW12: 0.044967552 | DX12: 0.018099137 | DY12: 0.062728222 | DZ12: 0.02003889 | EA12: 0.051097698 | EB12: 0.0057861667 | EC12: -0.0098060417 | ED12: -0.00695775 | EE12: -0.026506688 | EF12: 0.029233396
A13: 20 | B13: 48 | C13: 0.0074773642 | D13: -0.00545686 | E13: -0.0055236267 | F13: -0.059986527 | G13: 0.012047404 | H13: 0.017388387 | I13: 0.032285992 | J13: 0.023000409 | K13: 0.060326139 | L13: 0.02198047 | M13: 0.0032797582 | N13: -0.043392417 | O13: 0.017422699 | P13: 0.020856913 | Q13: 0.017456384 | R13: -0.016510711 | S13: -0.006013803 | T13: -0.074234082 | U13: -0.028761331 | V13: 0.0022166399 | W13: -0.031103088 | X13: -0.12112777 | Y13: -0.0066833587 | Z13: -0.081251402 | AA13: 0.047712648 | AB13: 0.015001573 | AC13: -0.0667717 | AD13: -0.020440228 | AE13: 0.077071417 | AF13: -0.073281161 | AG13: 0.0099052077 | AH13: -0.0096413392 | AI13: -0.01206755 | AJ13: 0.01628047 | AK13: -0.03835939 | AL13: -0.049258885 | AM13: -0.046282444 | AN13: -0.10533024 | AO13: -0.0093111879 | AP13: 0.05955084 | AQ13: -0.0023400742 | AR13: 0.020848044 | AS13: 0.023404964 | AT13: 0.086422915 | AU13: -0.015695418 | AV13: 0.079665976 | AW13: -0.026821238 | AX13: -0.032799832 | AY13: 0.014262204 | AZ13: -0.031220536 | BA13: -0.026188274 | BB13: 0.042875374 | BC13: -0.019110867 | BD13: 0.041676729 | BE13: -0.046048625 | BF13: -0.026302542 | BG13: 0.0083309167 | BH13: -0.041023656 | BI13: 0.025832708 | BJ13: 0.016847086 | BK13: -0.0088783959 | BL13: -0.03194786 | BM13: 0.053371769 | BN13: -0.011052542 | BO13: -0.030878716 | BP13: -0.0094326957 | BQ13: -0.041653064 | BR13: -0.0066814175 | BS13: 0.0074194718 | BT13: 0.00052107168 | BU13: 0.015527166 | BV13: -0.079930834 | BW13: -0.075714006 | BX13: -0.00074563881 | BY13: 0.039201957 | BZ13: 0.076138123 | CA13: 0.024012188 | CB13: 0.02601738 | CC13: 0.12011792 | CD13: 0.10508583 | CE13: 0.18382773 | CF13: -0.012043667 | CG13: -0.058014968 | CH13: -0.0040295061 | CI13: -0.0078951667 | CJ13: 0.054810181 | CK13: 0.065687126 | CL13: 0.072724175 | CM13: 0.014010735 | CN13: -0.030130667 | CO13: -0.035334344 | CP13: -0.020576996 | CQ13: -0.071178865 | CR13: 0.11164489 | CS13: 0.0039479583 | CT13: 0.00040854012 | CU13: -0.10709096 | CV13: 0.077656051 | CW13: 0.03630912 | CX13: 0.060033255 | CY13: 0.041201752 | CZ13: 0.05722422 | DA13: 0.049445771 | DB13: 0.10623525 | DC13: -0.014149867 | DD13: -0.051406292 | DE13: -0.022441996 | DF13: 0.017271632 | DG13: -0.07133576 | DH13: 0.088720708 | DI13: 0.089748125 | DJ13: -0.0033317562 | DK13: 0.012409074 | DL13: 0.022050691 | DM13: -0.011655894 | DN13: 0.012775889 | DO13: -0.044325139 | DP13: -0.058032309 | DQ13: 0.087129011 | DR13: 0.013771209 | DS13: 0.029915194 | DT13: -0.035426301 | DU13: -0.033005958 | DV13: -0.0098528048 | DW13: 0.042028479 | DX13: 0.02322961 | DY13: 0.0095046248 | DZ13: 0.030285251 | EA13: 0.062118417 | EB13: 0.00020102083 | EC13: -0.018775021 | ED13: 0.0070839792 | EE13: -0.041234375 | EF13: 0.044513042
A14: 50 | B14: 19 | C14: 0.033228978 | D14: -0.14164365 | E14: -0.047920746 | F14: -0.060341905 | G14: 0.05365663 | H14: -0.011508261 | I14: 0.030100135 | J14: 0.045231574 | K14: 0.050827466 | L14: 0.056271085 | M14: -0.019021714 | N14: -0.057369427 | O14: 0.0014944079 | P14: 0.058345922 | Q14: 0.079297658 | R14: 0.017762309 | S14: -0.024806746 | T14: -0.035019555 | U14: -0.030556169 | V14: -0.0524213 | W14: -0.074008159 | X14: -0.1866857 | Y14: -0.055190991 | Z14: -0.11670403 | AA14: 0.099905879 | AB14: 0.027335979 | AC14: 0.0030865623 | AD14: -0.069874592 | AE14: 0.11683692 | AF14: -0.096080095 | AG14: 0.025329295 | AH14: -0.0052502779 | AI14: -0.072072951 | AJ14: -0.015059036 | AK14: -0.077475339 | AL14: -0.051230183 | AM14: -0.061242166 | AN14: -0.098594667 | AO14: -0.060905705 | AP14: 0.069976525 | AQ14: 0.02973338 | AR14: 0.0075826917 | AS14: -0.0066693384 | AT14: 0.07940348 | AU14: -0.057421613 | AV14: 0.066258749 | AW14: -0.053928681 | AX14: -0.019370213 | AY14: 0.0016905718 | AZ14: -0.06107058 | BA14: -0.066889832 | BB14: 0.061734282 | BC14: 0.028505683 | BD14: 0.016418895 | BE14: -0.024118105 | BF14: -0.0052420526 | BG14: 0.010496842 | BH14: -0.073413464 | BI14: 0.032270895 | BJ14: 0.020017224 | BK14: -0.03369142 | BL14: -0.059737767 | BM14: 0.046278325 | BN14: -0.020936538 | BO14: -0.033609046 | BP14: -0.015673733 | BQ14: -0.015843524 | BR14: -0.02792943 | BS14: -0.041493955 | BT14: -0.030726476 | BU14: 0.018002514 | BV14: -0.10798163 | BW14: -0.13089751 | BX14: 0.014335295 | BY14: -0.04260449 | BZ14: 0.060034057 | CA14: 0.033454632 | CB14: 0.05947706 | CC14: 0.12059521 | CD14: 0.09801671 | CE14: 0.17055484 | CF14: -0.04287741 | CG14: -0.057320664 | CH14: -0.04887967 | CI14: -0.0038281579 | CJ14: 0.017796116 | CK14: 0.053792087 | CL14: 0.13734357 | CM14: -0.0050971069 | CN14: -0.019401105 | CO14: -0.078763759 | CP14: -0.093659358 | CQ14: -0.0322279 | CR14: 0.20771971 | CS14: -0.0038151053 | CT14: -0.0096618863 | CU14: -0.101545 | CV14: 0.15139684 | CW14: 0.044763884 | CX14: 0.036299409 | CY14: 0.09636113 | CZ14: 0.064063563 | DA14: 0.065392579 | DB14: 0.10460805 | DC14: -0.042998542 | DD14: -0.053898895 | DE14: -0.062526924 | DF14: 0.064180408 | DG14: -0.087324806 | DH14: 0.058742579 | DI14: 0.086646789 | DJ14: 0.0010237243 | DK14: 0.019071063 | DL14: 0.040754872 | DM14: -0.032421917 | DN14: -0.044935741 | DO14: -0.070288549 | DP14: -0.062914808 | DQ14: 0.071172565 | DR14: 0.052622519 | DS14: 0.089437754 | DT14: -0.044516954 | DU14: -0.068796263 | DV14: -0.045153224 | DW14: 0.0018098947 | DX14: 0.027689697 | DY14: 0.047660987 | DZ14: 0.021697589 | EA14: 0.10752553 | EB14: -0.025110526 | EC14: -0.019289632 | ED14: -0.033598368 | EE14: 0.0033992632 | EF14: 0.025524211
A15: 100 | B15: 10 | C15: 0.036350225 | D15: -0.27303487 | E15: -0.095344605 | F15: 0.034921437 | G15: 0.034403921 | H15: -0.0012437261 | I15: 0.079293091 | J15: 0.06212121 | K15: 0.094514798 | L15: 0.081171061 | M15: -0.0021330164 | N15: -0.10979619 | O15: -0.012270796 | P15: 0.064116183 | Q15: 0.045898731 | R15: 0.12669106 | S15: 0.08548789 | T15: -0.045891077 | U15: -0.07819939 | V15: -0.11012701 | W15: -0.10254359 | X15: -0.21118633 | Y15: -0.052028798 | Z15: -0.062704119 | AA15: 0.16085038 | AB15: 0.022166401 | AC15: -0.0043176688 | AD15: -0.081713375 | AE15: 0.21179264 | AF15: -0.13772629 | AG15: 0.044324544 | AH15: 0.033604373 | AI15: -0.085430111 | AJ15: -0.00946486 | AK15: -0.069361451 | AL15: -0.032360174 | AM15: -0.055122622 | AN15: -0.10168871 | AO15: -0.063369812 | AP15: 0.078285694 | AQ15: 0.036453319 | AR15: 0.017733826 | AS15: -0.048733221 | AT15: 0.070989813 | AU15: -0.077174077 | AV15: 0.037297929 | AW15: -0.091727473 | AX15: -0.081360566 | AY15: 0.029005659 | AZ15: -0.067846329 | BA15: 0.015151738 | BB15: 0.11272487 | BC15: 0.030936692 | BD15: 0.0073647 | BE15: -0.0462183 | BF15: -0.0569776 | BG15: 0.0137764 | BH15: -0.098649046 | BI15: 0.0263518 | BJ15: 0.011265027 | BK15: 0.045604932 | BL15: -0.059403871 | BM15: 0.048219004 | BN15: -0.04014257 | BO15: -0.027734476 | BP15: -0.014184221 | BQ15: -0.012802931 | BR15: -0.050157429 | BS15: -0.016823777 | BT15: -0.059850936 | BU15: -0.015140082 | BV15: -0.10464004 | BW15: -0.29887899 | BX15: 0.053851569 | BY15: -0.12602357 | BZ15: 0.10290647 | CA15: 0.0299629 | CB15: 0.092684106 | CC15: 0.1736496 | CD15: 0.12015208 | CE15: 0.0733674 | CF15: -0.04134943 | CG15: -0.085886022 | CH15: -0.081342608 | CI15: -0.069335 | CJ15: 0.040671717 | CK15: 0.095640748 | CL15: 0.16165447 | CM15: -0.046626536 | CN15: 0.0002176 | CO15: -0.10697924 | CP15: -0.13009875 | CQ15: 0.02496336 | CR15: 0.18148893 | CS15: 0.0169124 | CT15: 0.0049416704 | CU15: -0.12404993 | CV15: 0.18261155 | CW15: 0.026072091 | CX15: 0.024039607 | CY15: 0.092947904 | CZ15: 0.079886948 | DA15: 0.0888618 | DB15: 0.0970477 | DC15: -0.067692432 | DD15: -0.0675251 | DE15: -0.057163635 | DF15: -0.0060545263 | DG15: -0.11309156 | DH15: 0.1296235 | DI15: 0.042811 | DJ15: -0.051853853 | DK15: 0.10177483 | DL15: -0.0003039932 | DM15: -0.039052117 | DN15: -0.081730712 | DO15: -0.034104416 | DP15: -0.13430495 | DQ15: 0.037038689 | DR15: 0.070010567 | DS15: 0.0095715425 | DT15: -0.072163632 | DU15: -0.1171285 | DV15: -0.046727729 | DW15: -0.0608268 | DX15: 0.02154567 | DY15: -0.083673635 | DZ15: 0.036596498 | EA15: 0.1091777 | EB15: -0.056129 | EC15: -0.0177838 | ED15: -0.0723837 | EE15: -0.0031902 | EF15: 0.0296441
A16: 107 | B16: 9 | C16: 0.03943539 | D16: -0.23433798 | E16: -0.086704171 | F16: 0.078715472 | G16: 0.0081465507 | H16: -0.00064934946 | I16: 0.10921796 | J16: 0.073104639 | K16: 0.086420892 | L16: 0.085161604 | M16: -0.013987436 | N16: -0.1202425 | O16: -0.028587077 | P16: 0.061045232 | Q16: 0.081478643 | R16: 0.10310969 | S16: 0.10985904 | T16: -0.038406673 | U16: -0.091471935 | V16: -0.075571486 | W16: -0.10166568 | X16: -0.24053196 | Y16: -0.050278834 | Z16: -0.043010058 | AA16: 0.16615889 | AB16: 0.032295414 | AC16: 0.012765448 | AD16: -0.053136056 | AE16: 0.20962824 | AF16: -0.14791561 | AG16: 0.04377616 | AH16: 0.0317654 | AI16: -0.049078043 | AJ16: 0.0070259661 | AK16: -0.037433453 | AL16: -0.0054397026 | AM16: -0.066076731 | AN16: -0.1064562 | AO16: -0.061424672 | AP16: 0.077798368 | AQ16: 0.054497753 | AR16: 0.034371979 | AS16: -0.052642718 | AT16: 0.12256404 | AU16: -0.082090272 | AV16: 0.052080835 | AW16: -0.10898494 | AX16: -0.10062133 | AY16: 0.019601854 | AZ16: -0.088150182 | BA16: -0.033911562 | BB16: 0.10803892 | BC16: 0.038999392 | BD16: 0.0062841111 | BE16: -0.044140333 | BF16: -0.054584333 | BG16: 0.019331222 | BH16: -0.096162035 | BI16: 0.025620889 | BJ16: 0.020503816 | BK16: 0.051371625 | BL16: -0.070623566 | BM16: 0.039497985 | BN16: -0.047905833 | BO16: -0.02189036 | BP16: -0.020843184 | BQ16: -0.016478016 | BR16: -0.026296848 | BS16: -0.013191573 | BT16: -0.046660882 | BU16: -0.015064578 | BV16: -0.036585638 | BW16: -0.31797083 | BX16: 0.066559519 | BY16: -0.13255841 | BZ16: 0.11152585 | CA16: 0.027431 | CB16: 0.11586555 | CC16: 0.044386333 | CD16: 0.15507127 | CE16: 0.093613778 | CF16: -0.052800084 | CG16: -0.061727878 | CH16: -0.050448725 | CI16: -0.058343333 | CJ16: 0.029703385 | CK16: 0.08842269 | CL16: 0.19674044 | CM16: -0.0069997267 | CN16: 0.0096095556 | CO16: -0.13464021 | CP16: -0.11115145 | CQ16: 0.02033378 | CR16: 0.18928653 | CS16: 0.021808222 | CT16: 0.025557378 | CU16: -0.1354717 | CV16: 0.17225152 | CW16: 0.047341659 | CX16: 0.012240285 | CY16: 0.081280638 | CZ16: 0.10263326 | DA16: 0.11818056 | DB16: 0.098016667 | DC16: -0.083264052 | DD16: -0.074370111 | DE16: -0.0345524 | DF16: -0.0026980136 | DG16: -0.12637192 | DH16: 0.13714944 | DI16: 0.047828778 | DJ16: -0.029141406 | DK16: 0.13359436 | DL16: -0.021872874 | DM16: -0.018910374 | DN16: -0.11588673 | DO16: -0.046563866 | DP16: -0.16033399 | DQ16: 0.047070156 | DR16: 0.055191252 | DS16: -0.010423024 | DT16: -0.10053413 | DU16: -0.122773 | DV16: -0.045728317 | DW16: -0.071303111 | DX16: 0.021947728 | DY16: -0.094984864 | DZ16: 0.012649172 | EA16: 0.13979989 | EB16: -0.070877778 | EC16: -0.024936444 | ED16: -0.080285222 | EE16: -0.0043961111 | EF16: 0.034548444
A17: 120 | B17: 8 | C17: 0.038913469 | D17: -0.16854736 | E17: -0.096671109 | F17: 0.080752164 | G17: 0.10538707 | H17: 0.0079428568 | I17: 0.11307752 | J17: 0.048286948 | K17: 0.10156008 | L17: 0.042234791 | M17: 0.014659142 | N17: -0.10927783 | O17: -0.011306676 | P17: 0.066339369 | Q17: 0.10026683 | R17: 0.13642645 | S17: 0.11905439 | T17: -0.023342586 | U17: -0.062405902 | V17: -0.097259656 | W17: -0.11960398 | X17: -0.23798943 | Y17: -0.073623131 | Z17: -0.048325674 | AA17: 0.19128344 | AB17: 0.044538303 | AC17: 0.020086255 | AD17: -0.049777375 | AE17: 0.2221227 | AF17: -0.12028632 | AG17: 0.062640142 | AH17: 0.035472619 | AI17: -0.030587709 | AJ17: 0.042602631 | AK17: -0.02937589 | AL17: -0.027018182 | AM17: -0.075369368 | AN17: -0.11328712 | AO17: -0.012632335 | AP17: 0.077242814 | AQ17: 0.061277252 | AR17: 0.045802626 | AS17: -0.058802957 | AT17: 0.12707179 | AU17: -0.11569961 | AV17: 0.058529449 | AW17: -0.07618961 | AX17: -0.097619105 | AY17: 0.015478046 | AZ17: -0.070494231 | BA17: -0.038771615 | BB17: 0.12376406 | BC17: 0.027292824 | BD17: 0.019414125 | BE17: -0.016298625 | BF17: -0.077417 | BG17: -0.01315375 | BH17: -0.13319111 | BI17: 0.05745075 | BJ17: 0.0098580643 | BK17: 0.016751327 | BL17: -0.077482967 | BM17: 0.029059011 | BN17: -0.046915526 | BO17: -0.035179615 | BP17: -0.03599598 | BQ17: -0.01137651 | BR17: -0.0096463751 | BS17: -0.0041034691 | BT17: -0.05265016 | BU17: -0.038510385 | BV17: -0.038240957 | BW17: -0.20833683 | BX17: 0.08264099 | BY17: -0.14247738 | BZ17: 0.12057816 | CA17: 0.027196125 | CB17: 0.10916584 | CC17: 0.0417585 | CD17: 0.17295974 | CE17: 0.095707625 | CF17: -0.058238797 | CG17: -0.074714989 | CH17: -0.032969072 | CI17: -0.08245125 | CJ17: 0.020950827 | CK17: 0.083955848 | CL17: 0.1368391 | CM17: 0.0016699729 | CN17: 0.01363075 | CO17: -0.13741288 | CP17: -0.10822138 | CQ17: -0.051907103 | CR17: 0.19640263 | CS17: 0.011546625 | CT17: 0.01733928 | CU17: -0.15535189 | CV17: 0.15147138 | CW17: 0.063393219 | CX17: 0.010772395 | CY17: 0.075608913 | CZ17: 0.12424884 | DA17: 0.094495625 | DB17: 0.104271 | DC17: -0.098849393 | DD17: -0.04813 | DE17: -0.024124863 | DF17: -0.015674445 | DG17: -0.12321247 | DH17: 0.16343337 | DI17: 0.07018125 | DJ17: -0.045336158 | DK17: 0.15603643 | DL17: -0.0039297317 | DM17: -0.037227476 | DN17: -0.10647996 | DO17: -0.065250544 | DP17: -0.14203416 | DQ17: 0.072654005 | DR17: 0.055884815 | DS17: -0.0065055362 | DT17: -0.09313895 | DU17: -0.129494 | DV17: -0.045148836 | DW17: -0.07659975 | DX17: -0.02303518 | DY17: -0.12601054 | DZ17: -0.0047910532 | EA17: 0.16457237 | EB17: -0.073783625 | EC17: -0.020359375 | ED17: -0.082855625 | EE17: 0.000194375 | EF17: 0.04098475
A18: 137 | B18: 7 | C18: 0.059146798 | D18: -0.18401889 | E18: -0.10047562 | F18: 0.11938296 | G18: 0.10831637 | H18: 0.0086222278 | I18: 0.12862656 | J18: 0.091173232 | K18: 0.13564789 | L18: 0.050758207 | M18: 0.029051464 | N18: -0.14120749 | O18: 0.031737941 | P18: 0.082552612 | Q18: 0.09305959 | R18: 0.15418919 | S18: 0.14380523 | T18: -0.052309698 | U18: -0.055150343 | V18: -0.12139146 | W18: -0.13791724 | X18: -0.21512106 | Y18: -0.10387924 | Z18: -0.051469726 | AA18: 0.17257066 | AB18: 0.062644805 | AC18: -0.0013654205 | AD18: -0.072443789 | AE18: 0.25839135 | AF18: -0.15054364 | AG18: 0.08171998 | AH18: 0.040197461 | AI18: -0.046855541 | AJ18: 0.047393756 | AK18: -0.022832885 | AL18: -0.032812812 | AM18: -0.066643405 | AN18: -0.07929464 | AO18: -0.005427535 | AP18: 0.078278592 | AQ18: 0.064154974 | AR18: 0.039002474 | AS18: -0.083253128 | AT18: 0.16638581 | AU18: -0.13889821 | AV18: 0.060235665 | AW18: -0.097766862 | AX18: -0.12606434 | AY18: 0.030189359 | AZ18: -0.051646327 | BA18: -0.03530224 | BB18: 0.13765604 | BC18: -0.027942051 | BD18: 0.020277714 | BE18: -0.022232286 | BF18: -0.038142 | BG18: -0.0023085714 | BH18: -0.13789827 | BI18: 0.033489571 | BJ18: -0.0059560641 | BK18: 0.0009810839 | BL18: -0.081157674 | BM18: 0.028081356 | BN18: -0.05277439 | BO18: -0.020227496 | BP18: -0.04685754 | BQ18: -0.0019167841 | BR18: -0.0057481936 | BS18: -0.0039836251 | BT18: -0.061545323 | BU18: 0.0089206671 | BV18: -0.039624426 | BW18: -0.2183755 | BX18: 0.074580863 | BY18: -0.087465268 | BZ18: 0.15331999 | CA18: 0.033285857 | CB18: 0.097387283 | CC18: 0.10465971 | CD18: 0.19371682 | CE18: 0.077259857 | CF18: 0.043957743 | CG18: -0.091609256 | CH18: -0.045365649 | CI18: -0.11772357 | CJ18: -0.0037723665 | CK18: 0.096058032 | CL18: 0.15291394 | CM18: 0.01554875 | CN18: -0.028616857 | CO18: -0.15059751 | CP18: -0.11627032 | CQ18: -0.038242676 | CR18: 0.19372241 | CS18: 0.028129286 | CT18: -0.016272494 | CU18: -0.14456482 | CV18: 0.12702227 | CW18: 0.066558574 | CX18: 0.061560186 | CY18: 0.093178384 | CZ18: 0.13284286 | DA18: 0.078357857 | DB18: 0.118114 | DC18: -0.082819707 | DD18: -0.071071286 | DE18: -0.038420587 | DF18: -0.028071975 | DG18: -0.11821709 | DH18: 0.19240257 | DI18: 0.097962857 | DJ18: -0.04520404 | DK18: 0.15851363 | DL18: -0.0038302741 | DM18: -0.0052506787 | DN18: -0.12510868 | DO18: -0.030199017 | DP18: -0.13348647 | DQ18: 0.065749458 | DR18: 0.076840655 | DS18: -0.025385651 | DT18: -0.11601739 | DU18: -0.15871543 | DV18: -0.070527693 | DW18: -0.068637857 | DX18: -0.068177294 | DY18: -0.1657631 | DZ18: -0.043227855 | EA18: 0.19894729 | EB18: -0.097045 | EC18: -0.019598857 | ED18: -0.080269714 | EE18: -0.0011102857 | EF18: 0.063951857
A19: 160 | B19: 6 | C19: 0.07386193 | D19: -0.21954287 | E19: -0.14058368 | F19: 0.17768866 | G19: 0.096065972 | H19: -0.012068788 | I19: 0.13411218 | J19: 0.11143724 | K19: 0.23878941 | L19: 0.02032665 | M19: -0.043690236 | N19: -0.15184358 | O19: 0.031561874 | P19: 0.092534186 | Q19: 0.081866113 | R19: 0.14558327 | S19: 0.12269188 | T19: -0.051464717 | U19: -0.067250002 | V19: -0.09268832 | W19: -0.14662099 | X19: -0.14939987 | Y19: -0.10313024 | Z19: -0.057888725 | AA19: 0.1318329 | AB19: 0.051718753 | AC19: -0.014141543 | AD19: -0.023997457 | AE19: 0.30849286 | AF19: -0.16883058 | AG19: 0.041487103 | AH19: 0.056557715 | AI19: -0.081770125 | AJ19: 0.05154529 | AK19: -0.040581523 | AL19: -0.014914608 | AM19: -0.043106012 | AN19: -0.083568294 | AO19: -0.025892903 | AP19: 0.08757412 | AQ19: 0.042375665 | AR19: -0.041144515 | AS19: -0.10919888 | AT19: 0.18459366 | AU19: -0.15301463 | AV19: -0.0030326096 | AW19: -0.1366934 | AX19: -0.2241238 | AY19: 0.066273243 | AZ19: -0.11561153 | BA19: -0.0015090166 | BB19: 0.1597462 | BC19: -0.18457179 | BD19: -7.0833333e-05 | BE19: -0.030392667 | BF19: -0.049435667 | BG19: 0.00096333333 | BH19: -0.14049691 | BI19: 0.0259385 | BJ19: -0.021707302 | BK19: -0.069519037 | BL19: -0.079964658 | BM19: 0.031786265 | BN19: -0.067252647 | BO19: -0.025728961 | BP19: -0.062818808 | BQ19: -0.0099340445 | BR19: 0.006675246 | BS19: -0.024256339 | BT19: -0.082323404 | BU19: 0.043246635 | BV19: -0.030350792 | BW19: -0.30745301 | BX19: 0.054830282 | BY19: -0.079866927 | BZ19: 0.068702125 | CA19: 0.035610167 | CB19: 0.078976808 | CC19: 0.022505667 | CD19: 0.2156192 | CE19: 0.088474167 | CF19: 0.079051525 | CG19: -0.057117625 | CH19: -0.042715044 | CI19: -0.16520067 | CJ19: -0.011811923 | CK19: 0.11879726 | CL19: 0.11534778 | CM19: 0.075581871 | CN19: -0.015943167 | CO19: -0.16614656 | CP19: -0.13741472 | CQ19: -0.032394608 | CR19: 0.17630672 | CS19: 0.043775667 | CT19: -0.027940637 | CU19: -0.14660754 | CV19: 0.094553008 | CW19: 0.060515879 | CX19: 0.057634726 | CY19: 0.10789212 | CZ19: 0.11285183 | DA19: 0.0751825 | DB19: 0.147961 | DC19: -0.065587585 | DD19: -0.063547333 | DE19: -0.033018415 | DF19: -0.021296342 | DG19: -0.1264908 | DH19: 0.22459133 | DI19: 0.10846167 | DJ19: -0.048514351 | DK19: 0.12414459 | DL19: -0.011982786 | DM19: 0.046097902 | DN19: -0.1739283 | DO19: -0.04870552 | DP19: -0.17026813 | DQ19: 0.080374172 | DR19: 0.075962353 | DS19: -0.044918963 | DT19: -0.1331285 | DU19: -0.1505825 | DV19: -0.071593387 | DW19: -0.101297 | DX19: -0.094614193 | DY19: -0.15211941 | DZ19: -0.079643568 | EA19: 0.23304767 | EB19: -0.1062485 | EC19: -0.031323667 | ED19: -0.0861595 | EE19: 0.0073063333 | EF19: 0.07402
A20: 192 | B20: 5 | C20: -0.011241332 | D20: -0.22258639 | E20: -0.14612491 | F20: 0.20553126 | G20: 0.11718314 | H20: 0.011583026 | I20: 0.18586318 | J20: 0.14728813 | K20: 0.2147245 | L20: 0.0089997713 | M20: -0.077718228 | N20: -0.16814359 | O20: 0.049864886 | P20: 0.091169928 | Q20: 0.10704532 | R20: 0.19094247 | S20: 0.082562611 | T20: -0.085465456 | U20: -0.013720365 | V20: -0.1035176 | W20: -0.17308538 | X20: -0.21038641 | Y20: -0.12896504 | Z20: -0.074027168 | AA20: 0.13048337 | AB20: 0.032898545 | AC20: -0.047248263 | AD20: -0.026987304 | AE20: 0.16122121 | AF20: -0.22349782 | AG20: 0.032163249 | AH20: 0.090178201 | AI20: -0.078154545 | AJ20: 0.061990035 | AK20: -0.0082485151 | AL20: -0.020780265 | AM20: -0.033095981 | AN20: -0.075470194 | AO20: -0.045285082 | AP20: 0.13173046 | AQ20: 0.033308231 | AR20: -0.029739 | AS20: -0.042291716 | AT20: 0.23912375 | AU20: -0.14307264 | AV20: -0.032246613 | AW20: -0.22499784 | AX20: -0.20433922 | AY20: -0.082057636 | AZ20: -0.15627401 | BA20: -0.10207757 | BB20: 0.16765542 | BC20: -0.24014067 | BD20: 0.0083636 | BE20: -0.0384684 | BF20: -0.0552158 | BG20: -0.051727 | BH20: -0.1500573 | BI20: 0.0231736 | BJ20: -0.021629512 | BK20: -0.10259828 | BL20: -0.086292231 | BM20: 0.047468551 | BN20: -0.11855724 | BO20: 0.038461718 | BP20: -0.060407521 | BQ20: -0.015451707 | BR20: 0.012073632 | BS20: 0.0054075062 | BT20: -0.096530501 | BU20: -0.040683597 | BV20: 0.081543442 | BW20: -0.35182955 | BX20: 0.057988018 | BY20: -0.0046393591 | BZ20: 0.090271404 | CA20: 0.0502162 | CB20: -0.0001077551 | CC20: 0.0129148 | CD20: 0.1810275 | CE20: 0.0857774 | CF20: 0.10578489 | CG20: -0.075970241 | CH20: -0.022195229 | CI20: -0.1314838 | CJ20: -0.041509985 | CK20: 0.080589624 | CL20: 0.14931315 | CM20: 0.079454727 | CN20: -0.0193474 | CO20: -0.2285182 | CP20: -0.15666076 | CQ20: -0.023118045 | CR20: 0.19548611 | CS20: 0.0222938 | CT20: -0.018076711 | CU20: -0.14672801 | CV20: 0.11921413 | CW20: 0.067903708 | CX20: 0.090298551 | CY20: 0.10096666 | CZ20: 0.15516165 | DA20: 0.0770816 | DB20: 0.076967 | DC20: -0.037332311 | DD20: -0.0681628 | DE20: -0.010418722 | DF20: -0.045499958 | DG20: -0.12407331 | DH20: 0.2782996 | DI20: 0.137596 | DJ20: -0.039459946 | DK20: 0.084953981 | DL20: -0.019465373 | DM20: -0.042864774 | DN20: -0.18323473 | DO20: -0.049820855 | DP20: -0.20015543 | DQ20: 0.057460182 | DR20: 0.07851266 | DS20: 0.069792758 | DT20: -0.13343598 | DU20: -0.1763758 | DV20: -0.10204218 | DW20: -0.1035466 | DX20: -0.097851218 | DY20: -0.18740183 | DZ20: 0.018115127 | EA20: 0.2936912 | EB20: -0.1063144 | EC20: 0.0229776 | ED20: -0.0746258 | EE20: 0.0017416 | EF20: 0.0858
A21: 241 | B21: 4 | C21: -0.010384834 | D21: -0.32500828 | E21: -0.043717555 | F21: 0.18403858 | G21: 0.14384215 | H21: -0.037844077 | I21: 0.23932306 | J21: 0.090566639 | K21: 0.20688003 | L21: 0.057226167 | M21: -0.099684593 | N21: -0.13905068 | O21: 0.034351989 | P21: 0.1447726 | Q21: 0.081195369 | R21: 0.14269209 | S21: 0.20915948 | T21: -0.098461673 | U21: 0.080215736 | V21: -0.10537077 | W21: -0.15778848 | X21: -0.21363094 | Y21: -0.092729224 | Z21: -0.1093802 | AA21: 0.11063591 | AB21: 0.021955944 | AC21: -0.018827737 | AD21: 0.025933276 | AE21: 0.12810498 | AF21: -0.29514426 | AG21: 0.011046572 | AH21: 0.10758136 | AI21: -0.079594209 | AJ21: 0.070405342 | AK21: 0.018318369 | AL21: -0.037391486 | AM21: -0.068535807 | AN21: -0.11195606 | AO21: -0.047726396 | AP21: 0.072535144 | AQ21: 0.037036188 | AR21: -0.034197901 | AS21: -0.045406682 | AT21: 0.26483826 | AU21: -0.06345533 | AV21: -0.068713913 | AW21: -0.26325492 | AX21: -0.2177183 | AY21: -0.065722295 | AZ21: -0.093059394 | BA21: -0.019293208 | BB21: 0.22534614 | BC21: -0.16446053 | BD21: 0.0382225 | BE21: -0.0405905 | BF21: -0.06228975 | BG21: -0.07852475 | BH21: -0.10684211 | BI21: 0.046277 | BJ21: -0.023579026 | BK21: -0.082973162 | BL21: -0.14272109 | BM21: 0.040795286 | BN21: -0.063647948 | BO21: 0.063857236 | BP21: -0.10450913 | BQ21: -0.054542231 | BR21: 0.012323862 | BS21: 0.0058601728 | BT21: -0.092952203 | BU21: 0.012996607 | BV21: 0.04433998 | BW21: -0.18446067 | BX21: 0.088379335 | BY21: -0.055666292 | BZ21: 0.047662929 | CA21: 0.09506 | CB21: 0.073466099 | CC21: -0.0080195 | CD21: 0.28805606 | CE21: 0.0615145 | CF21: 0.11452616 | CG21: -0.085085335 | CH21: -0.15662644 | CI21: -0.12329225 | CJ21: -0.055140849 | CK21: 0.06715963 | CL21: 0.18743312 | CM21: 0.062994333 | CN21: -0.01128025 | CO21: -0.23779198 | CP21: -0.098307306 | CQ21: -0.022912194 | CR21: 0.23905997 | CS21: 0.03090725 | CT21: -0.086072557 | CU21: -0.15891662 | CV21: 0.15433184 | CW21: 0.038345517 | CX21: 0.10212218 | CY21: 0.15245231 | CZ21: 0.23745137 | DA21: 0.04170975 | DB21: 0.0714595 | DC21: -0.1539048 | DD21: -0.067027 | DE21: -0.028977737 | DF21: -0.1488089 | DG21: -0.14818493 | DH21: 0.081437 | DI21: 0.17984 | DJ21: -0.037911313 | DK21: 0.13950271 | DL21: -0.012736992 | DM21: 0.004254564 | DN21: -0.22029564 | DO21: 0.018558809 | DP21: -0.22901989 | DQ21: 0.070422699 | DR21: 0.050170859 | DS21: 0.084605434 | DT21: -0.1705708 | DU21: -0.14861475 | DV21: -0.15489825 | DW21: -0.103536 | DX21: -0.11682889 | DY21: -0.22566188 | DZ21: 0.17989102 | EA21: 0.26605775 | EB21: -0.103298 | EC21: 0.0271895 | ED21: -0.08272975 | EE21: -0.02131 | EF21: 0.0287945
A22: 321 | B22: 3 | C22: -0.025922327 | D22: -0.41742192 | E22: -0.022230412 | F22: 0.067831061 | G22: 0.10388436 | H22: -0.22980554 | I22: 0.2544329 | J22: 0.11837828 | K22: 0.24536591 | L22: 0.10748717 | M22: -0.074100059 | N22: -0.098030861 | O22: -0.0067158783 | P22: 0.072782884 | Q22: 0.089282518 | R22: 0.18067973 | S22: 0.24705663 | T22: -0.12881242 | U22: 0.15202918 | V22: -0.057024135 | W22: -0.20748027 | X22: -0.22178676 | Y22: -0.047938332 | Z22: -0.15015011 | AA22: 0.082524426 | AB22: -0.0038652301 | AC22: -0.085776461 | AD22: 0.018593749 | AE22: 0.13082384 | AF22: -0.42991677 | AG22: 0.010812101 | AH22: 0.10586596 | AI22: -0.094141261 | AJ22: 0.031699849 | AK22: 0.078575769 | AL22: -0.0011447262 | AM22: -0.084088903 | AN22: -0.11113281 | AO22: -0.074717373 | AP22: 0.062536354 | AQ22: -0.055126721 | AR22: -0.1081837 | AS22: 0.073843703 | AT22: 0.017728371 | AU22: -0.1099146 | AV22: -0.089753982 | AW22: -0.37079928 | AX22: 0.009875186 | AY22: -0.098456276 | AZ22: -0.2274855 | BA22: -0.04917694 | BB22: 0.30192994 | BC22: -0.19562604 | BD22: 0.079264 | BE22: -0.068485667 | BF22: -0.054886 | BG22: -0.096179667 | BH22: -0.12770701 | BI22: 0.082349333 | BJ22: -0.054996415 | BK22: -0.020854755 | BL22: -0.16178034 | BM22: 0.0024304832 | BN22: 0.015327552 | BO22: 0.050484429 | BP22: -0.07483555 | BQ22: -0.027830097 | BR22: 0.020813609 | BS22: -0.016372782 | BT22: 0.067143215 | BU22: 0.040368469 | BV22: 0.048603535 | BW22: -0.13217179 | BX22: 0.15293737 | BY22: -0.05559705 | BZ22: 0.047257736 | CA22: 0.14408033 | CB22: 0.06360427 | CC22: -0.125105 | CD22: 0.33387804 | CE22: 0.06684 | CF22: 0.10077036 | CG22: -0.20708533 | CH22: -0.15360628 | CI22: -0.230448 | CJ22: -0.12632536 | CK22: 0.11092354 | CL22: 0.094997012 | CM22: 0.046441279 | CN22: 0.021851333 | CO22: -0.18528576 | CP22: -0.17184373 | CQ22: -0.017159616 | CR22: 0.24677277 | CS22: 0.024439333 | CT22: -0.12609138 | CU22: -0.16735391 | CV22: 0.16622268 | CW22: 0.022884042 | CX22: 0.0037495933 | CY22: 0.16243987 | CZ22: 0.26292048 | DA22: 0.032454 | DB22: 0.054040667 | DC22: -0.14116724 | DD22: -0.015963333 | DE22: 0.017756504 | DF22: -0.097071706 | DG22: -0.088121411 | DH22: 0.081455333 | DI22: 0.060122333 | DJ22: -0.050246006 | DK22: 0.17913471 | DL22: -0.0032133307 | DM22: 0.042676549 | DN22: -0.30537503 | DO22: -0.023768668 | DP22: -0.16956243 | DQ22: 0.16540417 | DR22: -0.0060925526 | DS22: 0.12952384 | DT22: -0.058357009 | DU22: -0.16154567 | DV22: -0.15706237 | DW22: -0.081416 | DX22: -0.16435212 | DY22: -0.31775437 | DZ22: 0.16562625 | EA22: 0.14035633 | EB22: -0.14293033 | EC22: 0.088086 | ED22: -0.057499333 | EE22: -0.047636 | EF22: 0.036592667
A23: 482 | B23: 2 | C23: -0.031325685 | D23: 0.088966623 | E23: -0.015061588 | F23: 0.18239608 | G23: -0.026971569 | H23: -0.26281024 | I23: 0.25570287 | J23: 0.15529382 | K23: 0.14260758 | L23: 0.23244436 | M23: -0.25844992 | N23: -0.12680001 | O23: -0.019407711 | P23: 0.090401711 | Q23: 0.25084968 | R23: 0.089628003 | S23: 0.169295 | T23: -0.15460269 | U23: 0.21298177 | V23: 0.063357011 | W23: -0.33161915 | X23: -0.18178119 | Y23: -0.0075887634 | Z23: -0.14764041 | AA23: -0.056748446 | AB23: -0.030991385 | AC23: -0.1687548 | AD23: 0.0029952916 | AE23: 0.13721199 | AF23: -0.32465933 | AG23: -0.14589389 | AH23: 0.084171585 | AI23: -0.023228267 | AJ23: -0.0056431378 | AK23: 0.091199224 | AL23: -0.051310311 | AM23: -0.007769489 | AN23: -0.2423147 | AO23: 0.0053369522 | AP23: -0.0031210994 | AQ23: 0.17571221 | AR23: -0.2534608 | AS23: 0.081663621 | AT23: 0.1095059 | AU23: -0.20359589 | AV23: -0.049150067 | AW23: -0.58225997 | AX23: 0.014812779 | AY23: -0.0581396 | AZ23: -0.31598452 | BA23: 0.17208091 | BB23: -0.051049484 | BC23: -0.25286918 | BD23: 0.1259795 | BE23: -0.0865335 | BF23: -0.060013 | BG23: -0.0449095 | BH23: -0.063365196 | BI23: 0.121209 | BJ23: -0.10400332 | BK23: -0.0050098635 | BL23: -0.1495343 | BM23: -0.069495462 | BN23: 0.0069471708 | BO23: -0.036524942 | BP23: -0.098266399 | BQ23: -0.072047901 | BR23: 0.017844321 | BS23: -0.073275389 | BT23: 0.070189264 | BU23: 0.16327469 | BV23: 0.053269051 | BW23: -0.015362515 | BX23: 0.12421952 | BY23: 0.11824923 | BZ23: 0.0076697624 | CA23: 0.2063755 | CB23: -0.041664988 | CC23: -0.084545 | CD23: 0.19167646 | CE23: 0.059602 | CF23: 0.016160835 | CG23: -0.21663724 | CH23: -0.16212257 | CI23: -0.0591225 | CJ23: -0.1565159 | CK23: 0.071856391 | CL23: 0.16404946 | CM23: 0.006975009 | CN23: 0.049972 | CO23: -0.26845098 | CP23: -0.24610177 | CQ23: 0.02470227 | CR23: 0.15099817 | CS23: 0.069015 | CT23: -0.032850224 | CU23: -0.20210388 | CV23: 0.15333097 | CW23: -0.024186288 | CX23: -0.088716994 | CY23: 0.28171083 | CZ23: 0.18199879 | DA23: 0.064645 | DB23: 0.018748 | DC23: -0.1579489 | DD23: -0.01841 | DE23: 0.060085948 | DF23: -0.19137387 | DG23: -0.15297665 | DH23: 0.139228 | DI23: 0.096041 | DJ23: -0.087058008 | DK23: 0.27783322 | DL23: 0.026242652 | DM23: -0.010710334 | DN23: -0.26497486 | DO23: 0.084670828 | DP23: -0.17683962 | DQ23: 0.24594611 | DR23: -0.089886003 | DS23: 0.24719455 | DT23: -0.12395522 | DU23: -0.055638 | DV23: -0.1927414 | DW23: 0.0230525 | DX23: -0.17100279 | DY23: -0.26822193 | DZ23: 0.12933302 | EA23: -0.028757 | EB23: -0.1382285 | EC23: 0.0936435 | ED23: 0.038898 | EE23: -0.069211 | EF23: 0.093414
A24: 964 | B24: 1 | C24: -0.027766967 | D24: 0.081988379 | E24: 0.081880335 | F24: 0.20154572 | G24: -0.022622389 | H24: -0.35082219 | I24: 0.24038624 | J24: 0.0040357249 | K24: 0.050444336 | L24: 0.33375944 | M24: -0.14681934 | N24: -0.10519171 | O24: 0.036648791 | P24: 0.10424841 | Q24: -0.090144949 | R24: 0.10836549 | S24: 0.1398838 | T24: 0.27048671 | U24: 0.39296188 | V24: 0.11654032 | W24: -0.49571199 | X24: 0.036157896 | Y24: -0.02939884 | Z24: -0.15040993 | AA24: 0.21854458 | AB24: -0.30039379 | AC24: -0.40174733 | AD24: 0.059922147 | AE24: 0.19314179 | AF24: -0.49538941 | AG24: -0.38005539 | AH24: 0.05669736 | AI24: 0.0088083311 | AJ24: 0.080891244 | AK24: 0.11317916 | AL24: -0.10745443 | AM24: 0.018919281 | AN24: -0.22118947 | AO24: -0.066090112 | AP24: 0.022851715 | AQ24: 0.35649193 | AR24: -0.020350844 | AS24: 0.0032867737 | AT24: 0.15076898 | AU24: -0.22984102 | AV24: 0.24768466 | AW24: 0.14871096 | AX24: -0.11149134 | AY24: -0.26743574 | AZ24: -0.60989956 | BA24: 0.10178269 | BB24: -0.086159033 | BC24: 0.0043668696 | BD24: 0.01864 | BE24: -0.104131 | BF24: -0.100236 | BG24: -0.176624 | BH24: -0.14767357 | BI24: 0.169268 | BJ24: -0.0033483158 | BK24: -0.010019727 | BL24: -0.31716429 | BM24: 0.08478294 | BN24: -0.0068493418 | BO24: 0.16110969 | BP24: -0.12335118 | BQ24: 0.064169633 | BR24: 0.042356223 | BS24: -0.0012847175 | BT24: 0.055799256 | BU24: 0.45156954 | BV24: 0.046258706 | BW24: -0.15102745 | BX24: 0.05804337 | BY24: 0.11840823 | BZ24: 0.2588929 | CA24: 0.100028 | CB24: 0.064127083 | CC24: -0.18247 | CD24: 0.14430631 | CE24: 0.165565 | CF24: -0.043964634 | CG24: -0.51996897 | CH24: -0.21297288 | CI24: -0.058508 | CJ24: -0.30018689 | CK24: 0.32305927 | CL24: 0.015683748 | CM24: 0.044688538 | CN24: 0.014921 | CO24: -0.57240961 | CP24: -0.19806735 | CQ24: 0.16018965 | CR24: 0.13778746 | CS24: -0.026858 | CT24: 0.18289659 | CU24: -0.052729045 | CV24: 0.18286409 | CW24: -0.23499322 | CX24: 0.055207194 | CY24: 0.36022805 | CZ24: 0.11220663 | DA24: 0.03398 | DB24: -0.0165 | DC24: -0.28272978 | DD24: 0.0493 | DE24: -0.13158559 | DF24: -0.19463806 | DG24: -0.24858898 | DH24: 0.265805 | DI24: 0.037185 | DJ24: -0.13248861 | DK24: 0.33950921 | DL24: 0.061360513 | DM24: -0.1083161 | DN24: -0.51684794 | DO24: 0.08311429 | DP24: -0.22357182 | DQ24: 0.3590713 | DR24: -0.02051563 | DS24: 0.14400697 | DT24: -0.038362866 | DU24: 0.021782 | DV24: -0.75045655 | DW24: 0.101183 | DX24: -0.17373733 | DY24: -0.032066536 | DZ24: -0.048904664 | EA24: -0.054917 | EB24: -0.109231 | EC24: 0.143647 | ED24: -0.069835 | EE24: -0.107482 | EF24: 0.134085
A26: 大盤 | B26: TWII | C26: -0.017446771 | D26: 0.020701061 | E26: 0.023982129 | F26: -0.006557579 | G26: 0.03184513 | H26: 0.034348533 | I26: -0.0082549328 | J26: 0.012843524 | K26: -0.051018525 | L26: 0.00087394274 | M26: 0.023389576 | N26: 0.012988972 | O26: 0.0058545887 | P26: 0.027413207 | Q26: -0.0037129361 | R26: 0.024076614 | S26: -0.012190025 | T26: -0.039749578 | U26: -0.07315545 | V26: -0.05826023 | W26: 0.00077279757 | X26: 0.044591521 | Y26: -0.02769968 | Z26: 0.0020950059 | AA26: -0.023400551 | AB26: 0.032129371 | AC26: 0.038903273 | AD26: -0.042865382 | AE26: 0.018647195 | AF26: 0.015229768 | AG26: 0.036016604 | AH26: 0.0093546114 | AI26: 0.010748251 | AJ26: 0.013357754 | AK26: -0.0053327473 | AL26: 0.0013831358 | AM26: 0.020795928 | AN26: 0.031517702 | AO26: 0.0062417165 | AP26: 0.0061452617 | AQ26: 0.016946358 | AR26: 0.03468283 | AS26: 0.0030985886 | AT26: 0.015081347 | AU26: -0.019251209 | AV26: 0.038711513 | AW26: -0.021856951 | AX26: 0.0077743007 | AY26: 0.042397247 | AZ26: -0.026308975 | BA26: 0.0095717493 | BB26: -0.024249741 | BC26: 0.020163374 | BD26: -0.0035049988 | BE26: 0.020151935 | BF26: 0.00058133623 | BG26: -0.005219701 | BH26: -0.11587176 | BI26: 0.0087252257 | BJ26: -0.016377261 | BK26: 0.020840372 | BL26: 0.044975872 | BM26: 0.023954306 | BN26: 0.030239101 | BO26: -0.043725888 | BP26: 0.02188947 | BQ26: 0.0086274303 | BR26: -0.019192954 | BS26: 0.01973513 | BT26: 0.047694337 | BU26: 0.011454817 | BV26: 0.043228621 | BW26: -0.04274743 | BX26: -0.017811292 | BY26: -0.1511531 | BZ26: 0.124224 | CA26: -0.0045572538 | CB26: 0.06021124 | CC26: 0.085992033 | CD26: -0.0058084796 | CE26: -0.006041347 | CF26: 0.0024523244 | CG26: 0.089636252 | CH26: 0.070992733 | CI26: 0.027170643 | CJ26: 0.052468428 | CK26: 0.029480661 | CL26: 0.066825081 | CM26: -0.028772229 | CN26: 0.039462516 | CO26: -0.029031087 | CP26: 0.013983883 | CQ26: -0.032276965 | CR26: 0.0031035766 | CS26: 0.025591856 | CT26: 0.044391886 | CU26: -0.030338959 | CV26: -0.0012579765 | CW26: 0.0023363565 | CX26: -0.064264145 | CY26: 0.012909779 | CZ26: -0.12547709 | DA26: 0.011690683 | DB26: 0.0063378437 | DC26: -0.11730536 | DD26: -0.036010872 | DE26: 0.1389113 | DF26: -0.051143506 | DG26: 0.076731447 | DH26: 0.015508782 | DI26: 0.023223774 | DJ26: -0.018372876 | DK26: 0.062199014 | DL26: 0.020098304 | DM26: 0.01349894 | DN26: -0.030252213 | DO26: -0.017022836 | DP26: -0.021788523 | DQ26: 0.085745625 | DR26: 0.028106744 | DS26: -0.0023031598 | DT26: 0.058471198 | DU26: 0.067658949 | DV26: 0.0050207706 | DW26: 0.037416184 | DX26: 0.084111004 | DY26: -0.036832399 | DZ26: 0.0030917028 | EA26: -0.0019576282 | EB26: 0.026459104 | EC26: -0.024752539 | ED26: 0.034115491 | EE26: 0.021061974 | EF26: -0.020277393
B28: 低 | C28: 3043 | D28: 3043 | E28: 6130 | F28: 6130 | G28: 6130 | H28: 6130 | I28: 6130 | J28: 9906 | K28: 5324 | L28: 5324 | M28: 5324 | N28: 5324 | O28: 5324 | P28: 5455 | Q28: 5324 | R28: 5324 | S28: 2388 | T28: 2439 | U28: 1472 | V28: 2388 | W28: 4413 | X28: 2388 | Y28: 3232 | Z28: 6259 | AA28: 6259 | AB28: 6228 | AC28: 9906 | AD28: 9906 | AE28: 5381 | AF28: 5455 | AG28: 6259 | AH28: 6225 | AI28: 6225 | AJ28: 6225 | AK28: 6259 | AL28: 6259 | AM28: 6225 | AN28: 6225 | AO28: 6225 | AP28: 6225 | AQ28: 3064 | AR28: 6227 | AS28: 3064 | AT28: 3064 | AU28: 3064 | AV28: 3064 | AW28: 5205 | AX28: 3064 | AY28: 8044 | AZ28: 5386 | BA28: 4903 | BB28: 6225 | BC28: 4903 | BD28: 6291 | BE28: 5205 | BF28: 8067 | BG28: 1475 | BH28: 6165 | BI28: 1475 | BJ28: 6225 | BK28: 4303 | BL28: 6225 | BM28: 4303 | BN28: 6225 | BO28: 6225 | BP28: 6225 | BQ28: 6225 | BR28: 6225 | BS28: 6225 | BT28: 3085 | BU28: 3085 | BV28: 5310 | BW28: 3085 | BX28: 3064 | BY28: 3085 | BZ28: 8080 | CA28: 5205 | CB28: 5475 | CC28: 8087 | CD28: 5205 | CE28: 5205 | CF28: 8070 | CG28: 8070 | CH28: 8070 | CI28: 4304 | CJ28: 8070 | CK28: 8070 | CL28: 8070 | CM28: 8070 | CN28: 5205 | CO28: 8070 | CP28: 8070 | CQ28: 1325 | CR28: 3043 | CS28: 5205 | CT28: 1325 | CU28: 3064 | CV28: 1325 | CW28: 6276 | CX28: 8101 | CY28: 6276 | CZ28: 8101 | DA28: 1538 | DB28: 5314 | DC28: 2007 | DD28: 8080 | DE28: 2486 | DF28: 2486 | DG28: 5475 | DH28: 1538 | DI28: 8080 | DJ28: 6225 | DK28: 6225 | DL28: 5468 | DM28: 9945 | DN28: 4402 | DO28: 4402 | DP28: 8933 | DQ28: 8933 | DR28: 4419 | DS28: 2615 | DT28: 4419 | DU28: 5345 | DV28: 3085 | DW28: 4304 | DX28: 2482 | DY28: 2482 | DZ28: 6291 | EA28: 2321 | EB28: 2321 | EC28: 2321 | ED28: 2321 | EE28: 2321 | EF28: 2321
B29: 公司名稱 | C29: 科風 | D29: 科風 | E29: 上亞科技 | F29: 上亞科技 | G29: 上亞科技 | H29: 上亞科技 | I29: 上亞科技 | J29: 欣巴巴 | K29: 士開 | L29: 士開 | M29: 士開 | N29: 士開 | O29: 士開 | P29: 昇益 | Q29: 士開 | R29: 士開 | S29: 威盛 | T29: 美律 | U29: 三洋實業 | V29: 威盛 | W29: 飛寶企業 | X29: 威盛 | Y29: 昱捷 | Z29: 百徽 | AA29: 百徽 | AB29: 全譜 | AC29: 欣巴巴 | AD29: 欣巴巴 | AE29: 合正 | AF29: 昇益 | AG29: 百徽 | AH29: 天瀚 | AI29: 天瀚 | AJ29: 天瀚 | AK29: 百徽 | AL29: 百徽 | AM29: 天瀚 | AN29: 天瀚 | AO29: 天瀚 | AP29: 天瀚 | AQ29: 泰偉 | AR29: 茂綸 | AS29: 泰偉 | AT29: 泰偉 | AU29: 泰偉 | AV29: 泰偉 | AW29: 中茂 | AX29: 泰偉 | AY29: 網家 | AZ29: 青雲 | BA29: 聯光通 | BB29: 天瀚 | BC29: 聯光通 | BD29: 沛亨 | BE29: 中茂 | BF29: 志旭 | BG29: 業旺 | BH29: 浪凡 | BI29: 業旺 | BJ29: 天瀚 | BK29: 信立 | BL29: 天瀚 | BM29: 信立 | BN29: 天瀚 | BO29: 天瀚 | BP29: 天瀚 | BQ29: 天瀚 | BR29: 天瀚 | BS29: 天瀚 | BT29: 新零售 | BU29: 新零售 | BV29: 天剛 | BW29: 新零售 | BX29: 泰偉 | BY29: 新零售 | BZ29: 印鉐 | CA29: 中茂 | CB29: 德宏 | CC29: 麗升能源 | CD29: 中茂 | CE29: 中茂 | CF29: 長華* | CG29: 長華* | CH29: 長華* | CI29: 勝昱 | CJ29: 長華* | CK29: 長華* | CL29: 長華* | CM29: 長華* | CN29: 中茂 | CO29: 長華* | CP29: 長華* | CQ29: 恒大 | CR29: 科風 | CS29: 中茂 | CT29: 恒大 | CU29: 泰偉 | CV29: 恒大 | CW29: 安鈦克 | CX29: 華冠 | CY29: 安鈦克 | CZ29: 華冠 | DA29: 正峰 | DB29: 世紀 | DC29: 燁興 | DD29: 印鉐 | DE29: 一詮 | DF29: 一詮 | DG29: 德宏 | DH29: 正峰 | DI29: 印鉐 | DJ29: 天瀚 | DK29: 天瀚 | DL29: 凱鈺 | DM29: 潤泰新 | DN29: 郡都開發 | DO29: 郡都開發 | DP29: 愛地雅 | DQ29: 愛地雅 | DR29: 皇家美食 | DS29: 萬海 | DT29: 皇家美食 | DU29: 天揚 | DV29: 新零售 | DW29: 勝昱 | DX29: 連宇 | DY29: 連宇 | DZ29: 沛亨 | EA29: 東訊 | EB29: 東訊 | EC29: 東訊 | ED29: 東訊 | EE29: 東訊 | EF29: 東訊
B30: 高 | C30: 2540 | D30: 5364 | E30: 5364 | F30: 5364 | G30: 5364 | H30: 5364 | I30: 5364 | J30: 5364 | K30: 5364 | L30: 8941 | M30: 5364 | N30: 5364 | O30: 2408 | P30: 2323 | Q30: 2408 | R30: 2408 | S30: 2408 | T30: 2408 | U30: 2408 | V30: 2408 | W30: 2323 | X30: 5455 | Y30: 1449 | Z30: 4413 | AA30: 4502 | AB30: 4502 | AC30: 4502 | AD30: 4502 | AE30: 4502 | AF30: 4502 | AG30: 4502 | AH30: 2323 | AI30: 2323 | AJ30: 2323 | AK30: 2496 | AL30: 6246 | AM30: 2323 | AN30: 2323 | AO30: 2323 | AP30: 2323 | AQ30: 6246 | AR30: 2496 | AS30: 2496 | AT30: 2496 | AU30: 2496 | AV30: 2337 | AW30: 2337 | AX30: 2337 | AY30: 1475 | AZ30: 4303 | BA30: 6150 | BB30: 3252 | BC30: 6150 | BD30: 2330 | BE30: 2330 | BF30: 2330 | BG30: 2330 | BH30: 2342 | BI30: 2330 | BJ30: 1906 | BK30: 2388 | BL30: 8085 | BM30: 1529 | BN30: 8085 | BO30: 8085 | BP30: 8085 | BQ30: 3252 | BR30: 2409 | BS30: 3252 | BT30: 1529 | BU30: 1529 | BV30: 1529 | BW30: 5340 | BX30: 4702 | BY30: 2429 | BZ30: 5608 | CA30: 2330 | CB30: 1325 | CC30: 2330 | CD30: 5608 | CE30: 2330 | CF30: 1325 | CG30: 1325 | CH30: 1325 | CI30: 2330 | CJ30: 6204 | CK30: 6259 | CL30: 3086 | CM30: 6259 | CN30: 2330 | CO30: 2609 | CP30: 2609 | CQ30: 5475 | CR30: 2609 | CS30: 2330 | CT30: 5475 | CU30: 5475 | CV30: 5475 | CW30: 5475 | CX30: 1906 | CY30: 2364 | CZ30: 1906 | DA30: 2330 | DB30: 2330 | DC30: 2364 | DD30: 2330 | DE30: 2364 | DF30: 2364 | DG30: 2364 | DH30: 2330 | DI30: 2330 | DJ30: 2362 | DK30: 3252 | DL30: 3043 | DM30: 3043 | DN30: 3043 | DO30: 5314 | DP30: 3043 | DQ30: 5314 | DR30: 1906 | DS30: 8077 | DT30: 1314 | DU30: 2330 | DV30: 5314 | DW30: 2330 | DX30: 5314 | DY30: 5314 | DZ30: 5314 | EA30: 2330 | EB30: 2330 | EC30: 2330 | ED30: 2330 | EE30: 2330 | EF30: 2330
B31: 公司名稱 | C31: 愛山林 | D31: 力麗店 | E31: 力麗店 | F31: 力麗店 | G31: 力麗店 | H31: 力麗店 | I31: 力麗店 | J31: 力麗店 | K31: 力麗店 | L31: 關中 | M31: 力麗店 | N31: 力麗店 | O31: 南亞科 | P31: 中環 | Q31: 南亞科 | R31: 南亞科 | S31: 南亞科 | T31: 南亞科 | U31: 南亞科 | V31: 南亞科 | W31: 中環 | X31: 昇益 | Y31: 佳和 | Z31: 飛寶企業 | AA31: 健信 | AB31: 健信 | AC31: 健信 | AD31: 健信 | AE31: 健信 | AF31: 健信 | AG31: 健信 | AH31: 中環 | AI31: 中環 | AJ31: 中環 | AK31: 卓越 | AL31: 臺龍 | AM31: 中環 | AN31: 中環 | AO31: 中環 | AP31: 中環 | AQ31: 臺龍 | AR31: 卓越 | AS31: 卓越 | AT31: 卓越 | AU31: 卓越 | AV31: 旺宏 | AW31: 旺宏 | AX31: 旺宏 | AY31: 業旺 | AZ31: 信立 | BA31: 撼訊 | BB31: 海灣 | BC31: 撼訊 | BD31: 台積電 | BE31: 台積電 | BF31: 台積電 | BG31: 台積電 | BH31: 茂矽 | BI31: 台積電 | BJ31: 寶隆 | BK31: 威盛 | BL31: 福華 | BM31: 樂事綠能 | BN31: 福華 | BO31: 福華 | BP31: 福華 | BQ31: 海灣 | BR31: 友達 | BS31: 海灣 | BT31: 樂事綠能 | BU31: 樂事綠能 | BV31: 樂事綠能 | BW31: 建榮 | BX31: 中美實 | BY31: 銘旺科 | BZ31: 四維航 | CA31: 台積電 | CB31: 恒大 | CC31: 台積電 | CD31: 四維航 | CE31: 台積電 | CF31: 恒大 | CG31: 恒大 | CH31: 恒大 | CI31: 台積電 | CJ31: 艾華 | CK31: 百徽 | CL31: 華義 | CM31: 百徽 | CN31: 台積電 | CO31: 陽明 | CP31: 陽明 | CQ31: 德宏 | CR31: 陽明 | CS31: 台積電 | CT31: 德宏 | CU31: 德宏 | CV31: 德宏 | CW31: 德宏 | CX31: 寶隆 | CY31: 倫飛 | CZ31: 寶隆 | DA31: 台積電 | DB31: 台積電 | DC31: 倫飛 | DD31: 台積電 | DE31: 倫飛 | DF31: 倫飛 | DG31: 倫飛 | DH31: 台積電 | DI31: 台積電 | DJ31: 藍天 | DK31: 海灣 | DL31: 科風 | DM31: 科風 | DN31: 科風 | DO31: 世紀 | DP31: 科風 | DQ31: 世紀 | DR31: 寶隆 | DS31: 洛碁 | DT31: 中石化 | DU31: 台積電 | DV31: 世紀 | DW31: 台積電 | DX31: 世紀 | DY31: 世紀 | DZ31: 世紀 | EA31: 台積電 | EB31: 台積電 | EC31: 台積電 | ED31: 台積電 | EE31: 台積電 | EF31: 台積電

Sheet 夏普比率
A1: NN1
B2: Time | C2: 2013/12 | D2: 2014/01 | E2: 2014/02 | F2: 2014/03 | G2: 2014/04 | H2: 2014/05 | I2: 2014/06 | J2: 2014/07 | K2: 2014/08 | L2: 2014/09 | M2: 2014/10 | N2: 2014/11 | O2: 2014/12 | P2: 2015/01 | Q2: 2015/02 | R2: 2015/03 | S2: 2015/04 | T2: 2015/05 | U2: 2015/06 | V2: 2015/07 | W2: 2015/08 | X2: 2015/09 | Y2: 2015/10 | Z2: 2015/11 | AA2: 2015/12 | AB2: 2016/01 | AC2: 2016/02 | AD2: 2016/03 | AE2: 2016/04 | AF2: 2016/05 | AG2: 2016/06 | AH2: 2016/07 | AI2: 2016/08 | AJ2: 2016/09 | AK2: 2016/10 | AL2: 2016/11 | AM2: 2016/12 | AN2: 2017/01 | AO2: 2017/02 | AP2: 2017/03 | AQ2: 2017/04 | AR2: 2017/05 | AS2: 2017/06 | AT2: 2017/07 | AU2: 2017/08 | AV2: 2017/09 | AW2: 2017/10 | AX2: 2017/11 | AY2: 2017/12 | AZ2: 2018/01 | BA2: 2018/02 | BB2: 2018/03 | BC2: 2018/04 | BD2: 2018/05 | BE2: 2018/06 | BF2: 2018/07 | BG2: 2018/08 | BH2: 2018/09 | BI2: 2018/10 | BJ2: 2018/11 | BK2: 2018/12 | BL2: 2019/01 | BM2: 2019/02 | BN2: 2019/03 | BO2: 2019/04 | BP2: 2019/05 | BQ2: 2019/06 | BR2: 2019/07 | BS2: 2019/08 | BT2: 2019/09 | BU2: 2019/10 | BV2: 2019/11 | BW2: 2019/12 | BX2: 2020/01 | BY2: 2020/02 | BZ2: 2020/03 | CA2: 2020/04 | CB2: 2020/05 | CC2: 2020/06 | CD2: 2020/07 | CE2: 2020/08 | CF2: 2020/09 | CG2: 2020/10 | CH2: 2020/11 | CI2: 2020/12 | CJ2: 2021/01 | CK2: 2021/02 | CL2: 2021/03 | CM2: 2021/04 | CN2: 2021/05 | CO2: 2021/06 | CP2: 2021/07 | CQ2: 2021/08 | CR2: 2021/09 | CS2: 2021/10 | CT2: 2021/11 | CU2: 2021/12 | CV2: 2022/01 | CW2: 2022/02 | CX2: 2022/03 | CY2: 2022/04 | CZ2: 2022/05 | DA2: 2022/06 | DB2: 2022/07 | DC2: 2022/08 | DD2: 2022/09 | DE2: 2022/10 | DF2: 2022/11 | DG2: 2022/12 | DH2: 2023/01 | DI2: 2023/02 | DJ2: 2023/03 | DK2: 2023/04 | DL2: 2023/05 | DM2: 2023/06 | DN2: 2023/07 | DO2: 2023/08 | DP2: 2023/09 | DQ2: 2023/10 | DR2: 2023/11 | DS2: 2023/12 | DT2: 2024/01 | DU2: 2024/02 | DV2: 2024/03 | DW2: 2024/04 | DX2: 2024/05 | DY2: 2024/06 | DZ2: 2024/07 | EA2: 2024/08 | EB2: 2024/09 | EC2: 2024/10 | ED2: 2024/11 | EE2: 2024/12 | EF2: 2025/01
