Workbook

Sheet 預測IC
A1: NN2
B2: Time | C2: 2013/12 | D2: 2014/01 | E2: 2014/02 | F2: 2014/03 | G2: 2014/04 | H2: 2014/05 | I2: 2014/06 | J2: 2014/07 | K2: 2014/08 | L2: 2014/09 | M2: 2014/10 | N2: 2014/11 | O2: 2014/12 | P2: 2015/01 | Q2: 2015/02 | R2: 2015/03 | S2: 2015/04 | T2: 2015/05 | U2: 2015/06 | V2: 2015/07 | W2: 2015/08 | X2: 2015/09 | Y2: 2015/10 | Z2: 2015/11 | AA2: 2015/12 | AB2: 2016/01 | AC2: 2016/02 | AD2: 2016/03 | AE2: 2016/04 | AF2: 2016/05 | AG2: 2016/06 | AH2: 2016/07 | AI2: 2016/08 | AJ2: 2016/09 | AK2: 2016/10 | AL2: 2016/11 | AM2: 2016/12 | AN2: 2017/01 | AO2: 2017/02 | AP2: 2017/03 | AQ2: 2017/04 | AR2: 2017/05 | AS2: 2017/06 | AT2: 2017/07 | AU2: 2017/08 | AV2: 2017/09 | AW2: 2017/10 | AX2: 2017/11 | AY2: 2017/12 | AZ2: 2018/01 | BA2: 2018/02 | BB2: 2018/03 | BC2: 2018/04 | BD2: 2018/05 | BE2: 2018/06 | BF2: 2018/07 | BG2: 2018/08 | BH2: 2018/09 | BI2: 2018/10 | BJ2: 2018/11 | BK2: 2018/12 | BL2: 2019/01 | BM2: 2019/02 | BN2: 2019/03 | BO2: 2019/04 | BP2: 2019/05 | BQ2: 2019/06 | BR2: 2019/07 | BS2: 2019/08 | BT2: 2019/09 | BU2: 2019/10 | BV2: 2019/11 | BW2: 2019/12 | BX2: 2020/01 | BY2: 2020/02 | BZ2: 2020/03 | CA2: 2020/04 | CB2: 2020/05 | CC2: 2020/06 | CD2: 2020/07 | CE2: 2020/08 | CF2: 2020/09 | CG2: 2020/10 | CH2: 2020/11 | CI2: 2020/12 | CJ2: 2021/01 | CK2: 2021/02 | CL2: 2021/03 | CM2: 2021/04 | CN2: 2021/05 | CO2: 2021/06 | CP2: 2021/07 | CQ2: 2021/08 | CR2: 2021/09 | CS2: 2021/10 | CT2: 2021/11 | CU2: 2021/12 | CV2: 2022/01 | CW2: 2022/02 | CX2: 2022/03 | CY2: 2022/04 | CZ2: 2022/05 | DA2: 2022/06 | DB2: 2022/07 | DC2: 2022/08 | DD2: 2022/09 | DE2: 2022/10 | DF2: 2022/11 | DG2: 2022/12 | DH2: 2023/01 | DI2: 2023/02 | DJ2: 2023/03 | DK2: 2023/04 | DL2: 2023/05 | DM2: 2023/06 | DN2: 2023/07 | DO2: 2023/08 | DP2: 2023/09 | DQ2: 2023/10 | DR2: 2023/11 | DS2: 2023/12 | DT2: 2024/01 | DU2: 2024/02 | DV2: 2024/03 | DW2: 2024/04 | DX2: 2024/05 | DY2: 2024/06 | DZ2: 2024/07 | EA2: 2024/08 | EB2: 2024/09 | EC2: 2024/10 | ED2: 2024/11 | EE2: 2024/12 | EF2: 2025/01
B3: bm | C3: 0.057230778 | D3: 0.075454518 | E3: 0.053419497 | F3: 0.048055463 | G3: 0.056244601 | H3: 0.053408809 | I3: 0.054677729 | J3: 0.061407112 | K3: 0.061087191 | L3: 0.061945472 | M3: 0.064090975 | N3: 0.050166409 | O3: 0.050939202 | P3: 0.05394581 | Q3: 0.05463516 | R3: 0.054097041 | S3: 0.054209419 | T3: 0.056115322 | U3: 0.054694336 | V3: 0.055520311 | W3: 0.057895616 | X3: 0.056128561 | Y3: 0.054498971 | Z3: 0.056409225 | AA3: 0.054687083 | AB3: 0.054479975 | AC3: 0.057393115 | AD3: 0.057433717 | AE3: 0.042686142 | AF3: 0.056140695 | AG3: 0.055614285 | AH3: 0.020760968 | AI3: 0.025099238 | AJ3: 0.029194398 | AK3: 0.030455951 | AL3: 0.034250386 | AM3: 0.039540499 | AN3: 0.043252841 | AO3: 0.044728361 | AP3: 0.042892594 | AQ3: 0.045430332 | AR3: 0.044913445 | AS3: 0.048380431 | AT3: 0.041918073 | AU3: 0.041785151 | AV3: 0.04308163 | AW3: 0.046142738 | AX3: 0.045525301 | AY3: 0.047935985 | AZ3: 0.041659117 | BA3: 0.038711324 | BB3: 0.038947169 | BC3: 0.042427823 | BD3: 0.04405136 | BE3: 0.045637585 | BF3: 0.048670642 | BG3: 0.049968019 | BH3: 0.051808406 | BI3: 0.05058419 | BJ3: 0.052059561 | BK3: 0.052372251 | BL3: 0.050854672 | BM3: 0.052194197 | BN3: 0.056162696 | BO3: 0.054506797 | BP3: 0.040165633 | BQ3: 0.052233845 | BR3: 0.036525637 | BS3: 0.052801784 | BT3: 0.048056014 | BU3: -0.09914422 | BV3: 0.052249499 | BW3: 0.03947461 | BX3: 0.047410384 | BY3: 0.047043912 | BZ3: 0.046114489 | CA3: 0.042742863 | CB3: 0.03848974 | CC3: 0.037457056 | CD3: 0.039794289 | CE3: 0.037495688 | CF3: 0.025139354 | CG3: 0.035978682 | CH3: 0.031778947 | CI3: 0.034042399 | CJ3: 0.038737696 | CK3: 0.039908383 | CL3: 0.037117619 | CM3: 0.017108668 | CN3: 0.040649183 | CO3: 0.02801203 | CP3: 0.0060336315 | CQ3: 0.033265896 | CR3: 0.033467647 | CS3: 0.022955686 | CT3: 0.018620189 | CU3: 0.016736574 | CV3: 0.0088566393 | CW3: 0.018140115 | CX3: 0.023012115 | CY3: 0.025537871 | CZ3: -0.010740899 | DA3: 0.017809309 | DB3: 0.031221993 | DC3: 0.0099241827 | DD3: 0.033772524 | DE3: 0.023819208 | DF3: 0.025578402 | DG3: 0.013096854 | DH3: 0.025391292 | DI3: 0.023517698 | DJ3: 0.0031970106 | DK3: 0.00061636377 | DL3: 0.0051844632 | DM3: 0.025786715 | DN3: 0.0097193727 | DO3: 0.0026195138 | DP3: -0.0043171626 | DQ3: 0.02653504 | DR3: 0.032421928 | DS3: 0.026365884 | DT3: 0.018022846 | DU3: 0.020606074 | DV3: 0.023552461 | DW3: 0.021600418 | DX3: 0.014226238 | DY3: 0.015565707 | DZ3: 0.013406808 | EA3: 0.0049481243 | EB3: -0.012768214 | EC3: 0.036291156 | ED3: 0.024168495 | EE3: 0.02159296 | EF3: 0.026417185
B4: size | C4: -0.085349172 | D4: -0.05103204 | E4: -0.023255965 | F4: -0.030555831 | G4: -0.041839469 | H4: -0.027263904 | I4: -0.048288547 | J4: -0.037313268 | K4: -0.037903525 | L4: -0.037348431 | M4: -0.037616447 | N4: -0.03742402 | O4: -0.034556981 | P4: -0.034502812 | Q4: -0.027798316 | R4: -0.026597736 | S4: -0.028584613 | T4: -0.029216319 | U4: -0.028851731 | V4: -0.028718717 | W4: -0.02587227 | X4: -0.028767424 | Y4: -0.028886387 | Z4: -0.030202819 | AA4: -0.029697826 | AB4: -0.029449735 | AC4: -0.019321049 | AD4: -0.028943898 | AE4: -0.029567476 | AF4: -0.028563548 | AG4: -0.028323654 | AH4: -0.027333213 | AI4: -0.037235942 | AJ4: -0.03408863 | AK4: -0.02742449 | AL4: -0.024591474 | AM4: -0.029777821 | AN4: -0.033753969 | AO4: -0.035720218 | AP4: -0.018044906 | AQ4: -0.023741988 | AR4: -0.038850483 | AS4: -0.1345173 | AT4: -0.02849295 | AU4: -0.030869178 | AV4: -0.032064013 | AW4: -0.026232475 | AX4: -0.026473839 | AY4: -0.034000531 | AZ4: -0.027450914 | BA4: -0.031005733 | BB4: -0.033746343 | BC4: -0.031035988 | BD4: -0.030587777 | BE4: -0.032944158 | BF4: -0.031238463 | BG4: -0.032052599 | BH4: -0.030557938 | BI4: -0.031080937 | BJ4: -0.030351296 | BK4: -0.032760028 | BL4: -0.031334665 | BM4: -0.031740569 | BN4: 0.07982564 | BO4: -0.02243706 | BP4: -0.037594955 | BQ4: -0.032917906 | BR4: -0.012001145 | BS4: -0.013084842 | BT4: -0.026131108 | BU4: -0.035951588 | BV4: -0.033736389 | BW4: -0.024462303 | BX4: -0.032545313 | BY4: -0.031732854 | BZ4: -0.035243522 | CA4: -0.032394681 | CB4: -0.02393622 | CC4: -0.028863324 | CD4: -0.026372921 | CE4: -0.040299051 | CF4: -0.032261208 | CG4: -0.029903112 | CH4: -0.03120617 | CI4: -0.031554945 | CJ4: -0.032127731 | CK4: -0.031585943 | CL4: -0.031090209 | CM4: -0.031166909 | CN4: -0.03068649 | CO4: -0.030511757 | CP4: -0.030179881 | CQ4: -0.030264538 | CR4: -0.030227818 | CS4: -0.030388758 | CT4: -0.022377491 | CU4: -0.026706485 | CV4: -0.028211297 | CW4: -0.033567265 | CX4: -0.02785942 | CY4: -0.023028297 | CZ4: -0.026201611 | DA4: -0.02958351 | DB4: -0.033195734 | DC4: -0.031532101 | DD4: -0.029648697 | DE4: -0.028857935 | DF4: -0.02839925 | DG4: -0.026426362 | DH4: -0.030645844 | DI4: -0.029881418 | DJ4: -0.02959696 | DK4: -0.028411226 | DL4: -0.030489476 | DM4: -0.027597029 | DN4: -0.028250575 | DO4: -0.027726073 | DP4: -0.027154023 | DQ4: -0.026989534 | DR4: -0.028884927 | DS4: -0.026225228 | DT4: -0.14326423 | DU4: -0.043057509 | DV4: -0.032543007 | DW4: -0.027246328 | DX4: -0.027451478 | DY4: -0.028264472 | DZ4: -0.024180055 | EA4: -0.026992777 | EB4: -0.026342381 | EC4: -0.028216563 | ED4: -0.023997756 | EE4: -0.035310321 | EF4: -0.029033292
B5: mom | C5: 0.0038081713 | D5: -0.0054777833 | E5: -0.005490066 | F5: -0.0051145633 | G5: -0.0077640302 | H5: -0.0072011286 | I5: -0.0063504917 | J5: -0.0064376979 | K5: -0.0072753257 | L5: -0.0074702143 | M5: -0.0059039127 | N5: 0.012302655 | O5: 0.020934619 | P5: 0.0027155192 | Q5: 0.0030463424 | R5: -0.0048635076 | S5: -0.0016708683 | T5: 0.0041404879 | U5: 0.002761554 | V5: -0.00051478209 | W5: 0.00075550959 | X5: -0.0031146645 | Y5: -0.011311441 | Z5: -0.0028005762 | AA5: -0.0089693367 | AB5: -0.0081666028 | AC5: -0.016397143 | AD5: -0.010888714 | AE5: -0.0092730159 | AF5: -0.0046079545 | AG5: -0.0058455127 | AH5: -0.0049838116 | AI5: -0.0036265091 | AJ5: -0.003818823 | AK5: -0.0046545602 | AL5: -0.0053977398 | AM5: -0.0069995066 | AN5: 0.00099394354 | AO5: -0.0042327293 | AP5: -0.0062828083 | AQ5: -0.0027964443 | AR5: -0.0035480226 | AS5: -0.0018412303 | AT5: 0.017384442 | AU5: -0.0066342503 | AV5: 0.0073471954 | AW5: 0.0047246637 | AX5: -0.0017786961 | AY5: -0.00098629016 | AZ5: 0.010417148 | BA5: -0.0011489491 | BB5: -0.0020870927 | BC5: 0.0013366323 | BD5: 0.0050694281 | BE5: -0.0048598065 | BF5: 0.00051613257 | BG5: -0.0070163407 | BH5: -0.004190716 | BI5: 0.00030854528 | BJ5: -0.00029275671 | BK5: -0.011491623 | BL5: -0.012680532 | BM5: -0.0044326517 | BN5: -0.00089442637 | BO5: -0.0044179424 | BP5: -0.0085916733 | BQ5: -0.0044214986 | BR5: 0.001025304 | BS5: -0.00072602357 | BT5: 0.00022115291 | BU5: -0.0040715635 | BV5: -0.001552918 | BW5: -0.0038780456 | BX5: -0.0021147833 | BY5: -0.0026352899 | BZ5: 0.0018134824 | CA5: -0.016779374 | CB5: -0.018080382 | CC5: -0.0090212021 | CD5: -0.0060056518 | CE5: 0.0048917099 | CF5: -0.0049459008 | CG5: -0.0017642195 | CH5: -0.0022557762 | CI5: -0.0057940958 | CJ5: 0.005367903 | CK5: -0.0065037031 | CL5: -0.0092684589 | CM5: 0.0034533716 | CN5: -0.0015305429 | CO5: 0.0027638073 | CP5: -0.0030045167 | CQ5: -0.0042182007 | CR5: 0.001238219 | CS5: -0.0056209103 | CT5: -0.00012895511 | CU5: -0.0035577645 | CV5: -0.00088373589 | CW5: -0.0037108788 | CX5: -0.001892625 | CY5: -0.0022389428 | CZ5: -2.9421761e-05 | DA5: -0.0014534973 | DB5: -0.0033510185 | DC5: -0.0039163325 | DD5: -0.0047809812 | DE5: -0.0044807596 | DF5: -0.023375858 | DG5: -0.0039326213 | DH5: -0.0043730317 | DI5: -0.015652239 | DJ5: 0.006037062 | DK5: -0.0082938047 | DL5: -0.0044081835 | DM5: -0.00044374762 | DN5: -0.0030054445 | DO5: 0.0028427737 | DP5: -0.0061313035 | DQ5: -0.0046811854 | DR5: -0.007172246 | DS5: -0.0036357224 | DT5: -0.00029824208 | DU5: -0.005670514 | DV5: -0.0031858636 | DW5: -0.0070032077 | DX5: -0.006635204 | DY5: -0.0032449104 | DZ5: -0.0019835071 | EA5: -0.0025352328 | EB5: -0.004487603 | EC5: -0.0053785997 | ED5: -0.006454953 | EE5: -0.0062718079 | EF5: -0.0061802692
A6: 選絕對值最大 | C6: {=MATCH(MAX(ABS(C3:C5)),ABS(C3:C5),0)} -> 2 | D6: {=MATCH(MAX(ABS(D3:D5)),ABS(D3:D5),0)} -> 1 | E6: {=MATCH(MAX(ABS(E3:E5)),ABS(E3:E5),0)} -> 1 | F6: {=MATCH(MAX(ABS(F3:F5)),ABS(F3:F5),0)} -> 1 | G6: {=MATCH(MAX(ABS(G3:G5)),ABS(G3:G5),0)} -> 1 | H6: {=MATCH(MAX(ABS(H3:H5)),ABS(H3:H5),0)} -> 1 | I6: {=MATCH(MAX(ABS(I3:I5)),ABS(I3:I5),0)} -> 1 | J6: {=MATCH(MAX(ABS(J3:J5)),ABS(J3:J5),0)} -> 1 | ... EF6: {=MATCH(MAX(ABS(EF3:EF5)),ABS(EF3:EF5),0)} -> 2
C7: =IF(C6=1,"bm",IF(C6=2,"size",IF(C6=3,"mom"))) -> size | D7: =IF(D6=1,"bm",IF(D6=2,"size",IF(D6=3,"mom"))) -> bm | E7: =IF(E6=1,"bm",IF(E6=2,"size",IF(E6=3,"mom"))) -> bm | F7: =IF(F6=1,"bm",IF(F6=2,"size",IF(F6=3,"mom"))) -> bm | G7: =IF(G6=1,"bm",IF(G6=2,"size",IF(G6=3,"mom"))) -> bm | H7: =IF(H6=1,"bm",IF(H6=2,"size",IF(H6=3,"mom"))) -> bm | I7: =IF(I6=1,"bm",IF(I6=2,"size",IF(I6=3,"mom"))) -> bm | J7: =IF(J6=1,"bm",IF(J6=2,"size",IF(J6=3,"mom"))) -> bm | ... EF7: =IF(EF6=1,"bm",IF(EF6=2,"size",IF(EF6=3,"mom"))) -> size
C8: =IF(C6=1,C3,IF(C6=2,C4,IF(C6=3,C5))) -> -0.085349172 | D8: =IF(D6=1,D3,IF(D6=2,D4,IF(D6=3,D5))) -> 0.075454518 | E8: =IF(E6=1,E3,IF(E6=2,E4,IF(E6=3,E5))) -> 0.053419497 | F8: =IF(F6=1,F3,IF(F6=2,F4,IF(F6=3,F5))) -> 0.048055463 | G8: =IF(G6=1,G3,IF(G6=2,G4,IF(G6=3,G5))) -> 0.056244601 | H8: =IF(H6=1,H3,IF(H6=2,H4,IF(H6=3,H5))) -> 0.053408809 | I8: =IF(I6=1,I3,IF(I6=2,I4,IF(I6=3,I5))) -> 0.054677729 | J8: =IF(J6=1,J3,IF(J6=2,J4,IF(J6=3,J5))) -> 0.061407112 | ... EF8: =IF(EF6=1,EF3,IF(EF6=2,EF4,IF(EF6=3,EF5))) -> -0.029033292
A10: 投資組合 | C10: 公司數 | D10: 964
A11: 等分 | B11: 分數 | C11: 2014/01 | D11: 2014/02 | E11: 2014/03 | F11: 2014/04 | G11: 2014/05 | H11: 2014/06 | I11: 2014/07 | J11: 2014/08 | K11: 2014/09 | L11: 2014/10 | M11: 2014/11 | N11: 2014/12 | O11: 2015/01 | P11: 2015/02 | Q11: 2015/03 | R11: 2015/04 | S11: 2015/05 | T11: 2015/06 | U11: 2015/07 | V11: 2015/08 | W11: 2015/09 | X11: 2015/10 | Y11: 2015/11 | Z11: 2015/12 | AA11: 2016/01 | AB11: 2016/02 | AC11: 2016/03 | AD11: 2016/04 | AE11: 2016/05 | AF11: 2016/06 | AG11: 2016/07 | AH11: 2016/08 | AI11: 2016/09 | AJ11: 2016/10 | AK11: 2016/11 | AL11: 2016/12 | AM11: 2017/01 | AN11: 2017/02 | AO11: 2017/03 | AP11: 2017/04 | AQ11: 2017/05 | AR11: 2017/06 | AS11: 2017/07 | AT11: 2017/08 | AU11: 2017/09 | AV11: 2017/10 | AW11: 2017/11 | AX11: 2017/12 | AY11: 2018/01 | AZ11: 2018/02 | BA11: 2018/03 | BB11: 2018/04 | BC11: 2018/05 | BD11: 2018/06 | BE11: 2018/07 | BF11: 2018/08 | BG11: 2018/09 | BH11: 2018/10 | BI11: 2018/11 | BJ11: 2018/12 | BK11: 2019/01 | BL11: 2019/02 | BM11: 2019/03 | BN11: 2019/04 | BO11: 2019/05 | BP11: 2019/06 | BQ11: 2019/07 | BR11: 2019/08 | BS11: 2019/09 | BT11: 2019/10 | BU11: 2019/11 | BV11: 2019/12 | BW11: 2020/01 | BX11: 2020/02 | BY11: 2020/03 | BZ11: 2020/04 | CA11: 2020/05 | CB11: 2020/06 | CC11: 2020/07 | CD11: 2020/08 | CE11: 2020/09 | CF11: 2020/10 | CG11: 2020/11 | CH11: 2020/12 | CI11: 2021/01 | CJ11: 2021/02 | CK11: 2021/03 | CL11: 2021/04 | CM11: 2021/05 | CN11: 2021/06 | CO11: 2021/07 | CP11: 2021/08 | CQ11: 2021/09 | CR11: 2021/10 | CS11: 2021/11 | CT11: 2021/12 | CU11: 2022/01 | CV11: 2022/02 | CW11: 2022/03 | CX11: 2022/04 | CY11: 2022/05 | CZ11: 2022/06 | DA11: 2022/07 | DB11: 2022/08 | DC11: 2022/09 | DD11: 2022/10 | DE11: 2022/11 | DF11: 2022/12 | DG11: 2023/01 | DH11: 2023/02 | DI11: 2023/03 | DJ11: 2023/04 | DK11: 2023/05 | DL11: 2023/06 | DM11: 2023/07 | DN11: 2023/08 | DO11: 2023/09 | DP11: 2023/10 | DQ11: 2023/11 | DR11: 2023/12 | DS11: 2024/01 | DT11: 2024/02 | DU11: 2024/03 | DV11: 2024/04 | DW11: 2024/05 | DX11: 2024/06 | DY11: 2024/07 | DZ11: 2024/08 | EA11: 2024/09 | EB11: 2024/10 | EC11: 2024/11 | ED11: 2024/12 | EE11: 2025/01 | EF11: 2025/02
A12: 10 | B12: 96 | C12: 0.084653542 | D12: 0.020821795 | E12: -0.0067540284 | F12: -0.019868825 | G12: 0.0079043467 | H12: 0.0093593838 | I12: 0.036303937 | J12: 0.043784579 | K12: -0.010988404 | L12: -0.0022772308 | M12: -0.015551804 | N12: 0.052074108 | O12: 0.018629889 | P12: -0.021420421 | Q12: -0.033792784 | R12: 0.013397506 | S12: -0.071053897 | T12: -0.043243489 | U12: -0.020367221 | V12: 0.045029991 | W12: 0.022278442 | X12: 0.048519275 | Y12: -0.016788377 | Z12: 0.063623683 | AA12: -0.039403661 | AB12: 0.034689111 | AC12: 0.035114764 | AD12: 0.00584711 | AE12: -0.037897624 | AF12: 0.020432151 | AG12: 0.029982145 | AH12: 0.021100417 | AI12: 0.023246958 | AJ12: 0.021062375 | AK12: 0.048123704 | AL12: 0.017859003 | AM12: 0.030086116 | AN12: 0.069233234 | AO12: 0.002228793 | AP12: -0.033718345 | AQ12: -0.0076219364 | AR12: 0.013526259 | AS12: -0.0058433646 | AT12: 0.013834905 | AU12: 0.020708659 | AV12: -0.041360085 | AW12: 0.00062147702 | AX12: 0.043598467 | AY12: 0.024955293 | AZ12: -0.0023000261 | BA12: 0.0049378882 | BB12: 0.015274605 | BC12: 0.012272789 | BD12: 0.013630557 | BE12: 0.01860881 | BF12: 0.067792352 | BG12: 0.033670862 | BH12: 0.01422336 | BI12: 0.050021253 | BJ12: -0.00079599332 | BK12: -0.021284665 | BL12: 0.024709246 | BM12: -0.005169092 | BN12: 0.01950225 | BO12: 0.02424631 | BP12: -0.010508985 | BQ12: 0.01389675 | BR12: -0.0022610085 | BS12: 0.018863293 | BT12: 0.022031469 | BU12: -0.0087815171 | BV12: 0.023062456 | BW12: -0.029483769 | BX12: 0.011477162 | BY12: -0.0333708 | BZ12: 0.045356946 | CA12: -0.034400287 | CB12: 0.0019432421 | CC12: -0.016770964 | CD12: 0.11093363 | CE12: 0.15400716 | CF12: 0.0040780417 | CG12: 0.041857234 | CH12: 0.063297372 | CI12: -0.034655912 | CJ12: 0.01544518 | CK12: 0.012803144 | CL12: 0.11801561 | CM12: -0.071708563 | CN12: -0.027083701 | CO12: 0.071291854 | CP12: -0.012795812 | CQ12: 0.036572195 | CR12: 0.0021178784 | CS12: -0.014509312 | CT12: 0.032113958 | CU12: 0.013967375 | CV12: 0.0044034271 | CW12: 0.029757354 | CX12: 0.046547115 | CY12: -0.0059829422 | CZ12: 0.088562469 | DA12: 0.036978521 | DB12: 0.088981854 | DC12: 0.011473052 | DD12: 0.024888978 | DE12: -0.037235479 | DF12: 0.055486104 | DG12: -0.046409979 | DH12: 0.061195427 | DI12: 0.05974901 | DJ12: 0.015118677 | DK12: -0.031928208 | DL12: 0.0030896458 | DM12: -0.019237615 | DN12: 0.021917052 | DO12: 0.03055726 | DP12: 0.04595376 | DQ12: -0.033862052 | DR12: 0.018778943 | DS12: -0.035726155 | DT12: 0.025117865 | DU12: -0.057230229 | DV12: 0.029540875 | DW12: 0.044967552 | DX12: 0.021028542 | DY12: 0.053145313 | DZ12: 0.0062268438 | EA12: 0.051097698 | EB12: 0.0057861667 | EC12: 0.02665151 | ED12: -0.060508153 | EE12: -0.026506688 | EF12: 0.029233396
A13: 20 | B13: 48 | C13: 0.10411315 | D13: 0.029877611 | E13: -0.034496619 | F13: -0.034922156 | G13: -0.01490798 | H13: 0.015930385 | I13: 0.032682863 | J13: 0.034549892 | K13: -0.04533099 | L13: -0.029135669 | M13: 0.0077086563 | N13: 0.043151952 | O13: 0.036273276 | P13: -0.020856913 | Q13: -0.044218264 | R13: 0.0064899102 | S13: -0.1229153 | T13: -0.052899803 | U13: -0.054161075 | V13: 0.052779739 | W13: 0.031103088 | X13: 0.069750969 | Y13: -0.026471883 | Z13: 0.078424435 | AA13: -0.03211951 | AB13: 0.04667822 | AC13: 0.021871556 | AD13: 0.0065790452 | AE13: -0.042517211 | AF13: 0.031940464 | AG13: 0.031681783 | AH13: 0.031874708 | AI13: 0.019910042 | AJ13: 0.019885917 | AK13: 0.065987913 | AL13: 0.023151429 | AM13: 0.046282444 | AN13: 0.10533024 | AO13: 0.0093111879 | AP13: -0.05955084 | AQ13: -0.0060492888 | AR13: 0.010689186 | AS13: -0.0019364167 | AT13: 0.040463088 | AU13: 0.040976126 | AV13: -0.0094754726 | AW13: 0.0040800136 | AX13: 0.067153788 | AY13: 0.017564346 | AZ13: -0.0081034675 | BA13: 0.0065409376 | BB13: 0.042875374 | BC13: 0.011283767 | BD13: 0.0033444284 | BE13: 0.027391806 | BF13: 0.083929415 | BG13: 0.046566462 | BH13: 0.0084757298 | BI13: 0.052409132 | BJ13: -0.016847086 | BK13: -0.018391025 | BL13: 0.03194786 | BM13: 0.016918616 | BN13: -0.0048578333 | BO13: 0.030878716 | BP13: 0.0094326957 | BQ13: 0.041653064 | BR13: -0.0066814175 | BS13: 0.0074194718 | BT13: 0.038343506 | BU13: -0.017706555 | BV13: 0.020653597 | BW13: 0.0017632378 | BX13: 0.021078068 | BY13: -0.014512398 | BZ13: 0.076138123 | CA13: -0.033531566 | CB13: -0.0065958267 | CC13: -0.012530912 | CD13: 0.10508583 | CE13: 0.18382773 | CF13: 0.018229146 | CG13: 0.040449063 | CH13: 0.058334612 | CI13: -0.051853509 | CJ13: -0.003106088 | CK13: 0.032045269 | CL13: 0.081453366 | CM13: -0.10145233 | CN13: -0.026887566 | CO13: 0.085566146 | CP13: -0.034377458 | CQ13: 0.03818495 | CR13: 0.008279781 | CS13: 0.0039479583 | CT13: 0.043462167 | CU13: 0.011031208 | CV13: 0.024319187 | CW13: 0.010456521 | CX13: 0.0049866875 | CY13: -0.01311874 | CZ13: 0.090290625 | DA13: 0.049445771 | DB13: 0.10623525 | DC13: 0.023541125 | DD13: 0.010697601 | DE13: -0.042563896 | DF13: 0.083122687 | DG13: -0.047729313 | DH13: 0.088720708 | DI13: 0.089748125 | DJ13: 0.0059838542 | DK13: -0.019386396 | DL13: 0.027122937 | DM13: 0.00053195833 | DN13: 0.016935375 | DO13: 0.037863854 | DP13: 0.044997146 | DQ13: -0.033966542 | DR13: 0.013771209 | DS13: -0.038887628 | DT13: 0.050831354 | DU13: -0.033005958 | DV13: 0.043256333 | DW13: 0.042028479 | DX13: 0.039877438 | DY13: 0.056981146 | DZ13: 0.018301979 | EA13: 0.062118417 | EB13: 0.00020102083 | EC13: 0.041659753 | ED13: -0.065682094 | EE13: -0.041234375 | EF13: 0.044513042
A14: 50 | B14: 19 | C14: 0.11994163 | D14: 0.083347312 | E14: -0.047525943 | F14: -0.048454143 | G14: -0.041019916 | H14: 0.0076743243 | I14: 0.04378736 | J14: 0.023309972 | K14: -0.1341787 | L14: 0.0048471972 | M14: 0.0049945201 | N14: 0.082758985 | O14: 0.037475787 | P14: -0.058345922 | Q14: -0.12410387 | R14: -0.015941187 | S14: -0.16589323 | T14: -0.06984148 | U14: -0.10426666 | V14: 0.020089127 | W14: 0.074008159 | X14: 0.11326311 | Y14: -0.0052198746 | Z14: 0.038511926 | AA14: -0.03945018 | AB14: 0.070769377 | AC14: -0.013517269 | AD14: -0.012920107 | AE14: -0.10641207 | AF14: 0.040420703 | AG14: 0.020520895 | AH14: 0.063409947 | AI14: 0.010965316 | AJ14: 0.096294684 | AK14: 0.076911431 | AL14: 0.03796919 | AM14: 0.061242166 | AN14: 0.098594667 | AO14: 0.060905705 | AP14: -0.069976525 | AQ14: -0.00036796774 | AR14: 0.03764584 | AS14: 0.0092569474 | AT14: 0.03450658 | AU14: 0.039991649 | AV14: -0.018682885 | AW14: -0.018362932 | AX14: 0.13695103 | AY14: 0.015068119 | AZ14: -0.053348569 | BA14: 0.017621646 | BB14: 0.061734282 | BC14: -0.009820999 | BD14: 0.043327782 | BE14: 0.043787063 | BF14: 0.040770522 | BG14: 0.041374264 | BH14: 0.0053427556 | BI14: 0.050185213 | BJ14: -0.020017224 | BK14: -0.0055937517 | BL14: 0.059737767 | BM14: 0.039257215 | BN14: -0.046576842 | BO14: 0.033609046 | BP14: 0.015673733 | BQ14: 0.015843524 | BR14: -0.02792943 | BS14: -0.041493955 | BT14: 0.074012962 | BU14: 0.0088548354 | BV14: 0.025727182 | BW14: 0.012507948 | BX14: 0.05497076 | BY14: -0.0065962934 | BZ14: 0.060034057 | CA14: -0.024465266 | CB14: 0.022127617 | CC14: -0.012794081 | CD14: 0.09801671 | CE14: 0.17055484 | CF14: -0.020310316 | CG14: 0.053067028 | CH14: 0.064661392 | CI14: -0.10588478 | CJ14: -0.028667855 | CK14: 0.014016364 | CL14: 0.062269955 | CM14: -0.11006784 | CN14: -0.023026689 | CO14: 0.17324926 | CP14: -0.10547974 | CQ14: 0.053211628 | CR14: 0.055909138 | CS14: -0.0038151053 | CT14: 0.061872211 | CU14: 0.074250526 | CV14: 0.039399684 | CW14: 0.0082333684 | CX14: 0.024243895 | CY14: -0.02875912 | CZ14: 0.13617263 | DA14: 0.065392579 | DB14: 0.10460805 | DC14: 0.014753895 | DD14: -0.01675855 | DE14: -0.031057579 | DF14: 0.20156447 | DG14: -0.045583632 | DH14: 0.058742579 | DI14: 0.086646789 | DJ14: 0.015897789 | DK14: -0.081621684 | DL14: -0.0092726842 | DM14: -0.0011206842 | DN14: 0.030299895 | DO14: 0.102592 | DP14: 0.0036181579 | DQ14: -0.056019211 | DR14: 0.052622519 | DS14: -0.035044906 | DT14: 0.11767232 | DU14: -0.068796263 | DV14: 0.019435526 | DW14: 0.0018098947 | DX14: 0.038758158 | DY14: 0.074257842 | DZ14: 0.035030895 | EA14: 0.10752553 | EB14: -0.025110526 | EC14: 0.0060793821 | ED14: -0.10262971 | EE14: 0.0033992632 | EF14: 0.025524211
A15: 100 | B15: 10 | C15: 0.2276451 | D15: 0.016952865 | E15: -0.010198426 | F15: -0.10856229 | G15: -0.060636929 | H15: 0.050157825 | I15: 0.058431444 | J15: 0.049961465 | K15: -0.28659463 | L15: 0.032558505 | M15: 0.025497709 | N15: 0.12086815 | O15: 0.073757344 | P15: -0.064116183 | Q15: -0.15553684 | R15: -0.05212969 | S15: -0.2700079 | T15: -0.066800125 | U15: -0.13696806 | V15: -0.017131853 | W15: 0.10254359 | X15: 0.12684333 | Y15: 0.020629974 | Z15: 0.046719972 | AA15: -0.054081147 | AB15: 0.083700173 | AC15: 0.016480966 | AD15: 0.018936283 | AE15: -0.097797684 | AF15: 0.065819612 | AG15: 0.010123478 | AH15: -0.0145018 | AI15: 0.0742774 | AJ15: 0.0041834 | AK15: 0.06175962 | AL15: 0.044431662 | AM15: 0.055122622 | AN15: 0.10168871 | AO15: 0.063369812 | AP15: -0.078285694 | AQ15: -0.037367127 | AR15: 0.090293855 | AS15: -0.0224308 | AT15: 0.065254991 | AU15: 0.039943261 | AV15: -0.047226818 | AW15: 0.015659939 | AX15: 0.12523398 | AY15: 0.028017064 | AZ15: -0.09132328 | BA15: 0.010613515 | BB15: 0.11272487 | BC15: 0.062155144 | BD15: 0.053043274 | BE15: 0.048442721 | BF15: 0.047662979 | BG15: 0.0024895387 | BH15: 0.034441845 | BI15: 0.068586659 | BJ15: -0.011265027 | BK15: 0.00082375227 | BL15: 0.059403871 | BM15: 0.066824821 | BN15: -0.0660549 | BO15: 0.027734476 | BP15: 0.014184221 | BQ15: 0.012802931 | BR15: -0.050157429 | BS15: -0.016823777 | BT15: 0.089060206 | BU15: -0.01947642 | BV15: 0.058914968 | BW15: -0.03594589 | BX15: 0.028635895 | BY15: -0.061694091 | BZ15: 0.10290647 | CA15: -0.018592021 | CB15: 0.015056894 | CC15: -0.15231827 | CD15: 0.12015208 | CE15: 0.0733674 | CF15: -0.0036264 | CG15: -0.0042988793 | CH15: 0.062885958 | CI15: -0.038798415 | CJ15: -0.087044356 | CK15: 0.056672646 | CL15: 0.031421975 | CM15: -0.1081179 | CN15: -0.042634116 | CO15: 0.1733599 | CP15: -0.0343934 | CQ15: 0.037378011 | CR15: 0.04823707 | CS15: 0.0169124 | CT15: 0.0322169 | CU15: 0.1538636 | CV15: 0.060444 | CW15: -0.0272589 | CX15: 0.0178681 | CY15: -0.042470673 | CZ15: 0.1153667 | DA15: 0.0888618 | DB15: 0.0970477 | DC15: 0.0767265 | DD15: -0.04939369 | DE15: -0.0656079 | DF15: 0.3027216 | DG15: -0.0479178 | DH15: 0.1296235 | DI15: 0.042811 | DJ15: 0.0475665 | DK15: -0.100329 | DL15: 0.0077392 | DM15: 0.0017735 | DN15: -0.0670202 | DO15: 0.1595456 | DP15: -0.0403292 | DQ15: -0.0729378 | DR15: 0.070010567 | DS15: -0.076241908 | DT15: 0.0342967 | DU15: -0.1171285 | DV15: 0.0511299 | DW15: -0.0608268 | DX15: 0.0279597 | DY15: 0.1436096 | DZ15: 0.0404552 | EA15: 0.1091777 | EB15: -0.056129 | EC15: 0.066081856 | ED15: -0.11335706 | EE15: -0.0031902 | EF15: 0.0296441
A16: 107 | B16: 9 | C16: 0.20787511 | D16: -0.00072024867 | E16: -0.0028301766 | F16: -0.099382493 | G16: -0.073696265 | H16: 0.060999005 | I16: 0.057530619 | J16: 0.046709926 | K16: -0.28467055 | L16: 0.0098865346 | M16: 0.040334455 | N16: 0.12567063 | O16: 0.079826861 | P16: -0.061045232 | Q16: -0.15790307 | R16: -0.048990978 | S16: -0.28706302 | T16: -0.06721906 | U16: -0.13006247 | V16: -0.0060221453 | W16: 0.10166568 | X16: 0.12440978 | Y16: 0.020180588 | Z16: 0.043057931 | AA16: -0.043487636 | AB16: 0.074985042 | AC16: 0.047226236 | AD16: 0.0011220258 | AE16: -0.09650236 | AF16: 0.063685843 | AG16: 0.013290753 | AH16: -0.044108444 | AI16: 0.090523111 | AJ16: -0.01763 | AK16: 0.064421401 | AL16: 0.048688933 | AM16: 0.066076731 | AN16: 0.1064562 | AO16: 0.061424672 | AP16: -0.077798368 | AQ16: -0.0384662 | AR16: 0.10329118 | AS16: -0.028078667 | AT16: 0.049547155 | AU16: 0.041826838 | AV16: -0.0090725068 | AW16: 0.03925293 | AX16: 0.10082977 | AY16: 0.03381259 | AZ16: -0.10490964 | BA16: 0.014923105 | BB16: 0.10803892 | BC16: 0.067121466 | BD16: 0.035936712 | BE16: 0.051410994 | BF16: 0.064268054 | BG16: 0.013473282 | BH16: -0.013775614 | BI16: 0.041443808 | BJ16: -0.020503816 | BK16: 0.0029719903 | BL16: 0.070623566 | BM16: 0.081523875 | BN16: -0.067199333 | BO16: 0.02189036 | BP16: 0.020843184 | BQ16: 0.016478016 | BR16: -0.026296848 | BS16: -0.013191573 | BT16: 0.085483191 | BU16: -0.05776511 | BV16: 0.060711239 | BW16: -0.065740927 | BX16: 0.031559238 | BY16: -0.050563733 | BZ16: 0.11152585 | CA16: -0.02971439 | CB16: -0.001428045 | CC16: -0.15907251 | CD16: 0.15507127 | CE16: 0.093613778 | CF16: -0.014696 | CG16: -0.005378519 | CH16: 0.041697415 | CI16: -0.038709882 | CJ16: -0.045523551 | CK16: 0.076472984 | CL16: 0.015878682 | CM16: -0.11305433 | CN16: -0.033057515 | CO16: 0.209547 | CP16: -0.030684556 | CQ16: 0.041435606 | CR16: 0.048299767 | CS16: 0.021808222 | CT16: 0.048903889 | CU16: 0.15404611 | CV16: 0.059453444 | CW16: -0.031674667 | CX16: 0.0066858889 | CY16: -0.049117049 | CZ16: 0.16622078 | DA16: 0.11818056 | DB16: 0.098016667 | DC16: 0.063740111 | DD16: -0.070070935 | DE16: -0.056325333 | DF16: 0.32558089 | DG16: -0.045677 | DH16: 0.13714944 | DI16: 0.047828778 | DJ16: 0.051753111 | DK16: -0.096254333 | DL16: 0.0013668889 | DM16: 0.038135333 | DN16: -0.056705778 | DO16: 0.16959067 | DP16: -0.024715444 | DQ16: -0.06756 | DR16: 0.055191252 | DS16: -0.093752065 | DT16: 0.032059333 | DU16: -0.122773 | DV16: 0.045151778 | DW16: -0.071303111 | DX16: 0.037507111 | DY16: 0.15757178 | DZ16: 0.058810444 | EA16: 0.13979989 | EB16: -0.070877778 | EC16: 0.063532067 | ED16: -0.11541675 | EE16: -0.0043961111 | EF16: 0.034548444
A17: 120 | B17: 8 | C17: 0.20609237 | D17: -0.017334375 | E17: 0.0073790015 | F17: -0.11283752 | G17: -0.071222767 | H17: 0.076687822 | I17: 0.11372503 | J17: 0.041858395 | K17: -0.29682655 | L17: 0.0097108895 | M17: 0.064932035 | N17: 0.13594843 | O17: 0.10122677 | P17: -0.066339369 | Q17: -0.16180129 | R17: -0.052057609 | S17: -0.31065343 | T17: -0.071202015 | U17: -0.14127114 | V17: 0.0040111898 | W17: 0.11960398 | X17: 0.1168462 | Y17: 0.022928011 | Z17: 0.053868489 | AA17: -0.03520979 | AB17: 0.084852063 | AC17: 0.05872869 | AD17: 0.021912844 | AE17: -0.12715842 | AF17: 0.06142931 | AG17: 0.022740981 | AH17: -0.031922875 | AI17: 0.11486512 | AJ17: -0.02220825 | AK17: 0.073716275 | AL17: 0.050724406 | AM17: 0.075369368 | AN17: 0.11328712 | AO17: 0.012632335 | AP17: -0.077242814 | AQ17: -0.060527137 | AR17: 0.11393071 | AS17: -0.029516 | AT17: 0.052267806 | AU17: 0.054555507 | AV17: -0.021205903 | AW17: 0.008421888 | AX17: 0.096240559 | AY17: 0.027423697 | AZ17: -0.1251576 | BA17: 0.0098251791 | BB17: 0.12376406 | BC17: 0.083863195 | BD17: 0.022356482 | BE17: 0.077350242 | BF17: 0.055197497 | BG17: -0.035394236 | BH17: 0.013519461 | BI17: 0.087111945 | BJ17: -0.0098580643 | BK17: -0.013822952 | BL17: 0.077482967 | BM17: 0.07599777 | BN17: -0.073658 | BO17: 0.035179615 | BP17: 0.03599598 | BQ17: 0.01137651 | BR17: -0.0096463751 | BS17: -0.0041034691 | BT17: 0.10941638 | BU17: -0.071127819 | BV17: 0.070210303 | BW17: -0.080431713 | BX17: 0.028822965 | BY17: -0.084245468 | BZ17: 0.12057816 | CA17: -0.027934832 | CB17: -0.010477707 | CC17: -0.17495797 | CD17: 0.17295974 | CE17: 0.095707625 | CF17: -0.09512375 | CG17: -0.015527105 | CH17: 0.058636447 | CI17: -0.014531185 | CJ17: -0.050742321 | CK17: 0.091738573 | CL17: -0.0094263448 | CM17: -0.095492625 | CN17: -0.026718061 | CO17: 0.19808038 | CP17: -0.02161 | CQ17: 0.041087933 | CR17: 0.050676491 | CS17: 0.011546625 | CT17: 0.05865425 | CU17: 0.051108875 | CV17: 0.067891375 | CW17: -0.023157 | CX17: 0.0249915 | CY17: -0.049383299 | CZ17: 0.18413588 | DA17: 0.094495625 | DB17: 0.104271 | DC17: 0.0538875 | DD17: -0.085133933 | DE17: -0.051665375 | DF17: 0.35222738 | DG17: -0.047211125 | DH17: 0.16343337 | DI17: 0.07018125 | DJ17: 0.057146375 | DK17: -0.10277988 | DL17: -0.00578975 | DM17: 0.0425635 | DN17: -0.0606265 | DO17: 0.179762 | DP17: -0.025096125 | DQ17: -0.065244 | DR17: 0.055884815 | DS17: -0.12431616 | DT17: 0.016743 | DU17: -0.129494 | DV17: 0.062272375 | DW17: -0.07659975 | DX17: 0.044121875 | DY17: 0.10728225 | DZ17: 0.049212 | EA17: 0.16457237 | EB17: -0.073783625 | EC17: 0.016425217 | ED17: -0.12832444 | EE17: 0.000194375 | EF17: 0.04098475
A18: 137 | B18: 7 | C18: 0.18975114 | D18: -0.0081874671 | E18: -0.059000657 | F18: -0.13441437 | G18: -0.080794247 | H18: 0.12191279 | I18: 0.13550018 | J18: 0.043411516 | K18: -0.3586821 | L18: 0.012982487 | M18: 0.079702577 | N18: 0.14299243 | O18: 0.10367049 | P18: -0.082552612 | Q18: -0.18897542 | R18: -0.061492238 | S18: -0.38373263 | T18: -0.05424444 | U18: -0.13249502 | V18: 0.012895135 | W18: 0.13791724 | X18: 0.14345152 | Y18: 0.019232334 | Z18: 0.089234363 | AA18: -0.041705245 | AB18: 0.0846983 | AC18: 0.057823013 | AD18: 0.02659559 | AE18: -0.14352924 | AF18: 0.031873418 | AG18: 0.032493116 | AH18: -0.035914857 | AI18: 0.11808643 | AJ18: -0.0073281429 | AK18: 0.030152481 | AL18: 0.047527764 | AM18: 0.066643405 | AN18: 0.07929464 | AO18: 0.005427535 | AP18: -0.078278592 | AQ18: -0.076230845 | AR18: 0.12454551 | AS18: -0.045373286 | AT18: 0.04332565 | AU18: 0.064575644 | AV18: -0.028768756 | AW18: 0.024538034 | AX18: 0.10756087 | AY18: 0.034783279 | AZ18: -0.14840908 | BA18: 0.00063231092 | BB18: 0.13765604 | BC18: 0.083201573 | BD18: -0.024016272 | BE18: 0.068361213 | BF18: 0.045884536 | BG18: -0.016806241 | BH18: 0.020503853 | BI18: 0.10900001 | BJ18: 0.0059560641 | BK18: -0.058003244 | BL18: 0.081157674 | BM18: 0.10277394 | BN18: -0.078210143 | BO18: 0.020227496 | BP18: 0.04685754 | BQ18: 0.0019167841 | BR18: -0.0057481936 | BS18: -0.0039836251 | BT18: 0.11523675 | BU18: -0.080677444 | BV18: 0.080923395 | BW18: -0.085311087 | BX18: 0.019018475 | BY18: -0.12307498 | BZ18: 0.15331999 | CA18: -0.016076544 | CB18: -0.024577357 | CC18: -0.028173444 | CD18: 0.19371682 | CE18: 0.077259857 | CF18: -0.101859 | CG18: -0.0028013589 | CH18: 0.16265705 | CI18: -0.03886914 | CJ18: -0.062313678 | CK18: 0.090667784 | CL18: -0.030989545 | CM18: -0.10276871 | CN18: -0.035086254 | CO18: 0.228282 | CP18: -0.015498143 | CQ18: 0.047976536 | CR18: 0.055156129 | CS18: 0.028129286 | CT18: 0.076870857 | CU18: 0.0047417143 | CV18: 0.062944429 | CW18: -0.028329429 | CX18: -0.014079286 | CY18: -0.051357414 | CZ18: 0.20441243 | DA18: 0.078357857 | DB18: 0.118114 | DC18: 0.049208571 | DD18: -0.082462353 | DE18: -0.039306714 | DF18: 0.36669357 | DG18: -0.054770714 | DH18: 0.19240257 | DI18: 0.097962857 | DJ18: 0.050655 | DK18: -0.10652586 | DL18: -0.023409571 | DM18: 0.058456714 | DN18: -0.056873143 | DO18: 0.22031957 | DP18: -0.021509857 | DQ18: -0.061954714 | DR18: 0.076840655 | DS18: -0.147722 | DT18: -0.0074077143 | DU18: -0.15871543 | DV18: 0.085405857 | DW18: -0.068637857 | DX18: 0.061783714 | DY18: 0.13683229 | DZ18: 0.054629714 | EA18: 0.19894729 | EB18: -0.097045 | EC18: 0.0027641154 | ED18: -0.11047802 | EE18: -0.0011102857 | EF18: 0.063951857
A19: 160 | B19: 6 | C19: 0.19659983 | D19: -0.020170799 | E19: -0.054898094 | F19: -0.038646682 | G19: -0.097512091 | H19: 0.14889412 | I19: 0.13465433 | J19: 0.035429585 | K19: -0.41833785 | L19: 0.043048958 | M19: 0.086210339 | N19: 0.095347886 | O19: 0.092221383 | P19: -0.092534186 | Q19: -0.19716309 | R19: -0.090299091 | S19: -0.18416012 | T19: -0.027154278 | U19: -0.13569834 | V19: 0.036618688 | W19: 0.14662099 | X19: 0.11663905 | Y19: 0.025628638 | Z19: 0.091619111 | AA19: -0.041570185 | AB19: 0.10225361 | AC19: 0.028452835 | AD19: 0.035088929 | AE19: -0.16941606 | AF19: 0.038785667 | AG19: 0.022136219 | AH19: -0.016091333 | AI19: 0.091549333 | AJ19: 0.012166333 | AK19: 0.0075520425 | AL19: 0.070270946 | AM19: 0.043106012 | AN19: 0.083568294 | AO19: 0.025892903 | AP19: -0.08757412 | AQ19: -0.088252757 | AR19: 0.15351756 | AS19: -0.003687 | AT19: 0.049294982 | AU19: 0.076428716 | AV19: -0.050033021 | AW19: 0.022356168 | AX19: 0.080206414 | AY19: 0.02952897 | AZ19: -0.18687962 | BA19: -0.034363884 | BB19: 0.1597462 | BC19: 0.064055486 | BD19: -0.0032343926 | BE19: 0.051131874 | BF19: 0.013570974 | BG19: -0.016343658 | BH19: 0.0020182017 | BI19: 0.12779863 | BJ19: 0.021707302 | BK19: -0.051749526 | BL19: 0.079964658 | BM19: 0.1142506 | BN19: -0.081415167 | BO19: 0.025728961 | BP19: 0.062818808 | BQ19: 0.0099340445 | BR19: 0.006675246 | BS19: -0.024256339 | BT19: 0.14163268 | BU19: -0.075936251 | BV19: 0.093655241 | BW19: -0.10896696 | BX19: 0.034087785 | BY19: -0.10764974 | BZ19: 0.068702125 | CA19: -0.029328755 | CB19: -0.048041169 | CC19: -0.024723253 | CD19: 0.2156192 | CE19: 0.088474167 | CF19: -0.11169867 | CG19: -0.05063353 | CH19: 0.15288987 | CI19: -0.037066946 | CJ19: -0.0619405 | CK19: 0.10396772 | CL19: -0.04324028 | CM19: -0.11023517 | CN19: -0.076932655 | CO19: 0.25123567 | CP19: -0.029037 | CQ19: -0.0027299082 | CR19: 0.04969419 | CS19: 0.043775667 | CT19: 0.026422 | CU19: 0.0071573333 | CV19: 0.0761435 | CW19: -0.0321935 | CX19: 0.0011275 | CY19: -0.07092187 | CZ19: 0.1580145 | DA19: 0.0751825 | DB19: 0.147961 | DC19: 0.030276667 | DD19: -0.10625734 | DE19: -0.0060055 | DF19: 0.20550283 | DG19: -0.0663745 | DH19: 0.22459133 | DI19: 0.10846167 | DJ19: 0.080500333 | DK19: -0.12144067 | DL19: -0.023312833 | DM19: 0.057299833 | DN19: -0.064292 | DO19: 0.24926117 | DP19: -0.0040015 | DQ19: -0.0506225 | DR19: 0.075962353 | DS19: -0.17799555 | DT19: -0.0030765 | DU19: -0.1505825 | DV19: 0.038127167 | DW19: -0.101297 | DX19: 0.1082645 | DY19: 0.139248 | DZ19: 0.0785375 | EA19: 0.23304767 | EB19: -0.1062485 | EC19: -0.012190043 | ED19: -0.15093532 | EE19: 0.0073063333 | EF19: 0.07402
A20: 192 | B20: 5 | C20: 0.201551 | D20: 0.00035171826 | E20: 0.015499988 | F20: -0.091218422 | G20: -0.10036591 | H20: 0.164372 | I20: 0.15814956 | J20: 0.034471259 | K20: -0.090108654 | L20: 0.095708636 | M20: 0.10013341 | N20: 0.10192493 | O20: 0.099101484 | P20: -0.091169928 | Q20: -0.21672574 | R20: -0.10925306 | S20: -0.15518262 | T20: 0.015662911 | U20: -0.14864968 | V20: 0.012644103 | W20: 0.17308538 | X20: 0.1486972 | Y20: 0.04206749 | Z20: 0.10561696 | AA20: -0.021594553 | AB20: 0.084759841 | AC20: 0.056443346 | AD20: 0.034453903 | AE20: -0.19929286 | AF20: 0.039044678 | AG20: 0.027659219 | AH20: -0.027809 | AI20: 0.1163372 | AJ20: 0.0172406 | AK20: -0.013595115 | AL20: 0.072893452 | AM20: 0.033095981 | AN20: 0.075470194 | AO20: 0.045285082 | AP20: -0.13173046 | AQ20: 0.027452485 | AR20: 0.170049 | AS20: -0.0171428 | AT20: 0.0058587738 | AU20: 0.075692387 | AV20: -0.054625714 | AW20: 0.0068652682 | AX20: 0.11073255 | AY20: 0.038674698 | AZ20: -0.21380243 | BA20: -0.036798865 | BB20: 0.16765542 | BC20: 0.070605568 | BD20: -0.053429813 | BE20: -0.0059467971 | BF20: 0.0056885823 | BG20: -0.0069261427 | BH20: -0.071606447 | BI20: 0.13174527 | BJ20: 0.021629512 | BK20: -0.059233168 | BL20: 0.086292231 | BM20: 0.13691766 | BN20: 0.018636 | BO20: -0.038461718 | BP20: 0.060407521 | BQ20: 0.015451707 | BR20: 0.012073632 | BS20: 0.0054075062 | BT20: 0.14780303 | BU20: -0.098754949 | BV20: 0.11591833 | BW20: -0.13550325 | BX20: 0.030693637 | BY20: -0.10523397 | BZ20: 0.090271404 | CA20: -0.040102728 | CB20: -0.03825195 | CC20: -0.026043034 | CD20: 0.1810275 | CE20: 0.0857774 | CF20: -0.1312084 | CG20: -0.099052889 | CH20: 0.071864026 | CI20: -0.030394674 | CJ20: -0.12344032 | CK20: 0.090978397 | CL20: -0.092184934 | CM20: -0.0967742 | CN20: 0.022159411 | CO20: 0.2965734 | CP20: 0.0074242 | CQ20: 0.0061113579 | CR20: 0.073116245 | CS20: 0.0222938 | CT20: 0.0284154 | CU20: 0.0102228 | CV20: 0.0970042 | CW20: -0.0258182 | CX20: 0.009387 | CY20: -0.012479733 | CZ20: 0.1283034 | DA20: 0.0770816 | DB20: 0.076967 | DC20: 0.028902 | DD20: -0.14810881 | DE20: -0.0304664 | DF20: 0.2455754 | DG20: -0.0523458 | DH20: 0.2782996 | DI20: 0.137596 | DJ20: 0.0812774 | DK20: -0.0851846 | DL20: 0.0101866 | DM20: 0.0693358 | DN20: -0.0644584 | DO20: 0.258001 | DP20: -0.0216698 | DQ20: -0.038539 | DR20: 0.07851266 | DS20: -0.2060811 | DT20: 0.0048288 | DU20: -0.1763758 | DV20: -0.0301902 | DW20: -0.1035466 | DX20: 0.1459842 | DY20: 0.1215906 | DZ20: 0.0901994 | EA20: 0.2936912 | EB20: -0.1063144 | EC20: 0.034049581 | ED20: -0.17691886 | EE20: 0.0017416 | EF20: 0.0858
A21: 241 | B21: 4 | C21: 0.2146305 | D21: -0.0003677094 | E21: -0.00027935227 | F21: -0.051097484 | G21: -0.007296138 | H21: 0.19866806 | I21: 0.14725561 | J21: 0.060435326 | K21: -0.088973017 | L21: 0.10967961 | M21: 0.07566065 | N21: 0.099587412 | O21: 0.12978246 | P21: -0.1447726 | Q21: -0.25731007 | R21: -0.095575311 | S21: -0.12859029 | T21: -0.014040364 | U21: -0.086278418 | V21: 0.053557619 | W21: 0.15778848 | X21: 0.19733718 | Y21: 0.020833083 | Z21: 0.11420399 | AA21: 0.019491044 | AB21: 0.12983958 | AC21: 0.07430113 | AD21: 0.046697425 | AE21: -0.24045611 | AF21: 0.05312561 | AG21: 0.044302778 | AH21: -0.04340925 | AI21: 0.10212425 | AJ21: 0.0051835 | AK21: -0.035803168 | AL21: 0.065379823 | AM21: 0.068535807 | AN21: 0.11195606 | AO21: 0.047726396 | AP21: -0.072535144 | AQ21: 0.076865507 | AR21: 0.20518228 | AS21: 0.017048 | AT21: -0.0024929113 | AU21: 0.047809632 | AV21: -0.05552078 | AW21: 0.00979103 | AX21: 0.14314769 | AY21: 0.047021291 | AZ21: -0.25491127 | BA21: -0.071032182 | BB21: 0.22534614 | BC21: 0.038321148 | BD21: -0.021750863 | BE21: 0.0063505334 | BF21: 0.0035771002 | BG21: 0.036635189 | BH21: -0.076321363 | BI21: 0.1659696 | BJ21: 0.023579026 | BK21: -0.06844988 | BL21: 0.14272109 | BM21: 0.15512 | BN21: 0.02578825 | BO21: -0.063857236 | BP21: 0.10450913 | BQ21: 0.054542231 | BR21: 0.012323862 | BS21: 0.0058601728 | BT21: 0.13224469 | BU21: -0.13549646 | BV21: 0.142143 | BW21: -0.1466792 | BX21: -0.0029908193 | BY21: -0.050379851 | BZ21: 0.047662929 | CA21: -0.060517603 | CB21: -0.063421391 | CC21: -0.046693549 | CD21: 0.28805606 | CE21: 0.0615145 | CF21: -0.127168 | CG21: -0.14375119 | CH21: 0.080100321 | CI21: -0.080499616 | CJ21: -0.085627757 | CK21: 0.12705055 | CL21: -0.13389042 | CM21: -0.11623025 | CN21: 0.03053889 | CO21: 0.335483 | CP21: -0.09625275 | CQ21: 0.0032880917 | CR21: 0.090824278 | CS21: 0.03090725 | CT21: 0.04799475 | CU21: 0.00199725 | CV21: 0.13162775 | CW21: -0.03075275 | CX21: 0.01339875 | CY21: -0.0084819164 | CZ21: 0.19029675 | DA21: 0.04170975 | DB21: 0.0714595 | DC21: 0.04831 | DD21: 0.12132269 | DE21: -0.054719 | DF21: 0.30115175 | DG21: -0.05941075 | DH21: 0.081437 | DI21: 0.17984 | DJ21: 0.07330325 | DK21: -0.09089325 | DL21: 0.03220775 | DM21: 0.02498825 | DN21: -0.04687175 | DO21: 0.33162625 | DP21: -0.03710675 | DQ21: -0.02821525 | DR21: 0.050170859 | DS21: -0.20083947 | DT21: -0.0097095 | DU21: -0.14861475 | DV21: -0.049661 | DW21: -0.103536 | DX21: 0.11451475 | DY21: 0.16673 | DZ21: 0.09893 | EA21: 0.26605775 | EB21: -0.103298 | EC21: 0.014037055 | ED21: -0.054498856 | EE21: -0.02131 | EF21: 0.0287945
A22: 321 | B22: 3 | C22: 0.20528267 | D22: -0.044680897 | E22: -0.041027532 | F22: -0.097433996 | G22: -0.032954824 | H22: 0.17874946 | I22: 0.12349317 | J22: 0.052598589 | K22: -0.15328677 | L22: 0.17118336 | M22: -0.22515861 | N22: 0.13328042 | O22: 0.14348035 | P22: -0.072782884 | Q22: -0.27677689 | R22: -0.036628434 | S22: -0.16964656 | T22: -0.020238612 | U22: -0.11059002 | V22: 0.038286777 | W22: 0.20748027 | X22: 0.21490005 | Y22: 0.015732208 | Z22: 0.075548269 | AA22: 0.0070480169 | AB22: 0.13443621 | AC22: 0.074420381 | AD22: 0.012467303 | AE22: -0.22862111 | AF22: 0.047182316 | AG22: 0.05284154 | AH22: 0.00048666667 | AI22: 0.11100467 | AJ22: 0.013081333 | AK22: 0.10128856 | AL22: 0.040340967 | AM22: 0.084088903 | AN22: 0.11113281 | AO22: 0.074717373 | AP22: -0.062536354 | AQ22: 0.079426117 | AR22: 0.25053268 | AS22: 0.16459067 | AT22: -0.025136362 | AU22: 0.033500452 | AV22: -0.059813177 | AW22: -0.030149389 | AX22: 0.1737634 | AY22: 0.071733385 | AZ22: -0.15490378 | BA22: -0.045598425 | BB22: 0.30192994 | BC22: -0.13083694 | BD22: -0.022174181 | BE22: 0.022216183 | BF22: 0.013638817 | BG22: 0.046279512 | BH22: -0.12796054 | BI22: 0.11108872 | BJ22: 0.054996415 | BK22: -0.041839636 | BL22: 0.16178034 | BM22: 0.19179704 | BN22: 0.082934333 | BO22: -0.050484429 | BP22: 0.07483555 | BQ22: 0.027830097 | BR22: 0.020813609 | BS22: -0.016372782 | BT22: 0.1305307 | BU22: -0.21294877 | BV22: 0.15854397 | BW22: -0.1746685 | BX22: 0.036637446 | BY22: -0.0047467864 | BZ22: 0.047257736 | CA22: -0.027490078 | CB22: -0.14899328 | CC22: -0.014985703 | CD22: 0.33387804 | CE22: 0.06684 | CF22: -0.15557067 | CG22: -0.20326309 | CH22: 0.11591877 | CI22: -0.11777975 | CJ22: -0.10337951 | CK22: 0.036163343 | CL22: -0.2406518 | CM22: -0.21983 | CN22: -0.0085467718 | CO22: 0.272059 | CP22: -0.081321667 | CQ22: -0.012333779 | CR22: 0.16185042 | CS22: 0.024439333 | CT22: 0.038264667 | CU22: 0.026580667 | CV22: 0.18304533 | CW22: -0.0135 | CX22: 0.047288333 | CY22: -0.0079888258 | CZ22: 0.206697 | DA22: 0.032454 | DB22: 0.054040667 | DC22: 0.072343333 | DD22: 0.1478941 | DE22: -0.13335567 | DF22: 0.389668 | DG22: -0.071891 | DH22: 0.081455333 | DI22: 0.060122333 | DJ22: 0.042777667 | DK22: -0.091427667 | DL22: 0.021680333 | DM22: 0.031884333 | DN22: -0.083170333 | DO22: 0.075715333 | DP22: -0.105099 | DQ22: -0.051849333 | DR22: -0.0060925526 | DS22: -0.19705092 | DT22: -0.043682333 | DU22: -0.16154567 | DV22: 0.053372 | DW22: -0.081416 | DX22: 0.177263 | DY22: 0.11995633 | DZ22: 0.11083367 | EA22: 0.14035633 | EB22: -0.14293033 | EC22: 0.021495102 | ED22: -0.077413567 | EE22: -0.047636 | EF22: 0.036592667
A23: 482 | B23: 2 | C23: 0.282989 | D23: -0.029810668 | E23: -0.080941173 | F23: -0.14166491 | G23: -0.052224174 | H23: 0.20371831 | I23: 0.14815203 | J23: -0.098162291 | K23: -0.20448948 | L23: 0.05404353 | M23: -0.26256935 | N23: 0.15641924 | O23: 0.20456438 | P23: -0.090401711 | Q23: 0.059568017 | R23: -0.056211143 | S23: -0.11372453 | T23: -0.00037336921 | U23: -0.093757422 | V23: -0.023029457 | W23: 0.33161915 | X23: 0.26408569 | Y23: 0.014659802 | Z23: 0.033032515 | AA23: 0.006606292 | AB23: 0.06403978 | AC23: 0.076346338 | AD23: 0.0150109 | AE23: -0.33234425 | AF23: 0.06690626 | AG23: 0.091873658 | AH23: 0.037278 | AI23: 0.209152 | AJ23: 0.023587 | AK23: 0.1141111 | AL23: 0.13143171 | AM23: 0.007769489 | AN23: 0.2423147 | AO23: -0.0053369522 | AP23: 0.0031210994 | AQ23: 0.089424992 | AR23: 0.33674404 | AS23: 0.032169 | AT23: -0.041427722 | AU23: 0.033145526 | AV23: -0.027638994 | AW23: -0.05202691 | AX23: 0.069838154 | AY23: 0.17023398 | AZ23: -0.063753617 | BA23: 0.0096467801 | BB23: -0.051049484 | BC23: -0.30082825 | BD23: 0.094830881 | BE23: -0.071430762 | BF23: -0.022846991 | BG23: 0.074761471 | BH23: -0.20348398 | BI23: 0.19111208 | BJ23: 0.10400332 | BK23: 0.0020341083 | BL23: 0.1495343 | BM23: 0.18918069 | BN23: 0.03845 | BO23: 0.036524942 | BP23: 0.098266399 | BQ23: 0.072047901 | BR23: 0.017844321 | BS23: -0.073275389 | BT23: 0.14364981 | BU23: -0.20568774 | BV23: 0.11346757 | BW23: -0.20215233 | BX23: -0.0082131197 | BY23: -0.010205693 | BZ23: 0.0076697624 | CA23: -0.0756532 | CB23: -0.2176142 | CC23: 0.22495863 | CD23: 0.19167646 | CE23: 0.059602 | CF23: -0.1834305 | CG23: -0.39324379 | CH23: 0.18019645 | CI23: -0.30989942 | CJ23: -0.019875368 | CK23: 0.096116995 | CL23: -0.40866101 | CM23: -0.234705 | CN23: -0.053005178 | CO23: 0.2661575 | CP23: -0.1197175 | CQ23: -0.0091837445 | CR23: 0.011597804 | CS23: 0.069015 | CT23: 0.0653915 | CU23: -0.008776 | CV23: 0.2018495 | CW23: 0.064165 | CX23: -0.04425 | CY23: 0.022046531 | CZ23: 0.1660055 | DA23: 0.064645 | DB23: 0.018748 | DC23: 0.072415 | DD23: 0.21341104 | DE23: -0.1414445 | DF23: 0.4087975 | DG23: -0.0676225 | DH23: 0.139228 | DI23: 0.096041 | DJ23: -0.033823 | DK23: -0.0912435 | DL23: -0.056606 | DM23: 0.046477 | DN23: -0.1182 | DO23: 0.124068 | DP23: -0.0384035 | DQ23: -0.1211305 | DR23: -0.089886003 | DS23: -0.28809658 | DT23: -0.0542505 | DU23: -0.055638 | DV23: 0.008133 | DW23: 0.0230525 | DX23: 0.3194485 | DY23: -0.053925 | DZ23: -0.217175 | EA23: -0.028757 | EB23: -0.1382285 | EC23: -0.036584316 | ED23: -0.091425905 | EE23: -0.069211 | EF23: 0.093414
A24: 964 | B24: 1 | C24: 0.099113 | D24: -0.10404901 | E24: 0.07140033 | F24: -0.22715955 | G24: 0.22576002 | H24: 0.24668673 | I24: -0.0021119332 | J24: -0.099972193 | K24: -0.021515278 | L24: 0.095623251 | M24: -0.46302754 | N24: 0.14413045 | O24: 0.23530919 | P24: -0.10424841 | Q24: 0.060964962 | R24: -0.24569737 | S24: -0.35251446 | T24: 0.12369104 | U24: -0.14851867 | V24: -0.067139303 | W24: 0.49571199 | X24: 0.11802243 | Y24: 0.0094770149 | Z24: 0.10584233 | AA24: 0.013547768 | AB24: 0.19533962 | AC24: 0.12538038 | AD24: 0.0078218389 | AE24: -0.54125812 | AF24: 0.02252201 | AG24: 0.13873572 | AH24: -0.068617 | AI24: 0.310414 | AJ24: 0.085435 | AK24: 0.084883953 | AL24: -0.054676935 | AM24: -0.018919281 | AN24: 0.22118947 | AO24: 0.066090112 | AP24: -0.022851715 | AQ24: 0.047076973 | AR24: 0.0096392566 | AS24: 0.237832 | AT24: 0.030459207 | AU24: 0.04409532 | AV24: -0.087151952 | AW24: 0.0049875415 | AX24: 0.028306187 | AY24: 0.16812729 | AZ24: 0.037867074 | BA24: -0.053794732 | BB24: -0.086159033 | BC24: -0.80321601 | BD24: 0.18559522 | BE24: -0.046064354 | BF24: 0.087651336 | BG24: 0.026835966 | BH24: -0.38625534 | BI24: 0.22362911 | BJ24: 0.0033483158 | BK24: 0.0040235469 | BL24: 0.31716429 | BM24: 0.011473019 | BN24: 0.108911 | BO24: -0.16110969 | BP24: 0.12335118 | BQ24: -0.064169633 | BR24: 0.042356223 | BS24: -0.0012847175 | BT24: 0.1162707 | BU24: -0.22832663 | BV24: 0.10772845 | BW24: -0.061835884 | BX24: -0.13296006 | BY24: 0.10974567 | BZ24: 0.2588929 | CA24: -0.11522168 | CB24: 0.20876197 | CC24: 0.43985451 | CD24: 0.14430631 | CE24: 0.165565 | CF24: -0.16513 | CG24: -0.32381798 | CH24: 0.3542773 | CI24: 0.32845182 | CJ24: 0.013109485 | CK24: 0.093530079 | CL24: 0.14175533 | CM24: -0.63644 | CN24: -0.10773877 | CO24: 0.452474 | CP24: -0.249337 | CQ24: 0.11468717 | CR24: 0.061084838 | CS24: -0.026858 | CT24: -0.119542 | CU24: -0.006302 | CV24: 0.361476 | CW24: -0.00159 | CX24: 0.05277 | CY24: -0.080066905 | CZ24: 0.322591 | DA24: 0.03398 | DB24: -0.0165 | DC24: 0.17955 | DD24: 0.15338138 | DE24: -0.306639 | DF24: 0.525588 | DG24: -0.119545 | DH24: 0.265805 | DI24: 0.037185 | DJ24: 0.02108 | DK24: -0.119679 | DL24: -0.031749 | DM24: 0.00041 | DN24: -0.14903 | DO24: 0.115615 | DP24: -0.144327 | DQ24: -0.050486 | DR24: -0.02051563 | DS24: -0.21626154 | DT24: -0.074733 | DU24: 0.021782 | DV24: 0.098047 | DW24: 0.101183 | DX24: 0.285929 | DY24: -0.00324 | DZ24: -0.43351 | EA24: -0.054917 | EB24: -0.109231 | EC24: -0.014309919 | ED24: -0.056172845 | EE24: -0.107482 | EF24: 0.134085
A26: 大盤 | B26: TWII | C26: -0.017446771 | D26: 0.020701061 | E26: 0.023982129 | F26: -0.006557579 | G26: 0.03184513 | H26: 0.034348533 | I26: -0.0082549328 | J26: 0.012843524 | K26: -0.051018525 | L26: 0.00087394274 | M26: 0.023389576 | N26: 0.012988972 | O26: 0.0058545887 | P26: 0.027413207 | Q26: -0.0037129361 | R26: 0.024076614 | S26: -0.012190025 | T26: -0.039749578 | U26: -0.07315545 | V26: -0.05826023 | W26: 0.00077279757 | X26: 0.044591521 | Y26: -0.02769968 | Z26: 0.0020950059 | AA26: -0.023400551 | AB26: 0.032129371 | AC26: 0.038903273 | AD26: -0.042865382 | AE26: 0.018647195 | AF26: 0.015229768 | AG26: 0.036016604 | AH26: 0.0093546114 | AI26: 0.010748251 | AJ26: 0.013357754 | AK26: -0.0053327473 | AL26: 0.0013831358 | AM26: 0.020795928 | AN26: 0.031517702 | AO26: 0.0062417165 | AP26: 0.0061452617 | AQ26: 0.016946358 | AR26: 0.03468283 | AS26: 0.0030985886 | AT26: 0.015081347 | AU26: -0.019251209 | AV26: 0.038711513 | AW26: -0.021856951 | AX26: 0.0077743007 | AY26: 0.042397247 | AZ26: -0.026308975 | BA26: 0.0095717493 | BB26: -0.024249741 | BC26: 0.020163374 | BD26: -0.0035049988 | BE26: 0.020151935 | BF26: 0.00058133623 | BG26: -0.005219701 | BH26: -0.11587176 | BI26: 0.0087252257 | BJ26: -0.016377261 | BK26: 0.020840372 | BL26: 0.044975872 | BM26: 0.023954306 | BN26: 0.030239101 | BO26: -0.043725888 | BP26: 0.02188947 | BQ26: 0.0086274303 | BR26: -0.019192954 | BS26: 0.01973513 | BT26: 0.047694337 | BU26: 0.011454817 | BV26: 0.043228621 | BW26: -0.04274743 | BX26: -0.017811292 | BY26: -0.1511531 | BZ26: 0.124224 | CA26: -0.0045572538 | CB26: 0.06021124 | CC26: 0.085992033 | CD26: -0.0058084796 | CE26: -0.006041347 | CF26: 0.0024523244 | CG26: 0.089636252 | CH26: 0.070992733 | CI26: 0.027170643 | CJ26: 0.052468428 | CK26: 0.029480661 | CL26: 0.066825081 | CM26: -0.028772229 | CN26: 0.039462516 | CO26: -0.029031087 | CP26: 0.013983883 | CQ26: -0.032276965 | CR26: 0.0031035766 | CS26: 0.025591856 | CT26: 0.044391886 | CU26: -0.030338959 | CV26: -0.0012579765 | CW26: 0.0023363565 | CX26: -0.064264145 | CY26: 0.012909779 | CZ26: -0.12547709 | DA26: 0.011690683 | DB26: 0.0063378437 | DC26: -0.11730536 | DD26: -0.036010872 | DE26: 0.1389113 | DF26: -0.051143506 | DG26: 0.076731447 | DH26: 0.015508782 | DI26: 0.023223774 | DJ26: -0.018372876 | DK26: 0.062199014 | DL26: 0.020098304 | DM26: 0.01349894 | DN26: -0.030252213 | DO26: -0.017022836 | DP26: -0.021788523 | DQ26: 0.085745625 | DR26: 0.028106744 | DS26: -0.0023031598 | DT26: 0.058471198 | DU26: 0.067658949 | DV26: 0.0050207706 | DW26: 0.037416184 | DX26: 0.084111004 | DY26: -0.036832399 | DZ26: 0.0030917028 | EA26: -0.0019576282 | EB26: 0.026459104 | EC26: -0.024752539 | ED26: 0.034115491 | EE26: 0.021061974 | EF26: -0.020277393
B28: 低 | C28: 5455 | D28: 2540 | E28: 2540 | F28: 2540 | G28: 2540 | H28: 2540 | I28: 6114 | J28: 6242 | K28: 6242 | L28: 6242 | M28: 8077 | N28: 8077 | O28: 5455 | P28: 5455 | Q28: 5455 | R28: 5455 | S28: 5455 | T28: 5455 | U28: 4413 | V28: 4413 | W28: 4413 | X28: 6225 | Y28: 8044 | Z28: 6225 | AA28: 6225 | AB28: 6225 | AC28: 6225 | AD28: 6225 | AE28: 6225 | AF28: 6225 | AG28: 6225 | AH28: 6291 | AI28: 6291 | AJ28: 6291 | AK28: 6225 | AL28: 6225 | AM28: 6225 | AN28: 6225 | AO28: 6225 | AP28: 6225 | AQ28: 6225 | AR28: 6225 | AS28: 6291 | AT28: 6225 | AU28: 6225 | AV28: 6225 | AW28: 3043 | AX28: 3043 | AY28: 6225 | AZ28: 6225 | BA28: 6225 | BB28: 6225 | BC28: 6225 | BD28: 6225 | BE28: 6225 | BF28: 6225 | BG28: 6225 | BH28: 6225 | BI28: 6225 | BJ28: 6225 | BK28: 6225 | BL28: 6225 | BM28: 6225 | BN28: 1475 | BO28: 6225 | BP28: 6225 | BQ28: 6225 | BR28: 6225 | BS28: 6225 | BT28: 6225 | BU28: 8080 | BV28: 6225 | BW28: 5205 | BX28: 8080 | BY28: 8080 | BZ28: 8080 | CA28: 8080 | CB28: 8080 | CC28: 5205 | CD28: 5205 | CE28: 5205 | CF28: 4304 | CG28: 5205 | CH28: 5205 | CI28: 5205 | CJ28: 8080 | CK28: 8080 | CL28: 8080 | CM28: 5205 | CN28: 6287 | CO28: 5205 | CP28: 5205 | CQ28: 6287 | CR28: 6287 | CS28: 5205 | CT28: 5205 | CU28: 5205 | CV28: 5205 | CW28: 5205 | CX28: 5205 | CY28: 8101 | CZ28: 5205 | DA28: 1538 | DB28: 5314 | DC28: 5314 | DD28: 6225 | DE28: 1538 | DF28: 6225 | DG28: 5314 | DH28: 1538 | DI28: 8080 | DJ28: 8067 | DK28: 8080 | DL28: 8080 | DM28: 8080 | DN28: 8080 | DO28: 8080 | DP28: 8080 | DQ28: 2321 | DR28: 4419 | DS28: 4419 | DT28: 5345 | DU28: 5345 | DV28: 2321 | DW28: 4304 | DX28: 4304 | DY28: 2321 | DZ28: 8101 | EA28: 2321 | EB28: 2321 | EC28: 6287 | ED28: 6287 | EE28: 2321 | EF28: 2321
B29: 公司名稱 | C29: 昇益 | D29: 愛山林 | E29: 愛山林 | F29: 愛山林 | G29: 愛山林 | H29: 愛山林 | I29: 久威 | J29: 立康 | K29: 立康 | L29: 立康 | M29: 洛碁 | N29: 洛碁 | O29: 昇益 | P29: 昇益 | Q29: 昇益 | R29: 昇益 | S29: 昇益 | T29: 昇益 | U29: 飛寶企業 | V29: 飛寶企業 | W29: 飛寶企業 | X29: 天瀚 | Y29: 網家 | Z29: 天瀚 | AA29: 天瀚 | AB29: 天瀚 | AC29: 天瀚 | AD29: 天瀚 | AE29: 天瀚 | AF29: 天瀚 | AG29: 天瀚 | AH29: 沛亨 | AI29: 沛亨 | AJ29: 沛亨 | AK29: 天瀚 | AL29: 天瀚 | AM29: 天瀚 | AN29: 天瀚 | AO29: 天瀚 | AP29: 天瀚 | AQ29: 天瀚 | AR29: 天瀚 | AS29: 沛亨 | AT29: 天瀚 | AU29: 天瀚 | AV29: 天瀚 | AW29: 科風 | AX29: 科風 | AY29: 天瀚 | AZ29: 天瀚 | BA29: 天瀚 | BB29: 天瀚 | BC29: 天瀚 | BD29: 天瀚 | BE29: 天瀚 | BF29: 天瀚 | BG29: 天瀚 | BH29: 天瀚 | BI29: 天瀚 | BJ29: 天瀚 | BK29: 天瀚 | BL29: 天瀚 | BM29: 天瀚 | BN29: 業旺 | BO29: 天瀚 | BP29: 天瀚 | BQ29: 天瀚 | BR29: 天瀚 | BS29: 天瀚 | BT29: 天瀚 | BU29: 印鉐 | BV29: 天瀚 | BW29: 中茂 | BX29: 印鉐 | BY29: 印鉐 | BZ29: 印鉐 | CA29: 印鉐 | CB29: 印鉐 | CC29: 中茂 | CD29: 中茂 | CE29: 中茂 | CF29: 勝昱 | CG29: 中茂 | CH29: 中茂 | CI29: 中茂 | CJ29: 印鉐 | CK29: 印鉐 | CL29: 印鉐 | CM29: 中茂 | CN29: 元隆 | CO29: 中茂 | CP29: 中茂 | CQ29: 元隆 | CR29: 元隆 | CS29: 中茂 | CT29: 中茂 | CU29: 中茂 | CV29: 中茂 | CW29: 中茂 | CX29: 中茂 | CY29: 華冠 | CZ29: 中茂 | DA29: 正峰 | DB29: 世紀 | DC29: 世紀 | DD29: 天瀚 | DE29: 正峰 | DF29: 天瀚 | DG29: 世紀 | DH29: 正峰 | DI29: 印鉐 | DJ29: 志旭 | DK29: 印鉐 | DL29: 印鉐 | DM29: 印鉐 | DN29: 印鉐 | DO29: 印鉐 | DP29: 印鉐 | DQ29: 東訊 | DR29: 皇家美食 | DS29: 皇家美食 | DT29: 天揚 | DU29: 天揚 | DV29: 東訊 | DW29: 勝昱 | DX29: 勝昱 | DY29: 東訊 | DZ29: 華冠 | EA29: 東訊 | EB29: 東訊 | EC29: 元隆 | ED29: 元隆 | EE29: 東訊 | EF29: 東訊
B30: 高 | C30: 2330 | D30: 2323 | E30: 2323 | F30: 2323 | G30: 2323 | H30: 2323 | I30: 2323 | J30: 2323 | K30: 2323 | L30: 2323 | M30: 2323 | N30: 2323 | O30: 2323 | P30: 2323 | Q30: 2323 | R30: 2323 | S30: 2323 | T30: 2323 | U30: 2323 | V30: 2323 | W30: 2323 | X30: 2323 | Y30: 2323 | Z30: 2323 | AA30: 2323 | AB30: 2323 | AC30: 2323 | AD30: 2323 | AE30: 2323 | AF30: 2323 | AG30: 1314 | AH30: 2330 | AI30: 2330 | AJ30: 2330 | AK30: 2323 | AL30: 2323 | AM30: 2323 | AN30: 2323 | AO30: 2323 | AP30: 2323 | AQ30: 2323 | AR30: 2323 | AS30: 2330 | AT30: 2323 | AU30: 2323 | AV30: 2323 | AW30: 3252 | AX30: 3252 | AY30: 3252 | AZ30: 3252 | BA30: 3252 | BB30: 3252 | BC30: 1906 | BD30: 1906 | BE30: 1906 | BF30: 3252 | BG30: 1906 | BH30: 1906 | BI30: 1906 | BJ30: 1906 | BK30: 8085 | BL30: 8085 | BM30: 2201 | BN30: 2330 | BO30: 8085 | BP30: 8085 | BQ30: 3252 | BR30: 2409 | BS30: 3252 | BT30: 3311 | BU30: 3311 | BV30: 2321 | BW30: 3252 | BX30: 3252 | BY30: 3252 | BZ30: 5608 | CA30: 5608 | CB30: 5608 | CC30: 1314 | CD30: 5608 | CE30: 2330 | CF30: 2330 | CG30: 1314 | CH30: 1314 | CI30: 3252 | CJ30: 3252 | CK30: 3252 | CL30: 3252 | CM30: 2330 | CN30: 3252 | CO30: 2330 | CP30: 2330 | CQ30: 3252 | CR30: 3252 | CS30: 2330 | CT30: 2330 | CU30: 2330 | CV30: 2330 | CW30: 2330 | CX30: 2330 | CY30: 1906 | CZ30: 2330 | DA30: 2330 | DB30: 2330 | DC30: 2330 | DD30: 1906 | DE30: 2330 | DF30: 2330 | DG30: 2330 | DH30: 2330 | DI30: 2330 | DJ30: 2330 | DK30: 2330 | DL30: 2330 | DM30: 2330 | DN30: 2330 | DO30: 2330 | DP30: 2330 | DQ30: 2330 | DR30: 1906 | DS30: 1314 | DT30: 2330 | DU30: 2330 | DV30: 2330 | DW30: 2330 | DX30: 2330 | DY30: 2330 | DZ30: 2330 | EA30: 2330 | EB30: 2330 | EC30: 1314 | ED30: 1312 | EE30: 2330 | EF30: 2330
B31: 公司名稱 | C31: 台積電 | D31: 中環 | E31: 中環 | F31: 中環 | G31: 中環 | H31: 中環 | I31: 中環 | J31: 中環 | K31: 中環 | L31: 中環 | M31: 中環 | N31: 中環 | O31: 中環 | P31: 中環 | Q31: 中環 | R31: 中環 | S31: 中環 | T31: 中環 | U31: 中環 | V31: 中環 | W31: 中環 | X31: 中環 | Y31: 中環 | Z31: 中環 | AA31: 中環 | AB31: 中環 | AC31: 中環 | AD31: 中環 | AE31: 中環 | AF31: 中環 | AG31: 中石化 | AH31: 台積電 | AI31: 台積電 | AJ31: 台積電 | AK31: 中環 | AL31: 中環 | AM31: 中環 | AN31: 中環 | AO31: 中環 | AP31: 中環 | AQ31: 中環 | AR31: 中環 | AS31: 台積電 | AT31: 中環 | AU31: 中環 | AV31: 中環 | AW31: 海灣 | AX31: 海灣 | AY31: 海灣 | AZ31: 海灣 | BA31: 海灣 | BB31: 海灣 | BC31: 寶隆 | BD31: 寶隆 | BE31: 寶隆 | BF31: 海灣 | BG31: 寶隆 | BH31: 寶隆 | BI31: 寶隆 | BJ31: 寶隆 | BK31: 福華 | BL31: 福華 | BM31: 裕隆 | BN31: 台積電 | BO31: 福華 | BP31: 福華 | BQ31: 海灣 | BR31: 友達 | BS31: 海灣 | BT31: 閎暉 | BU31: 閎暉 | BV31: 東訊 | BW31: 海灣 | BX31: 海灣 | BY31: 海灣 | BZ31: 四維航 | CA31: 四維航 | CB31: 四維航 | CC31: 中石化 | CD31: 四維航 | CE31: 台積電 | CF31: 台積電 | CG31: 中石化 | CH31: 中石化 | CI31: 海灣 | CJ31: 海灣 | CK31: 海灣 | CL31: 海灣 | CM31: 台積電 | CN31: 海灣 | CO31: 台積電 | CP31: 台積電 | CQ31: 海灣 | CR31: 海灣 | CS31: 台積電 | CT31: 台積電 | CU31: 台積電 | CV31: 台積電 | CW31: 台積電 | CX31: 台積電 | CY31: 寶隆 | CZ31: 台積電 | DA31: 台積電 | DB31: 台積電 | DC31: 台積電 | DD31: 寶隆 | DE31: 台積電 | DF31: 台積電 | DG31: 台積電 | DH31: 台積電 | DI31: 台積電 | DJ31: 台積電 | DK31: 台積電 | DL31: 台積電 | DM31: 台積電 | DN31: 台積電 | DO31: 台積電 | DP31: 台積電 | DQ31: 台積電 | DR31: 寶隆 | DS31: 中石化 | DT31: 台積電 | DU31: 台積電 | DV31: 台積電 | DW31: 台積電 | DX31: 台積電 | DY31: 台積電 | DZ31: 台積電 | EA31: 台積電 | EB31: 台積電 | EC31: 中石化 | ED31: 國喬 | EE31: 台積電 | EF31: 台積電

Sheet 夏普比率
A1: NN2
B2: Time | C2: 2013/12 | D2: 2014/01 | E2: 2014/02 | F2: 2014/03 | G2: 2014/04 | H2: 2014/05 | I2: 2014/06 | J2: 2014/07 | K2: 2014/08 | L2: 2014/09 | M2: 2014/10 | N2: 2014/11 | O2: 2014/12 | P2: 2015/01 | Q2: 2015/02 | R2: 2015/03 | S2: 2015/04 | T2: 2015/05 | U2: 2015/06 | V2: 2015/07 | W2: 2015/08 | X2: 2015/09 | Y2: 2015/10 | Z2: 2015/11 | AA2: 2015/12 | AB2: 2016/01 | AC2: 2016/02 | AD2: 2016/03 | AE2: 2016/04 | AF2: 2016/05 | AG2: 2016/06 | AH2: 2016/07 | AI2: 2016/08 | AJ2: 2016/09 | AK2: 2016/10 | AL2: 2016/11 | AM2: 2016/12 | AN2: 2017/01 | AO2: 2017/02 | AP2: 2017/03 | AQ2: 2017/04 | AR2: 2017/05 | AS2: 2017/06 | AT2: 2017/07 | AU2: 2017/08 | AV2: 2017/09 | AW2: 2017/10 | AX2: 2017/11 | AY2: 2017/12 | AZ2: 2018/01 | BA2: 2018/02 | BB2: 2018/03 | BC2: 2018/04 | BD2: 2018/05 | BE2: 2018/06 | BF2: 2018/07 | BG2: 2018/08 | BH2: 2018/09 | BI2: 2018/10 | BJ2: 2018/11 | BK2: 2018/12 | BL2: 2019/01 | BM2: 2019/02 | BN2: 2019/03 | BO2: 2019/04 | BP2: 2019/05 | BQ2: 2019/06 | BR2: 2019/07 | BS2: 2019/08 | BT2: 2019/09 | BU2: 2019/10 | BV2: 2019/11 | BW2: 2019/12 | BX2: 2020/01 | BY2: 2020/02 | BZ2: 2020/03 | CA2: 2020/04 | CB2: 2020/05 | CC2: 2020/06 | CD2: 2020/07 | CE2: 2020/08 | CF2: 2020/09 | CG2: 2020/10 | CH2: 2020/11 | CI2: 2020/12 | CJ2: 2021/01 | CK2: 2021/02 | CL2: 2021/03 | CM2: 2021/04 | CN2: 2021/05 | CO2: 2021/06 | CP2: 2021/07 | CQ2: 2021/08 | CR2: 2021/09 | CS2: 2021/10 | CT2: 2021/11 | CU2: 2021/12 | CV2: 2022/01 | CW2: 2022/02 | CX2: 2022/03 | CY2: 2022/04 | CZ2: 2022/05 | DA2: 2022/06 | DB2: 2022/07 | DC2: 2022/08 | DD2: 2022/09 | DE2: 2022/10 | DF2: 2022/11 | DG2: 2022/12 | DH2: 2023/01 | DI2: 2023/02 | DJ2: 2023/03 | DK2: 2023/04 | DL2: 2023/05 | DM2: 2023/06 | DN2: 2023/07 | DO2: 2023/08 | DP2: 2023/09 | DQ2: 2023/10 | DR2: 2023/11 | DS2: 2023/12 | DT2: 2024/01 | DU2: 2024/02 | DV2: 2024/03 | DW2: 2024/04 | DX2: 2024/05 | DY2: 2024/06 | DZ2: 2024/07 | EA2: 2024/08 | EB2: 2024/09 | EC2: 2024/10 | ED2: 2024/11 | EE2: 2024/12 | EF2: 2025/01
