Workbook

Sheet 預測IC
A1: NN4
B2: Time | C2: 2013/12 | D2: 2014/01 | E2: 2014/02 | F2: 2014/03 | G2: 2014/04 | H2: 2014/05 | I2: 2014/06 | J2: 2014/07 | K2: 2014/08 | L2: 2014/09 | M2: 2014/10 | N2: 2014/11 | O2: 2014/12 | P2: 2015/01 | Q2: 2015/02 | R2: 2015/03 | S2: 2015/04 | T2: 2015/05 | U2: 2015/06 | V2: 2015/07 | W2: 2015/08 | X2: 2015/09 | Y2: 2015/10 | Z2: 2015/11 | AA2: 2015/12 | AB2: 2016/01 | AC2: 2016/02 | AD2: 2016/03 | AE2: 2016/04 | AF2: 2016/05 | AG2: 2016/06 | AH2: 2016/07 | AI2: 2016/08 | AJ2: 2016/09 | AK2: 2016/10 | AL2: 2016/11 | AM2: 2016/12 | AN2: 2017/01 | AO2: 2017/02 | AP2: 2017/03 | AQ2: 2017/04 | AR2: 2017/05 | AS2: 2017/06 | AT2: 2017/07 | AU2: 2017/08 | AV2: 2017/09 | AW2: 2017/10 | AX2: 2017/11 | AY2: 2017/12 | AZ2: 2018/01 | BA2: 2018/02 | BB2: 2018/03 | BC2: 2018/04 | BD2: 2018/05 | BE2: 2018/06 | BF2: 2018/07 | BG2: 2018/08 | BH2: 2018/09 | BI2: 2018/10 | BJ2: 2018/11 | BK2: 2018/12 | BL2: 2019/01 | BM2: 2019/02 | BN2: 2019/03 | BO2: 2019/04 | BP2: 2019/05 | BQ2: 2019/06 | BR2: 2019/07 | BS2: 2019/08 | BT2: 2019/09 | BU2: 2019/10 | BV2: 2019/11 | BW2: 2019/12 | BX2: 2020/01 | BY2: 2020/02 | BZ2: 2020/03 | CA2: 2020/04 | CB2: 2020/05 | CC2: 2020/06 | CD2: 2020/07 | CE2: 2020/08 | CF2: 2020/09 | CG2: 2020/10 | CH2: 2020/11 | CI2: 2020/12 | CJ2: 2021/01 | CK2: 2021/02 | CL2: 2021/03 | CM2: 2021/04 | CN2: 2021/05 | CO2: 2021/06 | CP2: 2021/07 | CQ2: 2021/08 | CR2: 2021/09 | CS2: 2021/10 | CT2: 2021/11 | CU2: 2021/12 | CV2: 2022/01 | CW2: 2022/02 | CX2: 2022/03 | CY2: 2022/04 | CZ2: 2022/05 | DA2: 2022/06 | DB2: 2022/07 | DC2: 2022/08 | DD2: 2022/09 | DE2: 2022/10 | DF2: 2022/11 | DG2: 2022/12 | DH2: 2023/01 | DI2: 2023/02 | DJ2: 2023/03 | DK2: 2023/04 | DL2: 2023/05 | DM2: 2023/06 | DN2: 2023/07 | DO2: 2023/08 | DP2: 2023/09 | DQ2: 2023/10 | DR2: 2023/11 | DS2: 2023/12 | DT2: 2024/01 | DU2: 2024/02 | DV2: 2024/03 | DW2: 2024/04 | DX2: 2024/05 | DY2: 2024/06 | DZ2: 2024/07 | EA2: 2024/08 | EB2: 2024/09 | EC2: 2024/10 | ED2: 2024/11 | EE2: 2024/12 | EF2: 2025/01 | EG2: 2025/02
B3: bm | C3: 0.053380694 | D3: 0.025363307 | E3: 0.037131086 | F3: -0.015433895 | G3: 0.038762547 | H3: 0.018920034 | I3: 0.03051983 | J3: -0.007065095 | K3: 0.0087663401 | L3: -0.016310772 | M3: 0.02265431 | N3: -0.01618601 | O3: -0.027719442 | P3: 0.092788354 | Q3: -0.016570717 | R3: -0.014206883 | S3: 0.04957927 | T3: 0.027950581 | U3: 0.00014803186 | V3: -0.019191418 | W3: -0.020450763 | X3: -0.038444549 | Y3: -0.021946479 | Z3: 0.014381051 | AA3: 0.028816506 | AB3: -0.023727335 | AC3: -0.012928918 | AD3: 0.022476669 | AE3: 0.038704991 | AF3: 0.012001708 | AG3: -0.027202442 | AH3: 0.017024014 | AI3: 0.014300147 | AJ3: 0.01841375 | AK3: 0.010560635 | AL3: 0.038964592 | AM3: 0.018552557 | AN3: 0.043863278 | AO3: -0.003669156 | AP3: 0.038291201 | AQ3: 0.010157695 | AR3: 0.0080924127 | AS3: -0.066054963 | AT3: 0.043137997 | AU3: 0.049771857 | AV3: 0.049413983 | AW3: 0.051071316 | AX3: 0.049621776 | AY3: 0.051257487 | AZ3: 0.042423129 | BA3: 0.039333701 | BB3: 0.039388258 | BC3: 0.042884018 | BD3: 0.044494439 | BE3: 0.046050392 | BF3: 0.052774351 | BG3: 0.052520696 | BH3: 0.052043032 | BI3: 0.053213786 | BJ3: 0.051484849 | BK3: 0.052345768 | BL3: 0.052821685 | BM3: 0.052466232 | BN3: 0.057477392 | BO3: 0.055104457 | BP3: 0.040814403 | BQ3: 0.052616533 | BR3: 0.03664574 | BS3: 0.054600824 | BT3: 0.045548383 | BU3: 0.055572357 | BV3: 0.052330784 | BW3: 0.041799743 | BX3: 0.0479641 | BY3: 0.04955405 | BZ3: 0.053468108 | CA3: 0.048687574 | CB3: 0.046025429 | CC3: 0.052412558 | CD3: 0.049619406 | CE3: 0.046824053 | CF3: 0.050924398 | CG3: 0.046287201 | CH3: 0.050006066 | CI3: 0.048990387 | CJ3: 0.050737027 | CK3: 0.050407581 | CL3: 0.051771164 | CM3: 0.049744159 | CN3: 0.049877673 | CO3: 0.048527718 | CP3: 0.04869274 | CQ3: 0.049047302 | CR3: 0.049837247 | CS3: 0.047483202 | CT3: 0.031795904 | CU3: 0.044976842 | CV3: 0.049786106 | CW3: 0.043859463 | CX3: 0.051966626 | CY3: 0.050948314 | CZ3: 0.044357844 | DA3: 0.045401514 | DB3: 0.052733634 | DC3: 0.052081622 | DD3: 0.049637035 | DE3: 0.0525898 | DF3: 0.04140893 | DG3: 0.043718357 | DH3: 0.046793398 | DI3: 0.047784906 | DJ3: 0.051443465 | DK3: 0.041621469 | DL3: 0.048520051 | DM3: 0.048485212 | DN3: 0.046739094 | DO3: 0.048157804 | DP3: 0.04762277 | DQ3: 0.048637111 | DR3: 0.048790317 | DS3: 0.044818055 | DT3: 0.048045274 | DU3: 0.047465518 | DV3: 0.046620265 | DW3: 0.047323689 | DX3: 0.047544401 | DY3: 0.047807489 | DZ3: 0.034820709 | EA3: 0.048265137 | EB3: 0.042205382 | EC3: 0.036263358 | ED3: 0.039504204 | EE3: 0.046422228 | EF3: 0.050174937
B4: size | C4: -0.025382355 | D4: -0.030302392 | E4: -0.022067005 | F4: -0.033426508 | G4: -0.043564618 | H4: -0.024043657 | I4: -0.026620017 | J4: -0.036628138 | K4: -0.033706646 | L4: -0.03978961 | M4: -0.038071342 | N4: -0.029651828 | O4: -0.036376376 | P4: -0.038347743 | Q4: -0.024343766 | R4: -0.033573233 | S4: -0.028594412 | T4: -0.02798361 | U4: -0.02942265 | V4: -0.027942499 | W4: -0.027846377 | X4: -0.029234068 | Y4: -0.03196783 | Z4: -0.029925361 | AA4: -0.030244136 | AB4: -0.028592777 | AC4: -0.027409475 | AD4: -0.029048892 | AE4: -0.030896455 | AF4: -0.028318249 | AG4: -0.028357839 | AH4: -0.020635519 | AI4: -0.039616738 | AJ4: -0.034279849 | AK4: -0.027382219 | AL4: -0.028631316 | AM4: -0.031148817 | AN4: -0.025323469 | AO4: -0.035884447 | AP4: -0.020551486 | AQ4: -0.021187438 | AR4: -0.026181202 | AS4: -0.029181501 | AT4: -0.02669511 | AU4: -0.030467244 | AV4: -0.032533787 | AW4: -0.027417561 | AX4: -0.026351918 | AY4: -0.03351121 | AZ4: -0.026826687 | BA4: -0.031055138 | BB4: -0.033870146 | BC4: -0.031388275 | BD4: -0.031560801 | BE4: -0.032705665 | BF4: -0.030919457 | BG4: -0.031984996 | BH4: -0.030280499 | BI4: -0.031126156 | BJ4: -0.030479368 | BK4: -0.032265529 | BL4: -0.031362556 | BM4: -0.031354729 | BN4: -0.012234848 | BO4: -0.023717724 | BP4: -0.02602464 | BQ4: -0.030553957 | BR4: -0.011215119 | BS4: -0.033343475 | BT4: -0.025871314 | BU4: -0.036363196 | BV4: -0.033731509 | BW4: -0.024674531 | BX4: -0.033149183 | BY4: -0.031638261 | BZ4: -0.035745308 | CA4: -0.032566581 | CB4: -0.024697717 | CC4: -0.029147785 | CD4: -0.02595346 | CE4: -0.031028131 | CF4: -0.031018134 | CG4: -0.030473333 | CH4: -0.031180024 | CI4: -0.030876048 | CJ4: -0.033132713 | CK4: -0.031985853 | CL4: -0.031450629 | CM4: -0.030559268 | CN4: -0.031584196 | CO4: -0.030493449 | CP4: -0.030219421 | CQ4: -0.031929124 | CR4: -0.0293497 | CS4: -0.030506747 | CT4: -0.023085918 | CU4: -0.027401416 | CV4: -0.028335974 | CW4: -0.032171883 | CX4: -0.027837746 | CY4: -0.027134022 | CZ4: -0.025732454 | DA4: -0.028771926 | DB4: -0.033348452 | DC4: -0.032358631 | DD4: -0.032213934 | DE4: -0.029715812 | DF4: -0.029115837 | DG4: -0.027615877 | DH4: -0.029729646 | DI4: -0.0298208 | DJ4: -0.030264959 | DK4: -0.029952951 | DL4: -0.030072087 | DM4: -0.028160347 | DN4: -0.027362494 | DO4: -0.028680921 | DP4: -0.026546771 | DQ4: -0.027645908 | DR4: -0.030578829 | DS4: -0.027206589 | DT4: -0.029622274 | DU4: -0.028198829 | DV4: -0.027983174 | DW4: -0.026147189 | DX4: -0.027574016 | DY4: -0.029771693 | DZ4: -0.023879239 | EA4: -0.026729578 | EB4: -0.026265992 | EC4: -0.028522423 | ED4: -0.023929797 | EE4: -0.035369247 | EF4: -0.028897885
B5: mom | C5: 0.0068580564 | D5: -0.0045473208 | E5: -0.0052568247 | F5: -0.0050700335 | G5: -0.0075548952 | H5: -0.0057517439 | I5: -0.0066213347 | J5: -0.006445678 | K5: -0.0072449944 | L5: -0.0074795205 | M5: -0.0057203313 | N5: 0.01217775 | O5: 0.020977385 | P5: 0.0041054371 | Q5: 0.0027524955 | R5: 0.0022056564 | S5: -0.0032005233 | T5: 0.0047661159 | U5: 0.0031950199 | V5: 0.00013798894 | W5: 0.00090849918 | X5: -0.0048395749 | Y5: -0.0096684145 | Z5: -0.0043582963 | AA5: -0.0094516985 | AB5: -0.0078619011 | AC5: -0.009573984 | AD5: -0.011925906 | AE5: -0.0090736486 | AF5: -0.0052689705 | AG5: -0.0062905294 | AH5: -0.0042838594 | AI5: -0.0036589741 | AJ5: -0.0031868441 | AK5: -0.0065460228 | AL5: -0.0054174191 | AM5: -0.0063505336 | AN5: 0.00094361149 | AO5: -0.0041886745 | AP5: -0.0063021155 | AQ5: -0.00078539003 | AR5: 0.00012744281 | AS5: -0.0026125095 | AT5: 0.017251728 | AU5: -0.011382638 | AV5: 0.0098412996 | AW5: 0.00644386 | AX5: -0.0094542578 | AY5: -0.0026053693 | AZ5: 0.010213769 | BA5: -0.00033708787 | BB5: -0.0076581961 | BC5: 0.0019559243 | BD5: -0.017539704 | BE5: -0.0058258567 | BF5: 0.00061481039 | BG5: -0.0072949403 | BH5: -0.0043838453 | BI5: 7.9724268e-05 | BJ5: -0.00041618734 | BK5: -0.0081078559 | BL5: -0.0018168367 | BM5: -0.0030251548 | BN5: -0.00071253179 | BO5: -0.0043908162 | BP5: -0.0086731631 | BQ5: 0.00098586292 | BR5: 0.00056344678 | BS5: -0.00072165515 | BT5: 0.00021159742 | BU5: -0.0039482755 | BV5: -0.0017540061 | BW5: -0.0039257919 | BX5: -0.0022805596 | BY5: -0.0025638358 | BZ5: 0.0009579889 | CA5: -0.017290488 | CB5: -0.018011753 | CC5: -0.011205501 | CD5: -0.005945398 | CE5: 0.0056577795 | CF5: -0.0050181304 | CG5: -0.0010808827 | CH5: -0.0024344833 | CI5: -0.0058056642 | CJ5: 0.0053442474 | CK5: -0.0066559319 | CL5: -0.0081223333 | CM5: 0.0044885189 | CN5: -0.0012609405 | CO5: 0.0022093973 | CP5: -0.0031657333 | CQ5: -0.004247616 | CR5: 0.00074740843 | CS5: -0.0068966434 | CT5: -0.00088150596 | CU5: -0.0054849479 | CV5: -0.00050015887 | CW5: -0.0036941525 | CX5: -0.0015164877 | CY5: -0.0022506022 | CZ5: -0.00010379159 | DA5: -0.0013994954 | DB5: -0.0028583268 | DC5: -0.0038185073 | DD5: -0.0047922488 | DE5: -0.0044267559 | DF5: -0.023297871 | DG5: -0.0066420962 | DH5: -0.0046426621 | DI5: -0.0021060877 | DJ5: -0.010628033 | DK5: -0.0096024703 | DL5: -0.0038239909 | DM5: -0.00061252154 | DN5: -0.0036278171 | DO5: 0.0029465526 | DP5: -0.0056377305 | DQ5: -0.0043007815 | DR5: -0.0070757018 | DS5: -0.0036393199 | DT5: -0.0010788124 | DU5: -0.0057610022 | DV5: -0.0031701692 | DW5: 0.00013763481 | DX5: -0.0052125226 | DY5: -0.0032316372 | DZ5: -0.0019697994 | EA5: -0.0025265156 | EB5: -0.0044835992 | EC5: -0.0046032607 | ED5: -0.0064388467 | EE5: -0.0059161326 | EF5: -0.0061999494
A6: 選絕對值最大 | C6: {=MATCH(MAX(ABS(C3:C5)), ABS(C3:C5), 0)} -> 1 | D6: {=MATCH(MAX(ABS(D3:D5)), ABS(D3:D5), 0)} -> 2 | E6: {=MATCH(MAX(ABS(E3:E5)), ABS(E3:E5), 0)} -> 1 | F6: {=MATCH(MAX(ABS(F3:F5)), ABS(F3:F5), 0)} -> 2 | G6: {=MATCH(MAX(ABS(G3:G5)), ABS(G3:G5), 0)} -> 2 | H6: {=MATCH(MAX(ABS(H3:H5)), ABS(H3:H5), 0)} -> 2 | I6: {=MATCH(MAX(ABS(I3:I5)), ABS(I3:I5), 0)} -> 1 | J6: {=MATCH(MAX(ABS(J3:J5)), ABS(J3:J5), 0)} -> 2 | ... EF6: {=MATCH(MAX(ABS(EF3:EF5)), ABS(EF3:EF5), 0)} -> 1
C7: =IF(C6=1,"bm",IF(C6=2,"size",IF(C6=3,"mom"))) -> bm | D7: =IF(D6=1,"bm",IF(D6=2,"size",IF(D6=3,"mom"))) -> size | E7: =IF(E6=1,"bm",IF(E6=2,"size",IF(E6=3,"mom"))) -> bm | F7: =IF(F6=1,"bm",IF(F6=2,"size",IF(F6=3,"mom"))) -> size | G7: =IF(G6=1,"bm",IF(G6=2,"size",IF(G6=3,"mom"))) -> size | H7: =IF(H6=1,"bm",IF(H6=2,"size",IF(H6=3,"mom"))) -> size | I7: =IF(I6=1,"bm",IF(I6=2,"size",IF(I6=3,"mom"))) -> bm | J7: =IF(J6=1,"bm",IF(J6=2,"size",IF(J6=3,"mom"))) -> size | ... EF7: =IF(EF6=1,"bm",IF(EF6=2,"size",IF(EF6=3,"mom"))) -> bm
C8: =IF(C6=1,C3,IF(C6=2,C4,IF(C6=3,C5))) -> 0.053380694 | D8: =IF(D6=1,D3,IF(D6=2,D4,IF(D6=3,D5))) -> -0.030302392 | E8: =IF(E6=1,E3,IF(E6=2,E4,IF(E6=3,E5))) -> 0.037131086 | F8: =IF(F6=1,F3,IF(F6=2,F4,IF(F6=3,F5))) -> -0.033426508 | G8: =IF(G6=1,G3,IF(G6=2,G4,IF(G6=3,G5))) -> -0.043564618 | H8: =IF(H6=1,H3,IF(H6=2,H4,IF(H6=3,H5))) -> -0.024043657 | I8: =IF(I6=1,I3,IF(I6=2,I4,IF(I6=3,I5))) -> 0.03051983 | J8: =IF(J6=1,J3,IF(J6=2,J4,IF(J6=3,J5))) -> -0.036628138 | ... EF8: =IF(EF6=1,EF3,IF(EF6=2,EF4,IF(EF6=3,EF5))) -> 0.050174937
A10: 投資組合 | C10: 公司數 | D10: 964
A11: 等分 | B11: 分數 | C11: 2014/01 | D11: 2014/02 | E11: 2014/03 | F11: 2014/04 | G11: 2014/05 | H11: 2014/06 | I11: 2014/07 | J11: 2014/08 | K11: 2014/09 | L11: 2014/10 | M11: 2014/11 | N11: 2014/12 | O11: 2015/01 | P11: 2015/02 | Q11: 2015/03 | R11: 2015/04 | S11: 2015/05 | T11: 2015/06 | U11: 2015/07 | V11: 2015/08 | W11: 2015/09 | X11: 2015/10 | Y11: 2015/11 | Z11: 2015/12 | AA11: 2016/01 | AB11: 2016/02 | AC11: 2016/03 | AD11: 2016/04 | AE11: 2016/05 | AF11: 2016/06 | AG11: 2016/07 | AH11: 2016/08 | AI11: 2016/09 | AJ11: 2016/10 | AK11: 2016/11 | AL11: 2016/12 | AM11: 2017/01 | AN11: 2017/02 | AO11: 2017/03 | AP11: 2017/04 | AQ11: 2017/05 | AR11: 2017/06 | AS11: 2017/07 | AT11: 2017/08 | AU11: 2017/09 | AV11: 2017/10 | AW11: 2017/11 | AX11: 2017/12 | AY11: 2018/01 | AZ11: 2018/02 | BA11: 2018/03 | BB11: 2018/04 | BC11: 2018/05 | BD11: 2018/06 | BE11: 2018/07 | BF11: 2018/08 | BG11: 2018/09 | BH11: 2018/10 | BI11: 2018/11 | BJ11: 2018/12 | BK11: 2019/01 | BL11: 2019/02 | BM11: 2019/03 | BN11: 2019/04 | BO11: 2019/05 | BP11: 2019/06 | BQ11: 2019/07 | BR11: 2019/08 | BS11: 2019/09 | BT11: 2019/10 | BU11: 2019/11 | BV11: 2019/12 | BW11: 2020/01 | BX11: 2020/02 | BY11: 2020/03 | BZ11: 2020/04 | CA11: 2020/05 | CB11: 2020/06 | CC11: 2020/07 | CD11: 2020/08 | CE11: 2020/09 | CF11: 2020/10 | CG11: 2020/11 | CH11: 2020/12 | CI11: 2021/01 | CJ11: 2021/02 | CK11: 2021/03 | CL11: 2021/04 | CM11: 2021/05 | CN11: 2021/06 | CO11: 2021/07 | CP11: 2021/08 | CQ11: 2021/09 | CR11: 2021/10 | CS11: 2021/11 | CT11: 2021/12 | CU11: 2022/01 | CV11: 2022/02 | CW11: 2022/03 | CX11: 2022/04 | CY11: 2022/05 | CZ11: 2022/06 | DA11: 2022/07 | DB11: 2022/08 | DC11: 2022/09 | DD11: 2022/10 | DE11: 2022/11 | DF11: 2022/12 | DG11: 2023/01 | DH11: 2023/02 | DI11: 2023/03 | DJ11: 2023/04 | DK11: 2023/05 | DL11: 2023/06 | DM11: 2023/07 | DN11: 2023/08 | DO11: 2023/09 | DP11: 2023/10 | DQ11: 2023/11 | DR11: 2023/12 | DS11: 2024/01 | DT11: 2024/02 | DU11: 2024/03 | DV11: 2024/04 | DW11: 2024/05 | DX11: 2024/06 | DY11: 2024/07 | DZ11: 2024/08 | EA11: 2024/09 | EB11: 2024/10 | EC11: 2024/11 | ED11: 2024/12 | EE11: 2025/01 | EF11: 2025/02
A12: 10 | B12: 96 | C12: 0.046867683 | D12: 0.11468851 | E12: -0.0067935603 | F12: 0.013421406 | G12: 0.011724969 | H12: 0.038530719 | I12: 0.038097115 | J12: -0.029407802 | K12: 0.018774177 | L12: -0.041890635 | M12: -0.0003966875 | N12: 0.06932675 | O12: 0.017240844 | P12: -0.019809765 | Q12: 0.035270469 | R12: 0.0066630833 | S12: -0.075752807 | T12: -0.0077403854 | U12: -0.016178792 | V12: 0.0062048021 | W12: 0.064039646 | X12: -0.048837873 | Y12: 0.015440104 | Z12: 0.0051660417 | AA12: -0.011916833 | AB12: -0.0037113229 | AC12: 0.0051674479 | AD12: 0.011230542 | AE12: -0.037521221 | AF12: 0.046181927 | AG12: 0.012079188 | AH12: 0.020093115 | AI12: 0.023246958 | AJ12: 0.021062375 | AK12: 0.010179771 | AL12: 0.017859003 | AM12: 0.020205823 | AN12: 0.070370866 | AO12: 0.011704 | AP12: -0.033728996 | AQ12: -0.0066816458 | AR12: -0.0075043646 | AS12: -0.019726131 | AT12: 0.013068927 | AU12: 0.01997465 | AV12: -0.041126071 | AW12: 0.00092954754 | AX12: 0.04302046 | AY12: 0.024483354 | AZ12: -0.0030582149 | BA12: 0.0041573906 | BB12: 0.015982892 | BC12: 0.012985576 | BD12: 0.011431424 | BE12: 0.024030491 | BF12: 0.068729809 | BG12: 0.03838813 | BH12: 0.011148916 | BI12: 0.051439927 | BJ12: -0.00079599332 | BK12: -0.021696474 | BL12: 0.024709246 | BM12: -0.0019252831 | BN12: 0.011338312 | BO12: 0.02424631 | BP12: -0.010576816 | BQ12: 0.01520658 | BR12: -0.0015066644 | BS12: 0.017696907 | BT12: 0.02179785 | BU12: 0.010209501 | BV12: 0.030223813 | BW12: -0.028816874 | BX12: 0.0097131055 | BY12: -0.03305141 | BZ12: 0.045004028 | CA12: -0.030447774 | CB12: 0.0016648876 | CC12: -0.017660897 | CD12: 0.11093363 | CE12: 0.011619408 | CF12: 0.026993353 | CG12: 0.041309333 | CH12: 0.06440264 | CI12: -0.035807413 | CJ12: 0.01761385 | CK12: 0.011994068 | CL12: 0.11801561 | CM12: -0.014382691 | CN12: -0.025586963 | CO12: -0.026747945 | CP12: 0.045040196 | CQ12: 0.037258661 | CR12: 0.002510872 | CS12: -0.015201648 | CT12: -0.0009616462 | CU12: 0.032036179 | CV12: 0.0082631539 | CW12: 0.0053812281 | CX12: 0.060989883 | CY12: -0.0061822201 | CZ12: 0.079607283 | DA12: 0.003403208 | DB12: -0.0234118 | DC12: 0.033044377 | DD12: 0.02691679 | DE12: -0.00018474425 | DF12: -0.0068330162 | DG12: -0.00079027007 | DH12: -0.0052621438 | DI12: -0.054443173 | DJ12: 0.0080625983 | DK12: -0.015264403 | DL12: -0.0010642652 | DM12: -0.0057147714 | DN12: 0.039228343 | DO12: 0.02212825 | DP12: 0.03258445 | DQ12: -0.023448391 | DR12: 0.018778943 | DS12: -0.03726403 | DT12: -0.044221205 | DU12: 0.013752648 | DV12: 0.052173184 | DW12: 0.039694302 | DX12: -0.049619207 | DY12: 0.017245148 | DZ12: -0.0047575251 | EA12: 0.064003941 | EB12: 0.0036693856 | EC12: 0.02665151 | ED12: -0.056628036 | EE12: 0.012458374 | EF12: 0.039233348
A13: 20 | B13: 48 | C13: 0.054209043 | D13: 0.1237451 | E13: -0.034496619 | F13: -0.011454812 | G13: 0.015744854 | H13: 0.029990354 | I13: 0.037315684 | J13: -0.043898813 | K13: -0.0013674792 | L13: -0.0060251042 | M13: 0.025687292 | N13: 0.099806729 | O13: 0.039789375 | P13: -0.021104073 | Q13: 0.073225021 | R13: 0.014159833 | S13: -0.1229153 | T13: -0.021634062 | U13: 0.0015963125 | V13: -0.020094125 | W13: 0.075476396 | X13: -0.075502649 | Y13: 0.013920375 | Z13: 0.020583917 | AA13: -0.016440042 | AB13: -0.016035979 | AC13: 0.0080312708 | AD13: 0.021543083 | AE13: -0.046284109 | AF13: 0.051936 | AG13: 0.0032824583 | AH13: 0.031874708 | AI13: 0.019910042 | AJ13: 0.019885917 | AK13: 0.0033189583 | AL13: 0.026329 | AM13: -0.0022829792 | AN13: 0.10533024 | AO13: 0.0030209792 | AP13: -0.05953822 | AQ13: -0.011081896 | AR13: 0.0092504167 | AS13: -0.039777953 | AT13: 0.040463088 | AU13: 0.042460982 | AV13: -0.009000778 | AW13: 0.0032682708 | AX13: 0.065349021 | AY13: 0.015767643 | AZ13: -0.0089977639 | BA13: 0.0078944526 | BB13: 0.042875374 | BC13: 0.01302658 | BD13: 0.0056020821 | BE13: 0.028423348 | BF13: 0.083929415 | BG13: 0.046566462 | BH13: 0.0069762719 | BI13: 0.05278812 | BJ13: -0.017654109 | BK13: -0.018391025 | BL13: 0.03696261 | BM13: 0.01505625 | BN13: 0.010892739 | BO13: 0.031735312 | BP13: 0.0076519468 | BQ13: 0.040819097 | BR13: -0.0070713815 | BS13: 0.0072582425 | BT13: 0.038343506 | BU13: 0.016526995 | BV13: 0.020643875 | BW13: 0.0017632378 | BX13: 0.021785491 | BY13: -0.014512398 | BZ13: 0.076927871 | CA13: -0.033531566 | CB13: -0.0071318694 | CC13: -0.012132616 | CD13: 0.10549188 | CE13: 0.01196831 | CF13: 0.046939453 | CG13: 0.037015272 | CH13: 0.058334612 | CI13: -0.051853509 | CJ13: -0.0038766003 | CK13: 0.032045269 | CL13: 0.084304391 | CM13: -0.010296804 | CN13: -0.026887566 | CO13: -0.013457459 | CP13: 0.070797472 | CQ13: 0.037948965 | CR13: 0.0086327962 | CS13: 0.01207816 | CT13: 0.0080707993 | CU13: 0.036006916 | CV13: -0.0022303746 | CW13: 0.0059770309 | CX13: 0.060643762 | CY13: -0.01311874 | CZ13: 0.05722422 | DA13: -0.007096531 | DB13: -0.040988946 | DC13: 0.029740185 | DD13: 0.0096115358 | DE13: 0.0051676529 | DF13: -0.028518797 | DG13: -0.0016306572 | DH13: 0.012992245 | DI13: -0.046561457 | DJ13: 0.00028247997 | DK13: 0.01202679 | DL13: -0.015654552 | DM13: -0.006658869 | DN13: 0.014839798 | DO13: 0.048531513 | DP13: 0.047238153 | DQ13: -0.026430081 | DR13: 0.013771209 | DS13: -0.038502775 | DT13: -0.035426301 | DU13: 0.020848415 | DV13: 0.079620144 | DW13: 0.045686979 | DX13: -0.064641919 | DY13: 0.035306138 | DZ13: -0.011770466 | EA13: 0.076590366 | EB13: 0.021373218 | EC13: 0.041659753 | ED13: -0.065682094 | EE13: 0.0087380257 | EF13: 0.067291157
A14: 50 | B14: 19 | C14: -0.030371566 | D14: 0.22230879 | E14: -0.047525943 | F14: 0.034543211 | G14: 0.085149211 | H14: 0.059588947 | I14: 0.04378736 | J14: -0.10509358 | K14: 0.012451474 | L14: -0.0084802105 | M14: -0.075951368 | N14: 0.20483268 | O14: 0.039642368 | P14: -0.058345922 | Q14: 0.058239053 | R14: -0.014151684 | S14: -0.16589323 | T14: -0.017361737 | U14: 0.036578263 | V14: -0.038374316 | W14: 0.11616537 | X14: -0.11440831 | Y14: -0.016763579 | Z14: 0.021252 | AA14: -0.0026256842 | AB14: -0.074982632 | AC14: -0.029292632 | AD14: 0.039327947 | AE14: -0.10743434 | AF14: 0.084317789 | AG14: 0.0063905789 | AH14: 0.063409947 | AI14: 0.010965316 | AJ14: 0.10046316 | AK14: -0.011509421 | AL14: 0.03796919 | AM14: 0.0031484211 | AN14: 0.092260489 | AO14: -0.0099975789 | AP14: -0.069976525 | AQ14: -0.0081264211 | AR14: 0.018170474 | AS14: -0.082332976 | AT14: 0.040924566 | AU14: 0.047021354 | AV14: -0.022684786 | AW14: -0.015421378 | AX14: 0.13695103 | AY14: 0.015068119 | AZ14: -0.053158248 | BA14: 0.020125911 | BB14: 0.061734282 | BC14: -0.0090839235 | BD14: 0.043327782 | BE14: 0.043176244 | BF14: 0.040770522 | BG14: 0.041374264 | BH14: -0.00028344417 | BI14: 0.052014236 | BJ14: -0.013254279 | BK14: -8.732528e-05 | BL14: 0.059737767 | BM14: 0.032002837 | BN14: 0.020936538 | BO14: 0.033609046 | BP14: 0.012822667 | BQ14: 0.012049423 | BR14: -0.02792943 | BS14: -0.038629204 | BT14: 0.073139129 | BU14: -0.0088548354 | BV14: 0.028891422 | BW14: 0.012507948 | BX14: 0.053858362 | BY14: -0.018521873 | BZ14: 0.11178052 | CA14: -0.024465266 | CB14: 0.022127617 | CC14: -0.020156605 | CD14: 0.09801671 | CE14: -0.072156719 | CF14: 0.095391142 | CG14: 0.053067028 | CH14: 0.064661392 | CI14: -0.10588478 | CJ14: -0.032530407 | CK14: 0.014016364 | CL14: 0.062269955 | CM14: 0.03204001 | CN14: -0.020479398 | CO14: -0.07358772 | CP14: 0.099809331 | CQ14: 0.053211628 | CR14: 0.056678555 | CS14: 0.05902712 | CT14: 0.019100577 | CU14: -0.044544442 | CV14: 0.022745715 | CW14: -0.0033983825 | CX14: 0.032764329 | CY14: -0.02875912 | CZ14: 0.064063563 | DA14: -0.024304289 | DB14: -0.016342777 | DC14: 0.027534093 | DD14: -0.01675855 | DE14: 0.0053842996 | DF14: -0.03977046 | DG14: 0.011446556 | DH14: 0.0047748372 | DI14: -0.053191997 | DJ14: 0.0010237243 | DK14: 0.018317376 | DL14: -0.015165162 | DM14: 0.0055042691 | DN14: 0.039851708 | DO14: 0.041375645 | DP14: 0.040532228 | DQ14: -0.08936786 | DR14: 0.052622519 | DS14: -0.035044906 | DT14: -0.044433184 | DU14: -0.044914949 | DV14: 0.10826235 | DW14: 0.091809329 | DX14: -0.10216122 | DY14: 0.03799708 | DZ14: -0.0043403396 | EA14: 0.078105266 | EB14: 0.0070174744 | EC14: 0.0060793821 | ED14: -0.10262971 | EE14: 0.01868795 | EF14: 0.066632347
A15: 100 | B15: 10 | C15: -0.096503142 | D15: 0.3727097 | E15: -0.010198426 | F15: 0.0903046 | G15: 0.0966062 | H15: 0.1188444 | I15: 0.058431444 | J15: -0.0645242 | K15: -0.004211 | L15: 0.0129669 | M15: -0.1884914 | N15: 0.3303096 | O15: 0.0461035 | P15: -0.064116183 | Q15: 0.1003768 | R15: 0.0167552 | S15: -0.27023205 | T15: -0.0493397 | U15: 0.0467887 | V15: -0.0856804 | W15: 0.1069346 | X15: -0.12684333 | Y15: -0.0241897 | Z15: -0.0236562 | AA15: 0.0465889 | AB15: -0.0739954 | AC15: -0.0400548 | AD15: 0.0396904 | AE15: -0.10131332 | AF15: 0.0497735 | AG15: -0.009745 | AH15: -0.0145018 | AI15: 0.0742774 | AJ15: 0.0041834 | AK15: -0.0369981 | AL15: 0.040555655 | AM15: 0.0019435 | AN15: 0.092861913 | AO15: 0.0357023 | AP15: -0.086457767 | AQ15: -0.0197473 | AR15: 0.0245503 | AS15: -0.053821179 | AT15: 0.065254991 | AU15: 0.039943261 | AV15: -0.047226818 | AW15: 0.015659939 | AX15: 0.12523398 | AY15: 0.028109416 | AZ15: -0.09132328 | BA15: 0.010613515 | BB15: 0.11120235 | BC15: 0.062155144 | BD15: 0.04294982 | BE15: 0.039146515 | BF15: 0.051177887 | BG15: 0.0028248221 | BH15: 0.033556537 | BI15: 0.068586659 | BJ15: -0.015619103 | BK15: -0.011156368 | BL15: 0.062748176 | BM15: 0.065206883 | BN15: 0.04014257 | BO15: 0.027734476 | BP15: 0.014184221 | BQ15: 0.012802931 | BR15: -0.050157429 | BS15: -0.016823777 | BT15: 0.089060206 | BU15: 0.01947642 | BV15: 0.059228937 | BW15: -0.03594589 | BX15: 0.020670546 | BY15: -0.087655118 | BZ15: 0.10290647 | CA15: -0.018592021 | CB15: 0.015056894 | CC15: -0.15350227 | CD15: 0.12015208 | CE15: -0.11664001 | CF15: 0.098469994 | CG15: -0.0042988793 | CH15: 0.062885958 | CI15: -0.027803072 | CJ15: -0.087044356 | CK15: 0.056672646 | CL15: 0.031421975 | CM15: 0.074631116 | CN15: -0.042634116 | CO15: -0.12944902 | CP15: 0.12753584 | CQ15: 0.036876324 | CR15: 0.046180622 | CS15: 0.060185172 | CT15: 0.007394575 | CU15: -0.06317866 | CV15: -0.0061418469 | CW15: -0.015390924 | CX15: 0.024039607 | CY15: -0.042470673 | CZ15: 0.077145074 | DA15: -0.026375835 | DB15: -0.030226618 | DC15: 0.024821107 | DD15: -0.035816313 | DE15: 0.024948715 | DF15: -0.042391306 | DG15: 0.016196732 | DH15: -0.018709011 | DI15: -0.011718449 | DJ15: -0.051522811 | DK15: 0.10177483 | DL15: 0.062635494 | DM15: -0.023808547 | DN15: 0.043996497 | DO15: 0.046296727 | DP15: 0.023735602 | DQ15: -0.099672215 | DR15: 0.039785608 | DS15: -0.083044917 | DT15: -0.072163632 | DU15: -0.045770729 | DV15: 0.13976836 | DW15: 0.025538627 | DX15: -0.11861625 | DY15: 0.10653917 | DZ15: -0.018920244 | EA15: 0.032239691 | EB15: 0.048518573 | EC15: 0.050736499 | ED15: -0.11335706 | EE15: -0.02245854 | EF15: 0.062208305
A16: 107 | B16: 9 | C16: -0.027383645 | D16: 0.40819544 | E16: -0.0028301766 | F16: 0.10741956 | G16: 0.10901356 | H16: 0.072848778 | I16: 0.057530619 | J16: -0.068693444 | K16: 0.017924444 | L16: 0.031026556 | M16: -0.19487578 | N16: 0.36698789 | O16: 0.015621111 | P16: -0.061045232 | Q16: 0.096619889 | R16: 0.019182444 | S16: -0.2854546 | T16: -0.023227444 | U16: 0.048649667 | V16: -0.10431522 | W16: 0.078373444 | X16: -0.12440978 | Y16: -0.0042885556 | Z16: -0.020075778 | AA16: 0.050227667 | AB16: -0.071016 | AC16: -0.041040111 | AD16: 0.034811 | AE16: -0.09650236 | AF16: 0.015010333 | AG16: -0.0083015556 | AH16: -0.044108444 | AI16: 0.090523111 | AJ16: -0.01763 | AK16: -0.0079863333 | AL16: 0.048688933 | AM16: 0.023732556 | AN16: 0.1064562 | AO16: 0.040042556 | AP16: -0.077798368 | AQ16: -0.024032556 | AR16: 0.032492222 | AS16: -0.065068225 | AT16: 0.059867139 | AU16: 0.041826838 | AV16: -0.0090725068 | AW16: 0.03925293 | AX16: 0.10082977 | AY16: 0.03381259 | AZ16: -0.10490964 | BA16: 0.0098081985 | BB16: 0.10803892 | BC16: 0.066102245 | BD16: 0.035936712 | BE16: 0.051410994 | BF16: 0.064268054 | BG16: 0.013845819 | BH16: -0.0054124801 | BI16: 0.05233576 | BJ16: -0.020503816 | BK16: -0.0021229518 | BL16: 0.070623566 | BM16: 0.091107172 | BN16: 0.047905833 | BO16: 0.02189036 | BP16: 0.011747198 | BQ16: 0.013312454 | BR16: -0.026296848 | BS16: -0.013191573 | BT16: 0.085483191 | BU16: 0.05776511 | BV16: 0.063782488 | BW16: -0.065740927 | BX16: 0.031559238 | BY16: -0.077354776 | BZ16: 0.11152585 | CA16: -0.017116104 | CB16: -0.001428045 | CC16: -0.15907251 | CD16: 0.15507127 | CE16: -0.13259506 | CF16: 0.10520126 | CG16: 0.0064480215 | CH16: 0.041697415 | CI16: -0.038709882 | CJ16: -0.045523551 | CK16: 0.076472984 | CL16: 0.019995369 | CM16: 0.088988628 | CN16: -0.033057515 | CO16: -0.17087869 | CP16: 0.13761382 | CQ16: 0.040878176 | CR16: 0.048299767 | CS16: 0.064948402 | CT16: 0.0050674065 | CU16: -0.064113369 | CV16: -0.017860959 | CW16: -0.012423342 | CX16: 0.012240285 | CY16: -0.049117049 | CZ16: 0.10263326 | DA16: -0.029804794 | DB16: -0.04271217 | DC16: 0.035357719 | DD16: -0.059977075 | DE16: -0.031193128 | DF16: -0.023146433 | DG16: 0.014452948 | DH16: -0.019129343 | DI16: -0.013233426 | DJ16: -0.036643143 | DK16: 0.13359436 | DL16: 0.071494375 | DM16: -0.03033095 | DN16: 0.042437853 | DO16: 0.052411859 | DP16: 0.019841949 | DQ16: -0.083033658 | DR16: 0.055191252 | DS16: -0.093752065 | DT16: -0.10069332 | DU16: -0.064473734 | DV16: 0.13695373 | DW16: 0.04091773 | DX16: -0.12528471 | DY16: 0.11635433 | DZ16: -0.03127708 | EA16: 0.046661372 | EB16: 0.077977783 | EC16: 0.051117652 | ED16: -0.11541675 | EE16: -0.03305827 | EF16: 0.039893907
A17: 120 | B17: 8 | C17: -0.045056429 | D17: 0.43958837 | E17: 0.0073790015 | F17: 0.146772 | G17: 0.11713263 | H17: 0.10499475 | I17: 0.11372503 | J17: -0.11529837 | K17: 0.03944375 | L17: 0.033774875 | M17: -0.22693988 | N17: 0.40510825 | O17: 0.024632125 | P17: -0.068410774 | Q17: 0.10643237 | R17: 0.001975 | S17: -0.31065343 | T17: -0.023508375 | U17: 0.052288375 | V17: -0.11635513 | W17: 0.079142125 | X17: -0.15721263 | Y17: 0.001499125 | Z17: -0.0216085 | AA17: 0.062256125 | AB17: -0.058334375 | AC17: -0.040799125 | AD17: 0.068619875 | AE17: -0.12715842 | AF17: 0.008412625 | AG17: -0.00135125 | AH17: -0.031922875 | AI17: 0.11486512 | AJ17: -0.010273125 | AK17: -0.013324625 | AL17: 0.050724406 | AM17: 0.027869125 | AN17: 0.11328712 | AO17: 0.030703875 | AP17: -0.077242814 | AQ17: -0.009230375 | AR17: 0.034996625 | AS17: -0.056323562 | AT17: 0.052267806 | AU17: 0.052648231 | AV17: -0.021508363 | AW17: 0.019163974 | AX17: 0.096240559 | AY17: 0.027423697 | AZ17: -0.12511082 | BA17: 0.0098251791 | BB17: 0.12376406 | BC17: 0.082716572 | BD17: 0.022356482 | BE17: 0.077350242 | BF17: 0.055197497 | BG17: -0.035394236 | BH17: -0.0017313848 | BI17: 0.099365392 | BJ17: -0.0098580643 | BK17: -0.013822952 | BL17: 0.073931305 | BM17: 0.07599777 | BN17: 0.047729619 | BO17: 0.019886081 | BP17: 0.026837501 | BQ17: 0.01137651 | BR17: -0.00091794541 | BS17: -0.0041034691 | BT17: 0.10941638 | BU17: 0.071127819 | BV17: 0.074446901 | BW17: -0.080431713 | BX17: 0.028822965 | BY17: -0.10018207 | BZ17: 0.12057816 | CA17: -0.027934832 | CB17: -0.0013353103 | CC17: -0.17495797 | CD17: 0.17295974 | CE17: -0.17511625 | CF17: 0.098746197 | CG17: -0.0022222469 | CH17: 0.058636447 | CI17: -0.014531185 | CJ17: -0.050742321 | CK17: 0.091738573 | CL17: -0.0094263448 | CM17: 0.13456934 | CN17: -0.026718061 | CO17: -0.20253863 | CP17: 0.14815927 | CQ17: 0.041087933 | CR17: 0.048737641 | CS17: 0.093039921 | CT17: 0.049260056 | CU17: -0.074408308 | CV17: 0.0038796079 | CW17: -0.019761854 | CX17: 0.010772395 | CY17: -0.049383299 | CZ17: 0.12424884 | DA17: -0.043895859 | DB17: -0.034883011 | DC17: 0.043363469 | DD17: -0.085133933 | DE17: -0.033180931 | DF17: -0.01123137 | DG17: 0.0069345764 | DH17: -0.038726651 | DI17: -0.0052932443 | DJ17: -0.045336158 | DK17: 0.15603643 | DL17: 0.073515601 | DM17: -0.052252911 | DN17: 0.035489033 | DO17: 0.05345137 | DP17: -0.016878609 | DQ17: -0.10770247 | DR17: 0.055884815 | DS17: -0.12431616 | DT17: -0.093980212 | DU17: -0.071730706 | DV17: 0.1177654 | DW17: 0.048681483 | DX17: -0.12953898 | DY17: 0.10312068 | DZ17: -0.048145299 | EA17: 0.011817924 | EB17: 0.087100349 | EC17: 0.016425217 | ED17: -0.12832444 | EE17: -0.02541336 | EF17: 0.047709767
A18: 137 | B18: 7 | C18: -0.053942228 | D18: 0.401884 | E18: -0.059000657 | F18: 0.21209086 | G18: 0.13305871 | H18: 0.12854 | I18: 0.13550018 | J18: -0.12516086 | K18: 0.031585286 | L18: 0.046671571 | M18: -0.25351286 | N18: 0.46182043 | O18: 0.024324143 | P18: -0.080174184 | Q18: 0.12173871 | R18: 0.019326571 | S18: -0.38373263 | T18: -0.0050295714 | U18: 0.028133571 | V18: -0.131253 | W18: 0.077297 | X18: -0.15584823 | Y18: 0.024211857 | Z18: -0.016905571 | AA18: 0.054805571 | AB18: -0.061714 | AC18: -0.074719857 | AD18: 0.096285857 | AE18: -0.14352924 | AF18: -0.0017495714 | AG18: -0.0086178571 | AH18: -0.035914857 | AI18: 0.11808643 | AJ18: -0.0073281429 | AK18: 0.027291286 | AL18: 0.045860126 | AM18: 0.009859 | AN18: 0.07929464 | AO18: 0.046668714 | AP18: -0.078278592 | AQ18: 0.016788143 | AR18: 0.061694429 | AS18: -0.085826552 | AT18: 0.04332565 | AU18: 0.06831534 | AV18: -0.028768756 | AW18: 0.024538034 | AX18: 0.10756087 | AY18: 0.034783279 | AZ18: -0.14840908 | BA18: -0.00051212561 | BB18: 0.13312051 | BC18: 0.083201573 | BD18: -0.024016272 | BE18: 0.068361213 | BF18: 0.045884536 | BG18: -0.034434629 | BH18: 0.030015992 | BI18: 0.10900001 | BJ18: 0.0059560641 | BK18: -0.050745051 | BL18: 0.081157674 | BM18: 0.10277394 | BN18: 0.05277439 | BO18: 0.020227496 | BP18: 0.04685754 | BQ18: 0.0019167841 | BR18: -0.0057481936 | BS18: -0.021497201 | BT18: 0.14287107 | BU18: 0.080677444 | BV18: 0.080923395 | BW18: -0.085311087 | BX18: 0.019018475 | BY18: -0.12307498 | BZ18: 0.15331999 | CA18: -0.016076544 | CB18: -0.024577357 | CC18: -0.028173444 | CD18: 0.19371682 | CE18: -0.16739394 | CF18: 0.069437751 | CG18: -0.0028013589 | CH18: 0.16265705 | CI18: -0.044565986 | CJ18: -0.062313678 | CK18: 0.090667784 | CL18: -0.030989545 | CM18: 0.1596358 | CN18: -0.037997037 | CO18: -0.23157388 | CP18: 0.16283911 | CQ18: 0.047976536 | CR18: 0.055156129 | CS18: 0.087017131 | CT18: 0.094951029 | CU18: -0.071648691 | CV18: 0.091040282 | CW18: -0.0084560856 | CX18: 0.061560186 | CY18: -0.051357414 | CZ18: 0.13284286 | DA18: -0.04738094 | DB18: -0.045735209 | DC18: 0.036408781 | DD18: -0.082462353 | DE18: -0.034801348 | DF18: -0.035042779 | DG18: -0.0076194732 | DH18: -0.028038013 | DI18: -0.016114629 | DJ18: -0.04520404 | DK18: 0.15851363 | DL18: 0.081397743 | DM18: -0.066508141 | DN18: -0.016722064 | DO18: 0.042104908 | DP18: -0.020604686 | DQ18: -0.10072728 | DR18: 0.076840655 | DS18: -0.147722 | DT18: -0.11601739 | DU18: -0.096895186 | DV18: 0.10564061 | DW18: 0.081908692 | DX18: -0.15360298 | DY18: 0.097428037 | DZ18: -0.075516359 | EA18: -0.0063615627 | EB18: 0.099846378 | EC18: 0.0058228475 | ED18: -0.12007743 | EE18: -0.013853754 | EF18: 0.048955017
A19: 160 | B19: 6 | C19: -0.077959416 | D19: 0.40752133 | E19: -0.048100232 | F19: 0.23617083 | G19: 0.15286517 | H19: 0.17761017 | I19: 0.13465433 | J19: -0.15622917 | K19: 0.0565395 | L19: 0.030361167 | M19: -0.26154167 | N19: 0.5323745 | O19: -0.019797 | P19: -0.092534186 | Q19: 0.17046433 | R19: 0.041943 | S19: -0.16657057 | T19: -0.10952683 | U19: 0.044184167 | V19: -0.1186835 | W19: 0.072415833 | X19: -0.12008629 | Y19: 0.024062167 | Z19: -0.022223 | AA19: 0.047301667 | AB19: -0.0607625 | AC19: -0.083512833 | AD19: 0.095992833 | AE19: -0.16941606 | AF19: 0.00026383333 | AG19: 0.0192985 | AH19: -0.016091333 | AI19: 0.091549333 | AJ19: 0.012166333 | AK19: 0.049060667 | AL19: 0.070270946 | AM19: 0.0105325 | AN19: 0.083568294 | AO19: 0.057746833 | AP19: -0.08757412 | AQ19: 0.054927833 | AR19: 0.074616833 | AS19: -0.097796955 | AT19: 0.049294982 | AU19: 0.076428716 | AV19: -0.048463102 | AW19: 0.022356168 | AX19: 0.080206414 | AY19: 0.02952897 | AZ19: -0.18687962 | BA19: -0.034363884 | BB19: 0.1597462 | BC19: 0.064055486 | BD19: -0.0032343926 | BE19: 0.053867498 | BF19: 0.013570974 | BG19: -0.016343658 | BH19: 0.0020182017 | BI19: 0.12779863 | BJ19: 0.021707302 | BK19: -0.051749526 | BL19: 0.079964658 | BM19: 0.1142506 | BN19: 0.067252647 | BO19: 0.025728961 | BP19: 0.037426263 | BQ19: 0.0099340445 | BR19: 0.006675246 | BS19: -0.024256339 | BT19: 0.14163268 | BU19: 0.075936251 | BV19: 0.093655241 | BW19: -0.10896696 | BX19: 0.034087785 | BY19: -0.10764974 | BZ19: 0.063815394 | CA19: -0.02154569 | CB19: -0.048041169 | CC19: -0.024723253 | CD19: 0.2070858 | CE19: -0.19826583 | CF19: 0.084971509 | CG19: -0.05063353 | CH19: 0.15288987 | CI19: -0.037066946 | CJ19: -0.0619405 | CK19: 0.10396772 | CL19: -0.04324028 | CM19: 0.17534764 | CN19: -0.076932655 | CO19: -0.2724544 | CP19: 0.1590326 | CQ19: -0.0027299082 | CR19: 0.049337666 | CS19: 0.060700851 | CT19: 0.12262043 | CU19: -0.083436397 | CV19: 0.089836091 | CW19: -0.021901808 | CX19: 0.093549718 | CY19: -0.07092187 | CZ19: 0.10046473 | DA19: -0.058223877 | DB19: -0.035720899 | DC19: -0.0351794 | DD19: -0.10452863 | DE19: -0.043945636 | DF19: -0.069693047 | DG19: -0.012746475 | DH19: -0.00015698313 | DI19: 0.0036664244 | DJ19: -0.048514351 | DK19: 0.12414459 | DL19: 0.070167408 | DM19: -0.081952255 | DN19: -0.0041776448 | DO19: 0.055126563 | DP19: 0.027165443 | DQ19: -0.12048938 | DR19: 0.075962353 | DS19: -0.17799555 | DT19: -0.1331285 | DU19: -0.1428307 | DV19: 0.11953184 | DW19: 0.060609139 | DX19: -0.13836513 | DY19: 0.070109578 | DZ19: -0.11192083 | EA19: -0.028079353 | EB19: 0.02177277 | EC19: -0.0086215225 | ED19: -0.15093532 | EE19: 0.012634043 | EF19: 0.016977955
A20: 192 | B20: 5 | C20: -0.1393246 | D20: 0.3820258 | E20: 0.021392427 | F20: 0.1824192 | G20: 0.1580282 | H20: 0.1439322 | I20: 0.15814956 | J20: -0.1332062 | K20: 0.0374036 | L20: 0.0306936 | M20: -0.268694 | N20: 0.5000116 | O20: -0.1101138 | P20: -0.091169928 | Q20: 0.2248266 | R20: 0.0664696 | S20: -0.16233623 | T20: -0.1008458 | U20: 0.032235 | V20: -0.1362882 | W20: 0.091085 | X20: -0.1528339 | Y20: -0.004858 | Z20: 0.0291584 | AA20: 0.066964 | AB20: -0.060423 | AC20: -0.0963082 | AD20: 0.1298426 | AE20: -0.17528151 | AF20: -0.0064676 | AG20: -0.0062396 | AH20: -0.027809 | AI20: 0.1163372 | AJ20: 0.0172406 | AK20: 0.0669686 | AL20: 0.072893452 | AM20: 0.0327386 | AN20: 0.075470194 | AO20: 0.068086 | AP20: -0.13173046 | AQ20: -0.0728986 | AR20: 0.0132892 | AS20: -0.11209581 | AT20: 0.0058587738 | AU20: 0.072899818 | AV20: -0.054625714 | AW20: 0.0068652682 | AX20: 0.11073255 | AY20: 0.038674698 | AZ20: -0.21380243 | BA20: -0.054045134 | BB20: 0.16765542 | BC20: 0.070605568 | BD20: -0.053429813 | BE20: -0.0059467971 | BF20: 0.0056885823 | BG20: 0.02249484 | BH20: -0.071606447 | BI20: 0.13174527 | BJ20: 0.021629512 | BK20: -0.059233168 | BL20: 0.086292231 | BM20: 0.13691766 | BN20: 0.084339641 | BO20: -0.038461718 | BP20: 0.060407521 | BQ20: 0.015451707 | BR20: 0.0082000826 | BS20: -0.0021226836 | BT20: 0.14780303 | BU20: 0.098754949 | BV20: 0.11591833 | BW20: -0.13550325 | BX20: 0.030693637 | BY20: -0.10523397 | BZ20: 0.090271404 | CA20: -0.0019938221 | CB20: -0.03825195 | CC20: 9.4695451e-05 | CD20: 0.1810275 | CE20: -0.2439638 | CF20: 0.080957937 | CG20: -0.099052889 | CH20: 0.071864026 | CI20: -0.030394674 | CJ20: -0.12344032 | CK20: 0.090978397 | CL20: -0.092184934 | CM20: 0.18905117 | CN20: 0.022159411 | CO20: -0.41597134 | CP20: 0.19203121 | CQ20: 0.0061113579 | CR20: 0.073116245 | CS20: 0.088364277 | CT20: 0.090474037 | CU20: -0.1041009 | CV20: 0.092511076 | CW20: 0.0099530629 | CX20: 0.090298551 | CY20: -0.012479733 | CZ20: 0.15516165 | DA20: -0.047471893 | DB20: -0.05690271 | DC20: -0.047084133 | DD20: -0.14810881 | DE20: -0.026749864 | DF20: 0.00085912153 | DG20: -0.0042022106 | DH20: -0.010975412 | DI20: -0.007757568 | DJ20: -0.039459946 | DK20: 0.084953981 | DL20: 0.075826636 | DM20: 0.0092836503 | DN20: 0.058019207 | DO20: 0.065815802 | DP20: 0.0098305314 | DQ20: -0.19132954 | DR20: 0.07851266 | DS20: -0.2060811 | DT20: -0.1272747 | DU20: -0.17206911 | DV20: 0.12934547 | DW20: 0.069060204 | DX20: -0.15386633 | DY20: 0.053618609 | DZ20: -0.084474578 | EA20: 0.013808726 | EB20: 0.027389158 | EC20: 0.034049581 | ED20: -0.17691886 | EE20: 0.0023672309 | EF20: 0.020281417
A21: 241 | B21: 4 | C21: -0.19764916 | D21: 0.126389 | E21: -0.00027935227 | F21: 0.203413 | G21: 0.145332 | H21: 0.162164 | I21: 0.14725561 | J21: -0.1367415 | K21: 0.00147 | L21: -0.005031 | M21: -0.199885 | N21: 0.5848905 | O21: -0.13927725 | P21: -0.1447726 | Q21: 0.27408575 | R21: 0.08490525 | S21: -0.12859029 | T21: -0.13112 | U21: -0.00982675 | V21: -0.13175025 | W21: 0.12449875 | X21: -0.19733718 | Y21: -0.0101475 | Z21: 0.039459 | AA21: 0.0280355 | AB21: -0.065287 | AC21: -0.15954125 | AD21: 0.1288245 | AE21: -0.24045611 | AF21: -0.0335655 | AG21: -0.010568 | AH21: -0.04340925 | AI21: 0.10212425 | AJ21: 0.0051835 | AK21: 0.1049905 | AL21: 0.065379823 | AM21: 0.03671075 | AN21: 0.11195606 | AO21: 0.09498575 | AP21: -0.062390554 | AQ21: -0.06719825 | AR21: -0.04798825 | AS21: -0.064455869 | AT21: -0.0024929113 | AU21: 0.047809632 | AV21: -0.05552078 | AW21: 0.00979103 | AX21: 0.14314769 | AY21: 0.047021291 | AZ21: -0.25491127 | BA21: -0.071032182 | BB21: 0.22559567 | BC21: 0.038321148 | BD21: -0.021750863 | BE21: 0.0063505334 | BF21: 0.0035771002 | BG21: 0.05002054 | BH21: -0.076321363 | BI21: 0.1659696 | BJ21: 0.023579026 | BK21: -0.06844988 | BL21: 0.14272109 | BM21: 0.15512 | BN21: 0.063647948 | BO21: -0.010668392 | BP21: 0.10450913 | BQ21: 0.054542231 | BR21: 0.013963257 | BS21: -0.025079854 | BT21: 0.13224469 | BU21: 0.12082094 | BV21: 0.142143 | BW21: -0.1466792 | BX21: -0.015407928 | BY21: -0.050379851 | BZ21: 0.09815671 | CA21: -0.024556069 | CB21: -0.11224361 | CC21: -0.046693549 | CD21: 0.28805606 | CE21: -0.30558931 | CF21: 0.13126568 | CG21: -0.14375119 | CH21: 0.080100321 | CI21: -0.080499616 | CJ21: -0.071754662 | CK21: 0.12705055 | CL21: -0.21045238 | CM21: 0.22550299 | CN21: 0.03053889 | CO21: -0.51486525 | CP21: 0.22270006 | CQ21: 0.0032880917 | CR21: 0.090824278 | CS21: 0.069646396 | CT21: 0.082292873 | CU21: -0.06267356 | CV21: 0.098225632 | CW21: 0.065005417 | CX21: 0.10212218 | CY21: -0.0084819164 | CZ21: 0.23745137 | DA21: 0.0011922565 | DB21: -0.034463409 | DC21: -0.038546271 | DD21: 0.12132269 | DE21: 0.012238109 | DF21: 0.0077285593 | DG21: 0.0078463781 | DH21: 0.01407682 | DI21: 0.034407478 | DJ21: -0.037911313 | DK21: 0.13950271 | DL21: 0.098364939 | DM21: -0.02983412 | DN21: 0.061960781 | DO21: 0.082445792 | DP21: 0.024266155 | DQ21: -0.12775339 | DR21: 0.050170859 | DS21: -0.20083947 | DT21: -0.1705708 | DU21: -0.028090294 | DV21: 0.14027598 | DW21: 0.11934722 | DX21: -0.18596621 | DY21: 0.024595996 | DZ21: -0.052844067 | EA21: -0.026250896 | EB21: 0.0084081462 | EC21: 0.0030649685 | ED21: -0.054498856 | EE21: 0.014428852 | EF21: -0.0079916029
A22: 321 | B22: 3 | C22: 0.064235718 | D22: 0.14242933 | E22: -0.041027532 | F22: -0.139868 | G22: 0.23294533 | H22: 0.124178 | I22: 0.12349317 | J22: -0.104252 | K22: 0.028656667 | L22: 0.014272 | M22: -0.18466333 | N22: 0.75614233 | O22: -0.066442333 | P22: -0.072782884 | Q22: 0.12727467 | R22: 0.066697667 | S22: -0.16964656 | T22: -0.104848 | U22: 0.052484333 | V22: -0.17562367 | W22: 0.158048 | X22: -0.21490005 | Y22: -0.069857333 | Z22: 0.023868 | AA22: 0.11812267 | AB22: -0.038273333 | AC22: -0.17721133 | AD22: 0.013571333 | AE22: -0.26268572 | AF22: -0.086403333 | AG22: -0.045970333 | AH22: 0.00048666667 | AI22: 0.11100467 | AJ22: 0.013081333 | AK22: -0.068266667 | AL22: 0.040340967 | AM22: 0.041473333 | AN22: 0.11113281 | AO22: 0.190673 | AP22: -0.062536354 | AQ22: -0.11012933 | AR22: -0.067924667 | AS22: -0.082810439 | AT22: 0.0065803903 | AU22: 0.053142792 | AV22: -0.059813177 | AW22: -0.030149389 | AX22: 0.1737634 | AY22: 0.071733385 | AZ22: -0.15490378 | BA22: -0.045598425 | BB22: 0.30192994 | BC22: -0.13083694 | BD22: 0.01294739 | BE22: 0.022216183 | BF22: 0.013638817 | BG22: 0.046279512 | BH22: -0.12796054 | BI22: 0.11108872 | BJ22: 0.054996415 | BK22: -0.041839636 | BL22: 0.16178034 | BM22: 0.10560448 | BN22: -0.015327552 | BO22: -0.097012896 | BP22: 0.07483555 | BQ22: 0.027830097 | BR22: 0.020813609 | BS22: -0.016372782 | BT22: 0.1305307 | BU22: 0.21294877 | BV22: 0.15854397 | BW22: -0.1746685 | BX22: 0.036637446 | BY22: -0.0047467864 | BZ22: 0.047257736 | CA22: -0.027490078 | CB22: -0.14899328 | CC22: -0.014985703 | CD22: 0.33387804 | CE22: -0.39338734 | CF22: 0.18879979 | CG22: -0.20326309 | CH22: 0.11591877 | CI22: -0.11777975 | CJ22: -0.10337951 | CK22: 0.036163343 | CL22: -0.2406518 | CM22: 0.30176026 | CN22: -0.0085467718 | CO22: -0.64995647 | CP22: 0.25940856 | CQ22: -0.012333779 | CR22: 0.16185042 | CS22: -0.015202184 | CT22: 0.058232521 | CU22: -0.11084142 | CV22: 0.1122337 | CW22: 0.036451253 | CX22: 0.0037495933 | CY22: -0.0079888258 | CZ22: 0.26292048 | DA22: -0.0039917539 | DB22: -0.030263359 | DC22: -0.03949433 | DD22: 0.1478941 | DE22: -0.005491758 | DF22: 0.017031775 | DG22: 0.031985043 | DH22: 0.013945346 | DI22: 0.063560999 | DJ22: -0.050246006 | DK22: 0.17913471 | DL22: 0.12494165 | DM22: -0.063466051 | DN22: 0.046763328 | DO22: 0.1234375 | DP22: 0.0021723233 | DQ22: -0.131031 | DR22: -0.0060925526 | DS22: -0.19705092 | DT22: -0.026376356 | DU22: -0.057495391 | DV22: 0.12570512 | DW22: 0.10950307 | DX22: -0.22244261 | DY22: -0.0081471166 | DZ22: -0.10374798 | EA22: -0.070548649 | EB22: -0.080596728 | EC22: 0.021495102 | ED22: -0.077413567 | EE22: 0.033446304 | EF22: -0.034790246
A23: 482 | B23: 2 | C23: -0.034987009 | D23: 0.254094 | E23: -0.080941173 | F23: -0.003742 | G23: 0.361632 | H23: -0.0181885 | I23: 0.14815203 | J23: -0.1148755 | K23: -0.0599185 | L23: 0.050771 | M23: -0.1472895 | N23: 0.975901 | O23: -0.1229 | P23: -0.090401711 | Q23: 0.2911775 | R23: 0.06282 | S23: -0.11372453 | T23: -0.084677 | U23: 0.0592365 | V23: -0.2324755 | W23: 0.259547 | X23: -0.26408569 | Y23: -0.0679545 | Z23: 0.041052 | AA23: 0.151652 | AB23: -0.047748 | AC23: -0.2340085 | AD23: 0.071627 | AE23: -0.36197538 | AF23: -0.0252995 | AG23: -0.0020555 | AH23: 0.037278 | AI23: 0.209152 | AJ23: 0.023587 | AK23: 0.01856 | AL23: 0.13143171 | AM23: 0.086695 | AN23: 0.2423147 | AO23: 0.3464845 | AP23: 0.0031210994 | AQ23: -0.099379 | AR23: -0.146136 | AS23: 0.014706888 | AT23: -0.041427722 | AU23: 0.033145526 | AV23: -0.027638994 | AW23: -0.05202691 | AX23: 0.069838154 | AY23: 0.17023398 | AZ23: -0.063753617 | BA23: 0.0096467801 | BB23: -0.051049484 | BC23: -0.30082825 | BD23: 0.094830881 | BE23: -0.071430762 | BF23: -0.022846991 | BG23: 0.074761471 | BH23: -0.20348398 | BI23: 0.19111208 | BJ23: 0.10400332 | BK23: 0.0046869777 | BL23: 0.1495343 | BM23: 0.18918069 | BN23: -0.0069471708 | BO23: -0.16631017 | BP23: 0.098266399 | BQ23: 0.049611841 | BR23: 0.017844321 | BS23: -0.073275389 | BT23: 0.14364981 | BU23: 0.20568774 | BV23: 0.11346757 | BW23: -0.20215233 | BX23: -0.0082131197 | BY23: -0.010205693 | BZ23: 0.0076697624 | CA23: -0.0756532 | CB23: -0.2176142 | CC23: 0.22495863 | CD23: 0.19167646 | CE23: -0.11662461 | CF23: 0.15713491 | CG23: -0.39324379 | CH23: 0.18019645 | CI23: -0.30989942 | CJ23: -0.019875368 | CK23: 0.096116995 | CL23: -0.40866101 | CM23: 0.38673295 | CN23: -0.053005178 | CO23: -0.90892329 | CP23: 0.31136074 | CQ23: -0.0091837445 | CR23: 0.13872539 | CS23: -0.036974219 | CT23: 0.045662542 | CU23: -0.021056596 | CV23: -0.022245137 | CW23: 0.10090133 | CX23: -0.088716994 | CY23: 0.022046531 | CZ23: 0.18199879 | DA23: -0.030982136 | DB23: -0.015955157 | DC23: 0.11919049 | DD23: 0.20992709 | DE23: -0.009395226 | DF23: 0.061942127 | DG23: 0.038270012 | DH23: 0.055413447 | DI23: 0.053479597 | DJ23: -0.087058008 | DK23: 0.27783322 | DL23: 0.21610106 | DM23: -0.019497305 | DN23: 0.006497196 | DO23: 0.1640913 | DP23: 0.047088233 | DQ23: -0.170211 | DR23: -0.089886003 | DS23: -0.28809658 | DT23: -0.12395522 | DU23: 0.034287185 | DV23: 0.27627161 | DW23: 0.14122823 | DX23: -0.31349321 | DY23: 0.16987683 | DZ23: -0.085690902 | EA23: -0.023448908 | EB23: -0.06275344 | EC23: -0.036584316 | ED23: -0.091425905 | EE23: 0.059050684 | EF23: -0.047782279
A24: 964 | B24: 1 | C24: 0.16299314 | D24: 0.10061 | E24: 0.07140033 | F24: 0.075326 | G24: 0.229607 | H24: 0.035856 | I24: -0.0021119332 | J24: -0.115461 | K24: 0.053733 | L24: 0.0938 | M24: -0.217786 | N24: 1.769032 | O24: -0.24428 | P24: -0.10424841 | Q24: -0.00284 | R24: -0.027827 | S24: -0.35251446 | T24: -0.28782 | U24: 0.285853 | V24: -0.09868 | W24: -0.164562 | X24: -0.11802243 | Y24: -0.120319 | Z24: -0.024395 | AA24: 0.094362 | AB24: -0.184249 | AC24: -0.24617 | AD24: 0.101174 | AE24: -0.54125812 | AF24: -0.165702 | AG24: 0.105901 | AH24: -0.068617 | AI24: 0.310414 | AJ24: 0.085435 | AK24: 0.00144 | AL24: -0.054676935 | AM24: 0.078599 | AN24: 0.22118947 | AO24: 0.082692 | AP24: -0.022851715 | AQ24: -0.217124 | AR24: -0.170833 | AS24: 0.027956077 | AT24: 0.030459207 | AU24: 0.04409532 | AV24: -0.087151952 | AW24: 0.0049875415 | AX24: 0.028306187 | AY24: 0.16812729 | AZ24: 0.037867074 | BA24: -0.053794732 | BB24: -0.086159033 | BC24: -0.59942164 | BD24: 0.18559522 | BE24: -0.046064354 | BF24: 0.087651336 | BG24: 0.026835966 | BH24: -0.38625534 | BI24: 0.22362911 | BJ24: 0.0033483158 | BK24: 0.0040235469 | BL24: 0.31716429 | BM24: 0.011473019 | BN24: 0.0068493418 | BO24: -0.16110969 | BP24: 0.12335118 | BQ24: -0.064169633 | BR24: 0.042356223 | BS24: -0.0012847175 | BT24: 0.1162707 | BU24: 0.22832663 | BV24: 0.10772845 | BW24: -0.061835884 | BX24: -0.13296006 | BY24: 0.10974567 | BZ24: 0.2588929 | CA24: -0.11522168 | CB24: 0.20876197 | CC24: 0.43985451 | CD24: 0.032392267 | CE24: -0.21012144 | CF24: 0.22172136 | CG24: -0.32381798 | CH24: 0.3542773 | CI24: 0.32845182 | CJ24: 0.013109485 | CK24: 0.093530079 | CL24: 0.14175533 | CM24: 0.54958711 | CN24: -0.10773877 | CO24: -0.77665322 | CP24: 0.28781577 | CQ24: 0.11468717 | CR24: 0.061084838 | CS24: -0.085895233 | CT24: 0.096419008 | CU24: -0.072751348 | CV24: 0.015064048 | CW24: 0.17511717 | CX24: 0.055207194 | CY24: -0.080066905 | CZ24: 0.11220663 | DA24: 0.024511204 | DB24: -0.19546067 | DC24: 0.1944536 | DD24: 0.15338138 | DE24: -0.17606276 | DF24: -0.10466498 | DG24: 0.059105834 | DH24: 0.09936698 | DI24: 0.14187546 | DJ24: -0.13248861 | DK24: 0.33950921 | DL24: 0.21310443 | DM24: -0.14143953 | DN24: 0.23333457 | DO24: 0.1854408 | DP24: 0.11437343 | DQ24: -0.13297735 | DR24: -0.02051563 | DS24: -0.21626154 | DT24: -0.038362866 | DU24: -0.047638587 | DV24: 0.1582247 | DW24: 0.10885709 | DX24: -0.31159313 | DY24: 0.34380429 | DZ24: -0.050469182 | EA24: 0.077350922 | EB24: 0.028371737 | EC24: -0.014309919 | ED24: -0.056172845 | EE24: 0.11342944 | EF24: 0.067276677
A26: 大盤 | B26: TWⅡ | C26: -0.017446771 | D26: 0.020701061 | E26: 0.023982129 | F26: -0.006557579 | G26: 0.03184513 | H26: 0.034348533 | I26: -0.0082549328 | J26: 0.012843524 | K26: -0.051018525 | L26: 0.00087394274 | M26: 0.023389576 | N26: 0.012988972 | O26: 0.0058545887 | P26: 0.027413207 | Q26: -0.0037129361 | R26: 0.024076614 | S26: -0.012190025 | T26: -0.039749578 | U26: -0.07315545 | V26: -0.05826023 | W26: 0.00077279757 | X26: 0.044591521 | Y26: -0.02769968 | Z26: 0.0020950059 | AA26: -0.023400551 | AB26: 0.032129371 | AC26: 0.038903273 | AD26: -0.042865382 | AE26: 0.018647195 | AF26: 0.015229768 | AG26: 0.036016604 | AH26: 0.0093546114 | AI26: 0.010748251 | AJ26: 0.013357754 | AK26: -0.0053327473 | AL26: 0.0013831358 | AM26: 0.020795928 | AN26: 0.031517702 | AO26: 0.0062417165 | AP26: 0.0061452617 | AQ26: 0.016946358 | AR26: 0.03468283 | AS26: 0.0030985886 | AT26: 0.015081347 | AU26: -0.019251209 | AV26: 0.038711513 | AW26: -0.021856951 | AX26: 0.0077743007 | AY26: 0.042397247 | AZ26: -0.026308975 | BA26: 0.0095717493 | BB26: -0.024249741 | BC26: 0.020163374 | BD26: -0.0035049988 | BE26: 0.020151935 | BF26: 0.00058133623 | BG26: -0.005219701 | BH26: -0.11587176 | BI26: 0.0087252257 | BJ26: -0.016377261 | BK26: 0.020840372 | BL26: 0.044975872 | BM26: 0.023954306 | BN26: 0.030239101 | BO26: -0.043725888 | BP26: 0.02188947 | BQ26: 0.0086274303 | BR26: -0.019192954 | BS26: 0.01973513 | BT26: 0.047694337 | BU26: 0.011454817 | BV26: 0.043228621 | BW26: -0.04274743 | BX26: -0.017811292 | BY26: -0.1511531 | BZ26: 0.124224 | CA26: -0.0045572538 | CB26: 0.06021124 | CC26: 0.085992033 | CD26: -0.0058084796 | CE26: -0.006041347 | CF26: 0.0024523244 | CG26: 0.089636252 | CH26: 0.070992733 | CI26: 0.027170643 | CJ26: 0.052468428 | CK26: 0.029480661 | CL26: 0.066825081 | CM26: -0.028772229 | CN26: 0.039462516 | CO26: -0.029031087 | CP26: 0.013983883 | CQ26: -0.032276965 | CR26: 0.0031035766 | CS26: 0.025591856 | CT26: 0.044391886 | CU26: -0.030338959 | CV26: -0.0012579765 | CW26: 0.0023363565 | CX26: -0.064264145 | CY26: 0.012909779 | CZ26: -0.12547709 | DA26: 0.011690683 | DB26: 0.0063378437 | DC26: -0.11730536 | DD26: -0.036010872 | DE26: 0.1389113 | DF26: -0.051143506 | DG26: 0.076731447 | DH26: 0.015508782 | DI26: 0.023223774 | DJ26: -0.018372876 | DK26: 0.062199014 | DL26: 0.020098304 | DM26: 0.01349894 | DN26: -0.030252213 | DO26: -0.017022836 | DP26: -0.021788523 | DQ26: 0.085745625 | DR26: 0.028106744 | DS26: -0.0023031598 | DT26: 0.058471198 | DU26: 0.067658949 | DV26: 0.0050207706 | DW26: 0.037416184 | DX26: 0.084111004 | DY26: -0.036832399 | DZ26: 0.0030917028 | EA26: -0.0019576282 | EB26: 0.026459104 | EC26: -0.024752539 | ED26: 0.034115491 | EE26: 0.021061974 | EF26: -0.020277393
B28: 低 | C28: 2540 | D28: 5455 | E28: 2540 | F28: 8097 | G28: 5455 | H28: 5455 | I28: 6114 | J28: 5455 | K28: 6291 | L28: 5455 | M28: 5455 | N28: 5455 | O28: 5455 | P28: 5455 | Q28: 6291 | R28: 6291 | S28: 5455 | T28: 6291 | U28: 6291 | V28: 6291 | W28: 6291 | X28: 6225 | Y28: 6291 | Z28: 6291 | AA28: 6291 | AB28: 6291 | AC28: 6291 | AD28: 6291 | AE28: 6225 | AF28: 6291 | AG28: 6291 | AH28: 6291 | AI28: 6291 | AJ28: 6291 | AK28: 6291 | AL28: 6225 | AM28: 6291 | AN28: 6225 | AO28: 6291 | AP28: 6225 | AQ28: 6291 | AR28: 6291 | AS28: 6225 | AT28: 6225 | AU28: 6225 | AV28: 6225 | AW28: 3043 | AX28: 3043 | AY28: 6225 | AZ28: 6225 | BA28: 6225 | BB28: 6225 | BC28: 6225 | BD28: 6225 | BE28: 6225 | BF28: 6225 | BG28: 6225 | BH28: 6225 | BI28: 6225 | BJ28: 6225 | BK28: 6225 | BL28: 6225 | BM28: 6225 | BN28: 6225 | BO28: 6225 | BP28: 6225 | BQ28: 6225 | BR28: 6225 | BS28: 6225 | BT28: 6225 | BU28: 8080 | BV28: 6225 | BW28: 5205 | BX28: 8080 | BY28: 8080 | BZ28: 8080 | CA28: 8080 | CB28: 8080 | CC28: 5205 | CD28: 5205 | CE28: 5205 | CF28: 5205 | CG28: 5205 | CH28: 5205 | CI28: 5205 | CJ28: 8080 | CK28: 8080 | CL28: 8080 | CM28: 5205 | CN28: 6287 | CO28: 6287 | CP28: 6287 | CQ28: 6287 | CR28: 6287 | CS28: 6287 | CT28: 6287 | CU28: 8101 | CV28: 8101 | CW28: 8101 | CX28: 8101 | CY28: 8101 | CZ28: 8101 | DA28: 6225 | DB28: 6225 | DC28: 6225 | DD28: 6225 | DE28: 6225 | DF28: 3064 | DG28: 6225 | DH28: 6225 | DI28: 6225 | DJ28: 6225 | DK28: 6225 | DL28: 6225 | DM28: 8084 | DN28: 8084 | DO28: 1519 | DP28: 1519 | DQ28: 8084 | DR28: 4419 | DS28: 4419 | DT28: 4419 | DU28: 4419 | DV28: 4419 | DW28: 4419 | DX28: 4419 | DY28: 1519 | DZ28: 1519 | EA28: 1519 | EB28: 1519 | EC28: 6287 | ED28: 6287 | EE28: 5314 | EF28: 5314
B29: 公司名稱 | C29: 愛山林 | D29: 昇益 | E29: 愛山林 | F29: 常珵 | G29: 昇益 | H29: 昇益 | I29: 久威 | J29: 昇益 | K29: 沛亨 | L29: 昇益 | M29: 昇益 | N29: 昇益 | O29: 昇益 | P29: 昇益 | Q29: 沛亨 | R29: 沛亨 | S29: 昇益 | T29: 沛亨 | U29: 沛亨 | V29: 沛亨 | W29: 沛亨 | X29: 天瀚 | Y29: 沛亨 | Z29: 沛亨 | AA29: 沛亨 | AB29: 沛亨 | AC29: 沛亨 | AD29: 沛亨 | AE29: 天瀚 | AF29: 沛亨 | AG29: 沛亨 | AH29: 沛亨 | AI29: 沛亨 | AJ29: 沛亨 | AK29: 沛亨 | AL29: 天瀚 | AM29: 沛亨 | AN29: 天瀚 | AO29: 沛亨 | AP29: 天瀚 | AQ29: 沛亨 | AR29: 沛亨 | AS29: 天瀚 | AT29: 天瀚 | AU29: 天瀚 | AV29: 天瀚 | AW29: 科風 | AX29: 科風 | AY29: 天瀚 | AZ29: 天瀚 | BA29: 天瀚 | BB29: 天瀚 | BC29: 天瀚 | BD29: 天瀚 | BE29: 天瀚 | BF29: 天瀚 | BG29: 天瀚 | BH29: 天瀚 | BI29: 天瀚 | BJ29: 天瀚 | BK29: 天瀚 | BL29: 天瀚 | BM29: 天瀚 | BN29: 天瀚 | BO29: 天瀚 | BP29: 天瀚 | BQ29: 天瀚 | BR29: 天瀚 | BS29: 天瀚 | BT29: 天瀚 | BU29: 印鉐 | BV29: 天瀚 | BW29: 中茂 | BX29: 印鉐 | BY29: 印鉐 | BZ29: 印鉐 | CA29: 印鉐 | CB29: 印鉐 | CC29: 中茂 | CD29: 中茂 | CE29: 中茂 | CF29: 中茂 | CG29: 中茂 | CH29: 中茂 | CI29: 中茂 | CJ29: 印鉐 | CK29: 印鉐 | CL29: 印鉐 | CM29: 中茂 | CN29: 元隆 | CO29: 元隆 | CP29: 元隆 | CQ29: 元隆 | CR29: 元隆 | CS29: 元隆 | CT29: 元隆 | CU29: 華冠 | CV29: 華冠 | CW29: 華冠 | CX29: 華冠 | CY29: 華冠 | CZ29: 華冠 | DA29: 天瀚 | DB29: 天瀚 | DC29: 天瀚 | DD29: 天瀚 | DE29: 天瀚 | DF29: 泰偉 | DG29: 天瀚 | DH29: 天瀚 | DI29: 天瀚 | DJ29: 天瀚 | DK29: 天瀚 | DL29: 天瀚 | DM29: 巨虹 | DN29: 巨虹 | DO29: 華城 | DP29: 華城 | DQ29: 巨虹 | DR29: 皇家美食 | DS29: 皇家美食 | DT29: 皇家美食 | DU29: 皇家美食 | DV29: 皇家美食 | DW29: 皇家美食 | DX29: 皇家美食 | DY29: 華城 | DZ29: 華城 | EA29: 華城 | EB29: 華城 | EC29: 元隆 | ED29: 元隆 | EE29: 世紀 | EF29: 世紀
B30: 高 | C30: 2492 | D30: 2330 | E30: 2323 | F30: 2330 | G30: 2330 | H30: 2330 | I30: 2323 | J30: 2330 | K30: 2330 | L30: 2330 | M30: 2330 | N30: 2330 | O30: 2330 | P30: 2323 | Q30: 2330 | R30: 2330 | S30: 2323 | T30: 2330 | U30: 2330 | V30: 2330 | W30: 2330 | X30: 2323 | Y30: 2330 | Z30: 2330 | AA30: 2330 | AB30: 2330 | AC30: 2330 | AD30: 2330 | AE30: 2323 | AF30: 2330 | AG30: 2330 | AH30: 2330 | AI30: 2330 | AJ30: 2330 | AK30: 2330 | AL30: 2323 | AM30: 2330 | AN30: 2323 | AO30: 2330 | AP30: 2323 | AQ30: 2330 | AR30: 2330 | AS30: 2323 | AT30: 2323 | AU30: 2323 | AV30: 2323 | AW30: 3252 | AX30: 3252 | AY30: 3252 | AZ30: 3252 | BA30: 3252 | BB30: 3252 | BC30: 3252 | BD30: 1906 | BE30: 1906 | BF30: 3252 | BG30: 1906 | BH30: 1906 | BI30: 1906 | BJ30: 1906 | BK30: 8085 | BL30: 8085 | BM30: 2201 | BN30: 8085 | BO30: 8085 | BP30: 8085 | BQ30: 3252 | BR30: 2409 | BS30: 3252 | BT30: 3311 | BU30: 3311 | BV30: 2321 | BW30: 3252 | BX30: 3252 | BY30: 3252 | BZ30: 5608 | CA30: 5608 | CB30: 5608 | CC30: 1314 | CD30: 1314 | CE30: 1314 | CF30: 1314 | CG30: 1314 | CH30: 1314 | CI30: 3252 | CJ30: 3252 | CK30: 3252 | CL30: 3252 | CM30: 3252 | CN30: 3252 | CO30: 3252 | CP30: 1906 | CQ30: 3252 | CR30: 3252 | CS30: 1906 | CT30: 1906 | CU30: 1906 | CV30: 1906 | CW30: 1906 | CX30: 1906 | CY30: 1906 | CZ30: 1906 | DA30: 1314 | DB30: 4414 | DC30: 1312 | DD30: 1906 | DE30: 2323 | DF30: 2323 | DG30: 2362 | DH30: 3252 | DI30: 2362 | DJ30: 2362 | DK30: 3252 | DL30: 1314 | DM30: 2603 | DN30: 2603 | DO30: 2603 | DP30: 2603 | DQ30: 1906 | DR30: 1906 | DS30: 1314 | DT30: 1314 | DU30: 1314 | DV30: 1314 | DW30: 1312 | DX30: 1314 | DY30: 1312 | DZ30: 1312 | EA30: 1312 | EB30: 1312 | EC30: 1314 | ED30: 1312 | EE30: 1312 | EF30: 1314
B31: 公司名稱 | C31: 華新科 | D31: 台積電 | E31: 中環 | F31: 台積電 | G31: 台積電 | H31: 台積電 | I31: 中環 | J31: 台積電 | K31: 台積電 | L31: 台積電 | M31: 台積電 | N31: 台積電 | O31: 台積電 | P31: 中環 | Q31: 台積電 | R31: 台積電 | S31: 中環 | T31: 台積電 | U31: 台積電 | V31: 台積電 | W31: 台積電 | X31: 中環 | Y31: 台積電 | Z31: 台積電 | AA31: 台積電 | AB31: 台積電 | AC31: 台積電 | AD31: 台積電 | AE31: 中環 | AF31: 台積電 | AG31: 台積電 | AH31: 台積電 | AI31: 台積電 | AJ31: 台積電 | AK31: 台積電 | AL31: 中環 | AM31: 台積電 | AN31: 中環 | AO31: 台積電 | AP31: 中環 | AQ31: 台積電 | AR31: 台積電 | AS31: 中環 | AT31: 中環 | AU31: 中環 | AV31: 中環 | AW31: 海灣 | AX31: 海灣 | AY31: 海灣 | AZ31: 海灣 | BA31: 海灣 | BB31: 海灣 | BC31: 海灣 | BD31: 寶隆 | BE31: 寶隆 | BF31: 海灣 | BG31: 寶隆 | BH31: 寶隆 | BI31: 寶隆 | BJ31: 寶隆 | BK31: 福華 | BL31: 福華 | BM31: 裕隆 | BN31: 福華 | BO31: 福華 | BP31: 福華 | BQ31: 海灣 | BR31: 友達 | BS31: 海灣 | BT31: 閎暉 | BU31: 閎暉 | BV31: 東訊 | BW31: 海灣 | BX31: 海灣 | BY31: 海灣 | BZ31: 四維航 | CA31: 四維航 | CB31: 四維航 | CC31: 中石化 | CD31: 中石化 | CE31: 中石化 | CF31: 中石化 | CG31: 中石化 | CH31: 中石化 | CI31: 海灣 | CJ31: 海灣 | CK31: 海灣 | CL31: 海灣 | CM31: 海灣 | CN31: 海灣 | CO31: 海灣 | CP31: 寶隆 | CQ31: 海灣 | CR31: 海灣 | CS31: 寶隆 | CT31: 寶隆 | CU31: 寶隆 | CV31: 寶隆 | CW31: 寶隆 | CX31: 寶隆 | CY31: 寶隆 | CZ31: 寶隆 | DA31: 中石化 | DB31: 如興 | DC31: 國喬 | DD31: 寶隆 | DE31: 中環 | DF31: 中環 | DG31: 藍天 | DH31: 海灣 | DI31: 藍天 | DJ31: 藍天 | DK31: 海灣 | DL31: 中石化 | DM31: 長榮 | DN31: 長榮 | DO31: 長榮 | DP31: 長榮 | DQ31: 寶隆 | DR31: 寶隆 | DS31: 中石化 | DT31: 中石化 | DU31: 中石化 | DV31: 中石化 | DW31: 國喬 | DX31: 中石化 | DY31: 國喬 | DZ31: 國喬 | EA31: 國喬 | EB31: 國喬 | EC31: 中石化 | ED31: 國喬 | EE31: 國喬 | EF31: 中石化

Sheet 勝率
A1: =預測IC!A1 -> NN4
B2: Time | C2: 2013/12 | D2: 2014/01 | E2: 2014/02 | F2: 2014/03 | G2: 2014/04 | H2: 2014/05 | I2: 2014/06 | J2: 2014/07 | K2: 2014/08 | L2: 2014/09 | M2: 2014/10 | N2: 2014/11 | O2: 2014/12 | P2: 2015/01 | Q2: 2015/02 | R2: 2015/03 | S2: 2015/04 | T2: 2015/05 | U2: 2015/06 | V2: 2015/07 | W2: 2015/08 | X2: 2015/09 | Y2: 2015/10 | Z2: 2015/11 | AA2: 2015/12 | AB2: 2016/01 | AC2: 2016/02 | AD2: 2016/03 | AE2: 2016/04 | AF2: 2016/05 | AG2: 2016/06 | AH2: 2016/07 | AI2: 2016/08 | AJ2: 2016/09 | AK2: 2016/10 | AL2: 2016/11 | AM2: 2016/12 | AN2: 2017/01 | AO2: 2017/02 | AP2: 2017/03 | AQ2: 2017/04 | AR2: 2017/05 | AS2: 2017/06 | AT2: 2017/07 | AU2: 2017/08 | AV2: 2017/09 | AW2: 2017/10 | AX2: 2017/11 | AY2: 2017/12 | AZ2: 2018/01 | BA2: 2018/02 | BB2: 2018/03 | BC2: 2018/04 | BD2: 2018/05 | BE2: 2018/06 | BF2: 2018/07 | BG2: 2018/08 | BH2: 2018/09 | BI2: 2018/10 | BJ2: 2018/11 | BK2: 2018/12 | BL2: 2019/01 | BM2: 2019/02 | BN2: 2019/03 | BO2: 2019/04 | BP2: 2019/05 | BQ2: 2019/06 | BR2: 2019/07 | BS2: 2019/08 | BT2: 2019/09 | BU2: 2019/10 | BV2: 2019/11 | BW2: 2019/12 | BX2: 2020/01 | BY2: 2020/02 | BZ2: 2020/03 | CA2: 2020/04 | CB2: 2020/05 | CC2: 2020/06 | CD2: 2020/07 | CE2: 2020/08 | CF2: 2020/09 | CG2: 2020/10 | CH2: 2020/11 | CI2: 2020/12 | CJ2: 2021/01 | CK2: 2021/02 | CL2: 2021/03 | CM2: 2021/04 | CN2: 2021/05 | CO2: 2021/06 | CP2: 2021/07 | CQ2: 2021/08 | CR2: 2021/09 | CS2: 2021/10 | CT2: 2021/11 | CU2: 2021/12 | CV2: 2022/01 | CW2: 2022/02 | CX2: 2022/03 | CY2: 2022/04 | CZ2: 2022/05 | DA2: 2022/06 | DB2: 2022/07 | DC2: 2022/08 | DD2: 2022/09 | DE2: 2022/10 | DF2: 2022/11 | DG2: 2022/12 | DH2: 2023/01 | DI2: 2023/02 | DJ2: 2023/03 | DK2: 2023/04 | DL2: 2023/05 | DM2: 2023/06 | DN2: 2023/07 | DO2: 2023/08 | DP2: 2023/09 | DQ2: 2023/10 | DR2: 2023/11 | DS2: 2023/12 | DT2: 2024/01 | DU2: 2024/02 | DV2: 2024/03 | DW2: 2024/04 | DX2: 2024/05 | DY2: 2024/06 | DZ2: 2024/07 | EA2: 2024/08 | EB2: 2024/09 | EC2: 2024/10 | ED2: 2024/11 | EE2: 2024/12 | EF2: 2025/01 | EG2: 2025/02
B3: bm | C3: =預測IC!C3 -> 0.053380694 | D3: =預測IC!D3 -> 0.025363307 | E3: =預測IC!E3 -> 0.037131086 | F3: =預測IC!F3 -> -0.015433895 | G3: =預測IC!G3 -> 0.038762547 | H3: =預測IC!H3 -> 0.018920034 | I3: =預測IC!I3 -> 0.03051983 | J3: =預測IC!J3 -> -0.007065095 | ... EF3: =預測IC!EF3 -> 0.050174937
