Workbook

Sheet 預測IC
A1: OLS
B2: Time | C2: 2013/12 | D2: 2014/01 | E2: 2014/02 | F2: 2014/03 | G2: 2014/04 | H2: 2014/05 | I2: 2014/06 | J2: 2014/07 | K2: 2014/08 | L2: 2014/09 | M2: 2014/10 | N2: 2014/11 | O2: 2014/12 | P2: 2015/01 | Q2: 2015/02 | R2: 2015/03 | S2: 2015/04 | T2: 2015/05 | U2: 2015/06 | V2: 2015/07 | W2: 2015/08 | X2: 2015/09 | Y2: 2015/10 | Z2: 2015/11 | AA2: 2015/12 | AB2: 2016/01 | AC2: 2016/02 | AD2: 2016/03 | AE2: 2016/04 | AF2: 2016/05 | AG2: 2016/06 | AH2: 2016/07 | AI2: 2016/08 | AJ2: 2016/09 | AK2: 2016/10 | AL2: 2016/11 | AM2: 2016/12 | AN2: 2017/01 | AO2: 2017/02 | AP2: 2017/03 | AQ2: 2017/04 | AR2: 2017/05 | AS2: 2017/06 | AT2: 2017/07 | AU2: 2017/08 | AV2: 2017/09 | AW2: 2017/10 | AX2: 2017/11 | AY2: 2017/12 | AZ2: 2018/01 | BA2: 2018/02 | BB2: 2018/03 | BC2: 2018/04 | BD2: 2018/05 | BE2: 2018/06 | BF2: 2018/07 | BG2: 2018/08 | BH2: 2018/09 | BI2: 2018/10 | BJ2: 2018/11 | BK2: 2018/12 | BL2: 2019/01 | BM2: 2019/02 | BN2: 2019/03 | BO2: 2019/04 | BP2: 2019/05 | BQ2: 2019/06 | BR2: 2019/07 | BS2: 2019/08 | BT2: 2019/09 | BU2: 2019/10 | BV2: 2019/11 | BW2: 2019/12 | BX2: 2020/01 | BY2: 2020/02 | BZ2: 2020/03 | CA2: 2020/04 | CB2: 2020/05 | CC2: 2020/06 | CD2: 2020/07 | CE2: 2020/08 | CF2: 2020/09 | CG2: 2020/10 | CH2: 2020/11 | CI2: 2020/12 | CJ2: 2021/01 | CK2: 2021/02 | CL2: 2021/03 | CM2: 2021/04 | CN2: 2021/05 | CO2: 2021/06 | CP2: 2021/07 | CQ2: 2021/08 | CR2: 2021/09 | CS2: 2021/10 | CT2: 2021/11 | CU2: 2021/12 | CV2: 2022/01 | CW2: 2022/02 | CX2: 2022/03 | CY2: 2022/04 | CZ2: 2022/05 | DA2: 2022/06 | DB2: 2022/07 | DC2: 2022/08 | DD2: 2022/09 | DE2: 2022/10 | DF2: 2022/11 | DG2: 2022/12 | DH2: 2023/01 | DI2: 2023/02 | DJ2: 2023/03 | DK2: 2023/04 | DL2: 2023/05 | DM2: 2023/06 | DN2: 2023/07 | DO2: 2023/08 | DP2: 2023/09 | DQ2: 2023/10 | DR2: 2023/11 | DS2: 2023/12 | DT2: 2024/01 | DU2: 2024/02 | DV2: 2024/03 | DW2: 2024/04 | DX2: 2024/05 | DY2: 2024/06 | DZ2: 2024/07 | EA2: 2024/08 | EB2: 2024/09 | EC2: 2024/10 | ED2: 2024/11 | EE2: 2024/12 | EF2: 2025/01
B3: bm | C3: 0.078798869 | D3: 0.17973309 | E3: 0.015489079 | F3: -0.022168251 | G3: -0.0081037288 | H3: -0.015401269 | I3: -0.19676559 | J3: 0.27883034 | K3: -0.0056931615 | L3: -0.047889749 | M3: -0.0052700848 | N3: -0.19106965 | O3: 0.31084678 | P3: 0.11377091 | Q3: -0.1230705 | R3: -0.11255849 | S3: 0.10466589 | T3: -0.14458477 | U3: -0.26280781 | V3: 0.0030188655 | W3: 0.1319604 | X3: -0.089415174 | Y3: 0.27906325 | Z3: 0.10308974 | AA3: 0.48637749 | AB3: -0.23481983 | AC3: 0.012096511 | AD3: 0.024631762 | AE3: -0.0056680955 | AF3: -0.056269213 | AG3: 0.12240493 | AH3: 0.043996775 | AI3: 0.16226839 | AJ3: 0.068930167 | AK3: 0.087359956 | AL3: 0.18738072 | AM3: 0.09683735 | AN3: 0.20757366 | AO3: 0.11797586 | AP3: -0.028503518 | AQ3: -0.21143964 | AR3: -0.032302566 | AS3: 0.14111009 | AT3: -0.034807512 | AU3: 0.044456114 | AV3: 0.021162739 | AW3: -0.174155 | AX3: 0.076317817 | AY3: 0.0090306432 | AZ3: 0.01663895 | BA3: 0.16049955 | BB3: -0.12374095 | BC3: 0.1567369 | BD3: 0.16688347 | BE3: -0.13147229 | BF3: 0.0099500133 | BG3: 0.31531124 | BH3: 0.27010118 | BI3: 0.056315449 | BJ3: -0.0024098169 | BK3: 0.079800376 | BL3: -0.023392394 | BM3: 0.09400894 | BN3: 0.017643906 | BO3: -0.14928794 | BP3: 0.041225941 | BQ3: -0.082741207 | BR3: 0.2134647 | BS3: -0.067985398 | BT3: 0.1443504 | BU3: 0.11377938 | BV3: 0.0056009583 | BW3: 0.11314664 | BX3: -0.090571157 | BY3: 0.11856974 | BZ3: -0.14071284 | CA3: 0.073472777 | CB3: -0.17102561 | CC3: 0.086731636 | CD3: 0.031267716 | CE3: 0.21879704 | CF3: -0.14159471 | CG3: 0.099731607 | CH3: 0.04530807 | CI3: 0.08944114 | CJ3: -0.39111281 | CK3: -0.10979117 | CL3: -0.043456184 | CM3: 0.18311247 | CN3: -0.39746168 | CO3: -0.096930226 | CP3: -0.09568205 | CQ3: 0.17197497 | CR3: 0.061939485 | CS3: -0.047664039 | CT3: -0.01047398 | CU3: -0.034400595 | CV3: -0.022584229 | CW3: 0.039676014 | CX3: -0.053904733 | CY3: 0.027221885 | CZ3: 0.098878435 | DA3: 0.31254073 | DB3: -0.15564613 | DC3: -0.18695853 | DD3: -0.16852286 | DE3: 0.16779761 | DF3: -0.091638386 | DG3: -0.075708963 | DH3: 0.0077960521 | DI3: -0.002550038 | DJ3: -0.068988363 | DK3: 0.046125319 | DL3: -0.0583377 | DM3: -0.070566062 | DN3: 0.028092871 | DO3: -0.070883392 | DP3: 0.1611314 | DQ3: 0.15474401 | DR3: -0.10742533 | DS3: 0.11284172 | DT3: -0.091401515 | DU3: -0.065441571 | DV3: -0.073758706 | DW3: 0.06615577 | DX3: 0.069417132 | DY3: -0.10299217 | DZ3: 0.2639134 | EA3: -0.089759101 | EB3: 0.19432477 | EC3: -0.03009712 | ED3: 0.028618295 | EE3: -0.087371805 | EF3: -0.020976445
B4: size | C4: -0.20332989 | D4: -0.19670615 | E4: -0.25411089 | F4: 0.046098133 | G4: 0.030705585 | H4: -0.050794665 | I4: 0.00077645993 | J4: 0.048875938 | K4: -0.10205313 | L4: -0.018648797 | M4: -0.055059353 | N4: -0.029805396 | O4: -0.18676846 | P4: 0.030016143 | Q4: 0.097885091 | R4: -0.093921518 | S4: 0.022808946 | T4: 0.073321485 | U4: 0.0074453756 | V4: -0.021623073 | W4: -0.005767973 | X4: -0.16986219 | Y4: -0.23417866 | Z4: -0.010182399 | AA4: -0.0031047646 | AB4: -0.16354737 | AC4: -0.065817326 | AD4: -0.053291002 | AE4: 0.044148085 | AF4: 0.081272613 | AG4: -0.10178725 | AH4: 0.11881082 | AI4: -0.086264025 | AJ4: -0.097080354 | AK4: 0.077483446 | AL4: 0.018676259 | AM4: -0.0073616058 | AN4: 0.011279679 | AO4: -0.044653673 | AP4: 0.080316784 | AQ4: -0.090654894 | AR4: 0.11489009 | AS4: 0.082303546 | AT4: 0.0092421254 | AU4: -0.03316186 | AV4: -0.21730532 | AW4: 0.052685656 | AX4: 0.013493886 | AY4: 0.10416615 | AZ4: 0.017139754 | BA4: -0.15393948 | BB4: -0.25209001 | BC4: -0.15090895 | BD4: -0.022569065 | BE4: -0.031980233 | BF4: 0.12360403 | BG4: -0.074229896 | BH4: -0.064502473 | BI4: 0.018247963 | BJ4: -0.15119856 | BK4: -0.057995346 | BL4: -0.046827852 | BM4: 0.020078087 | BN4: 0.041159851 | BO4: 0.044821747 | BP4: 0.083537286 | BQ4: 0.030584215 | BR4: -0.11513802 | BS4: -0.019945733 | BT4: -0.033400625 | BU4: -0.045048157 | BV4: 0.1729823 | BW4: -0.099199124 | BX4: -0.06836025 | BY4: -0.18303207 | BZ4: 0.085483425 | CA4: 0.0097162093 | CB4: 0.19814488 | CC4: -0.29368551 | CD4: -0.1324802 | CE4: -0.058262283 | CF4: -0.11406913 | CG4: 0.056736524 | CH4: -0.004729678 | CI4: 0.084443902 | CJ4: 0.027869588 | CK4: -0.022324698 | CL4: -0.068175763 | CM4: 0.040425863 | CN4: 0.18770362 | CO4: 0.0013964513 | CP4: 0.020238037 | CQ4: -0.030594997 | CR4: -0.28726341 | CS4: -0.27841973 | CT4: 0.082270681 | CU4: -0.1048555 | CV4: 0.11088352 | CW4: -0.050507103 | CX4: 0.059564972 | CY4: -0.17485207 | CZ4: -0.12999289 | DA4: -0.2206104 | DB4: -0.049769885 | DC4: -0.14288222 | DD4: 0.10063563 | DE4: 0.044473068 | DF4: 0.055744001 | DG4: -0.14018951 | DH4: 0.15742014 | DI4: -0.061975928 | DJ4: -0.12007759 | DK4: -0.16386028 | DL4: 0.094497365 | DM4: 0.23347888 | DN4: 0.074138937 | DO4: -0.044768182 | DP4: -0.0692689 | DQ4: -0.16944704 | DR4: -0.12923836 | DS4: -0.073029031 | DT4: -0.2035882 | DU4: -0.054890572 | DV4: 0.011078382 | DW4: -0.0045384064 | DX4: -0.084289001 | DY4: 0.10021882 | DZ4: -0.13097722 | EA4: -0.193158 | EB4: -0.31868387 | EC4: 0.049076536 | ED4: 0.052784729 | EE4: 0.12014486 | EF4: 0.2440528
B5: mom | C5: -0.20935792 | D5: -0.10736277 | E5: 0.52484761 | F5: 0.04683706 | G5: -0.21047143 | H5: 0.47441496 | I5: 0.14678499 | J5: -0.056231753 | K5: 0.27552846 | L5: -0.43004286 | M5: 0.32376775 | N5: -0.34824165 | O5: -0.097528912 | P5: 0.39546612 | Q5: 0.048467491 | R5: -0.098851332 | S5: 0.30579214 | T5: 0.072071946 | U5: -0.00047890409 | V5: -0.13936695 | W5: -0.39469013 | X5: -0.12947787 | Y5: -0.68127296 | Z5: -0.0041720387 | AA5: 0.018198047 | AB5: 0.20112166 | AC5: -0.089163225 | AD5: 0.14514146 | AE5: 0.074669148 | AF5: 0.17577042 | AG5: -0.30336041 | AH5: -0.34824991 | AI5: 0.25872372 | AJ5: -0.48889197 | AK5: 0.13254843 | AL5: -0.023789776 | AM5: 0.011752405 | AN5: -0.074933433 | AO5: 0.18446332 | AP5: 0.032348031 | AQ5: 0.15119843 | AR5: -0.09528311 | AS5: -0.12600437 | AT5: 0.15164479 | AU5: -0.20083705 | AV5: 0.078906368 | AW5: 0.00067935762 | AX5: 0.11229312 | AY5: -0.11805612 | AZ5: 0.20621977 | BA5: -0.039691919 | BB5: 0.08299594 | BC5: -0.13000543 | BD5: -0.10631616 | BE5: 0.1159334 | BF5: -0.28526227 | BG5: -0.15093334 | BH5: 0.0029199401 | BI5: 0.058126574 | BJ5: -0.25986983 | BK5: 0.18487945 | BL5: -0.26913173 | BM5: 0.17173819 | BN5: -0.18092216 | BO5: -0.063203738 | BP5: 0.0718675 | BQ5: -0.16861046 | BR5: -0.025447832 | BS5: 0.12442411 | BT5: 0.20772231 | BU5: -0.060051294 | BV5: -0.051700003 | BW5: -0.12680157 | BX5: -0.10582029 | BY5: 0.05360732 | BZ5: -0.034479447 | CA5: -0.020066211 | CB5: 0.084589607 | CC5: -0.11038366 | CD5: 0.32742329 | CE5: -0.014867197 | CF5: -0.14937325 | CG5: 0.16320028 | CH5: -0.069038325 | CI5: -0.11536215 | CJ5: -0.26301724 | CK5: 0.3789735 | CL5: -0.076383454 | CM5: 0.042833444 | CN5: -0.15161553 | CO5: 0.43716797 | CP5: -0.0041833928 | CQ5: -0.49935244 | CR5: 0.33985704 | CS5: -0.18988697 | CT5: 0.22461975 | CU5: -0.25171771 | CV5: -0.060587944 | CW5: 0.21087706 | CX5: 0.2501615 | CY5: -0.52413354 | CZ5: 0.82161831 | DA5: -0.17652298 | DB5: 0.13115958 | DC5: 0.17573665 | DD5: -0.42083892 | DE5: -0.22797242 | DF5: -0.33715974 | DG5: -0.4440037 | DH5: -0.042932794 | DI5: 0.30896916 | DJ5: -0.28669248 | DK5: 0.84621249 | DL5: -0.16924034 | DM5: -0.43945017 | DN5: 0.74751337 | DO5: -0.39996426 | DP5: -0.044863264 | DQ5: -0.5886343 | DR5: -0.0065627469 | DS5: -0.19878519 | DT5: 0.41321178 | DU5: -0.17065403 | DV5: 0.68828032 | DW5: 0.040806005 | DX5: -0.19993472 | DY5: 0.56631421 | DZ5: 0.4736288 | EA5: 0.095444978 | EB5: -1.0763609 | EC5: -0.13610629 | ED5: -0.27349656 | EE5: 0.60134859 | EF5: 0.0067468791
A6: 選絕對值最大 | C6: {=MATCH(MAX(ABS(C3:C5)),ABS(C3:C5),0)} -> 3 | D6: {=MATCH(MAX(ABS(D3:D5)),ABS(D3:D5),0)} -> 2 | E6: {=MATCH(MAX(ABS(E3:E5)),ABS(E3:E5),0)} -> 3 | F6: {=MATCH(MAX(ABS(F3:F5)),ABS(F3:F5),0)} -> 3 | G6: {=MATCH(MAX(ABS(G3:G5)),ABS(G3:G5),0)} -> 3 | H6: {=MATCH(MAX(ABS(H3:H5)),ABS(H3:H5),0)} -> 3 | I6: {=MATCH(MAX(ABS(I3:I5)),ABS(I3:I5),0)} -> 1 | J6: {=MATCH(MAX(ABS(J3:J5)),ABS(J3:J5),0)} -> 1 | ... EF6: {=MATCH(MAX(ABS(EF3:EF5)),ABS(EF3:EF5),0)} -> 2
C7: =IF(C6=1,"bm",IF(C6=2,"size",IF(C6=3,"mom"))) -> mom | D7: =IF(D6=1,"bm",IF(D6=2,"size",IF(D6=3,"mom"))) -> size | E7: =IF(E6=1,"bm",IF(E6=2,"size",IF(E6=3,"mom"))) -> mom | F7: =IF(F6=1,"bm",IF(F6=2,"size",IF(F6=3,"mom"))) -> mom | G7: =IF(G6=1,"bm",IF(G6=2,"size",IF(G6=3,"mom"))) -> mom | H7: =IF(H6=1,"bm",IF(H6=2,"size",IF(H6=3,"mom"))) -> mom | I7: =IF(I6=1,"bm",IF(I6=2,"size",IF(I6=3,"mom"))) -> bm | J7: =IF(J6=1,"bm",IF(J6=2,"size",IF(J6=3,"mom"))) -> bm | ... EF7: =IF(EF6=1,"bm",IF(EF6=2,"size",IF(EF6=3,"mom"))) -> size
C8: =IF(C6=1,C3,IF(C6=2,C4,IF(C6=3,C5))) -> -0.20935792 | D8: =IF(D6=1,D3,IF(D6=2,D4,IF(D6=3,D5))) -> -0.19670615 | E8: =IF(E6=1,E3,IF(E6=2,E4,IF(E6=3,E5))) -> 0.52484761 | F8: =IF(F6=1,F3,IF(F6=2,F4,IF(F6=3,F5))) -> 0.04683706 | G8: =IF(G6=1,G3,IF(G6=2,G4,IF(G6=3,G5))) -> -0.21047143 | H8: =IF(H6=1,H3,IF(H6=2,H4,IF(H6=3,H5))) -> 0.47441496 | I8: =IF(I6=1,I3,IF(I6=2,I4,IF(I6=3,I5))) -> -0.19676559 | J8: =IF(J6=1,J3,IF(J6=2,J4,IF(J6=3,J5))) -> 0.27883034 | ... EF8: =IF(EF6=1,EF3,IF(EF6=2,EF4,IF(EF6=3,EF5))) -> 0.2440528
A10: 投資組合 | C10: 公司數 | D10: 964
A11: 等第 | B11: 分數 | C11: 2014/01 | D11: 2014/02 | E11: 2014/03 | F11: 2014/04 | G11: 2014/05 | H11: 2014/06 | I11: 2014/07 | J11: 2014/08 | K11: 2014/09 | L11: 2014/10 | M11: 2014/11 | N11: 2014/12 | O11: 2015/01 | P11: 2015/02 | Q11: 2015/03 | R11: 2015/04 | S11: 2015/05 | T11: 2015/06 | U11: 2015/07 | V11: 2015/08 | W11: 2015/09 | X11: 2015/10 | Y11: 2015/11 | Z11: 2015/12 | AA11: 2016/01 | AB11: 2016/02 | AC11: 2016/03 | AD11: 2016/04 | AE11: 2016/05 | AF11: 2016/06 | AG11: 2016/07 | AH11: 2016/08 | AI11: 2016/09 | AJ11: 2016/10 | AK11: 2016/11 | AL11: 2016/12 | AM11: 2017/01 | AN11: 2017/02 | AO11: 2017/03 | AP11: 2017/04 | AQ11: 2017/05 | AR11: 2017/06 | AS11: 2017/07 | AT11: 2017/08 | AU11: 2017/09 | AV11: 2017/10 | AW11: 2017/11 | AX11: 2017/12 | AY11: 2018/01 | AZ11: 2018/02 | BA11: 2018/03 | BB11: 2018/04 | BC11: 2018/05 | BD11: 2018/06 | BE11: 2018/07 | BF11: 2018/08 | BG11: 2018/09 | BH11: 2018/10 | BI11: 2018/11 | BJ11: 2018/12 | BK11: 2019/01 | BL11: 2019/02 | BM11: 2019/03 | BN11: 2019/04 | BO11: 2019/05 | BP11: 2019/06 | BQ11: 2019/07 | BR11: 2019/08 | BS11: 2019/09 | BT11: 2019/10 | BU11: 2019/11 | BV11: 2019/12 | BW11: 2020/01 | BX11: 2020/02 | BY11: 2020/03 | BZ11: 2020/04 | CA11: 2020/05 | CB11: 2020/06 | CC11: 2020/07 | CD11: 2020/08 | CE11: 2020/09 | CF11: 2020/10 | CG11: 2020/11 | CH11: 2020/12 | CI11: 2021/01 | CJ11: 2021/02 | CK11: 2021/03 | CL11: 2021/04 | CM11: 2021/05 | CN11: 2021/06 | CO11: 2021/07 | CP11: 2021/08 | CQ11: 2021/09 | CR11: 2021/10 | CS11: 2021/11 | CT11: 2021/12 | CU11: 2022/01 | CV11: 2022/02 | CW11: 2022/03 | CX11: 2022/04 | CY11: 2022/05 | CZ11: 2022/06 | DA11: 2022/07 | DB11: 2022/08 | DC11: 2022/09 | DD11: 2022/10 | DE11: 2022/11 | DF11: 2022/12 | DG11: 2023/01 | DH11: 2023/02 | DI11: 2023/03 | DJ11: 2023/04 | DK11: 2023/05 | DL11: 2023/06 | DM11: 2023/07 | DN11: 2023/08 | DO11: 2023/09 | DP11: 2023/10 | DQ11: 2023/11 | DR11: 2023/12 | DS11: 2024/01 | DT11: 2024/02 | DU11: 2024/03 | DV11: 2024/04 | DW11: 2024/05 | DX11: 2024/06 | DY11: 2024/07 | DZ11: 2024/08 | EA11: 2024/09 | EB11: 2024/10 | EC11: 2024/11 | ED11: 2024/12 | EE11: 2025/01 | EF11: 2025/02
A12: 10 | B12: 96 | C12: 0.014499247 | D12: 0.11468851 | E12: -0.0013937245 | F12: -0.055959385 | G12: -0.031947449 | H12: 0.0095992584 | I12: -0.036303937 | J12: 0.043784579 | K12: 0.029187998 | L12: -0.008758556 | M12: 0.026889174 | N12: 0.034703354 | O12: 0.018629889 | P12: -0.00025432811 | Q12: 0.033792784 | R12: -0.013397506 | S12: 0.01105503 | T12: 0.043243489 | U12: 0.020367221 | V12: -0.0095109537 | W12: 0.028417663 | X12: 0.02707374 | Y12: -0.020598394 | Z12: 0.063623683 | AA12: -0.039403661 | AB12: -0.034689111 | AC12: 0.046772946 | AD12: -0.0025304298 | AE12: 0.046437717 | AF12: -0.052012103 | AG12: 0.0038149304 | AH12: 0.015713034 | AI12: 0.0087937925 | AJ12: 0.018723296 | AK12: -0.016475368 | AL12: 0.017859003 | AM12: 0.030086116 | AN12: 0.069233234 | AO12: 0.014995471 | AP12: 0.0046336667 | AQ12: 0.0076219364 | AR12: 0.0075043646 | AS12: 0.019099718 | AT12: 0.072195382 | AU12: -0.0037135364 | AV12: -0.021789896 | AW12: -0.00062147702 | AX12: -0.044696012 | AY12: -0.017491322 | AZ12: -0.023614553 | BA12: 0.0049378882 | BB12: 0.0057850729 | BC12: 0.012272789 | BD12: 0.013630557 | BE12: -0.01860881 | BF12: 0.067616949 | BG12: 0.033670862 | BH12: 0.01422336 | BI12: -0.043756064 | BJ12: 0.024663126 | BK12: -0.0006573835 | BL12: 0.032129098 | BM12: 0.050305685 | BN12: 0.011575967 | BO12: -0.02424631 | BP12: 0.0264225 | BQ12: 0.018715509 | BR12: -0.0022610085 | BS12: -0.032642855 | BT12: 0.016364783 | BU12: 0.0087815171 | BV12: -0.032053312 | BW12: 0.044477004 | BX12: 0.0069851539 | BY12: -0.045816958 | BZ12: -0.045356946 | CA12: -0.034400287 | CB12: -0.072475719 | CC12: 0.065566042 | CD12: -0.044355263 | CE12: 0.011619408 | CF12: -0.0080212745 | CG12: -0.04927796 | CH12: 0.016463112 | CI12: 0.035598031 | CJ12: -0.01544518 | CK12: 0.056101441 | CL12: -0.07844028 | CM12: -0.015219726 | CN12: 0.027083701 | CO12: -0.024819785 | CP12: -0.045299021 | CQ12: 0.062684347 | CR12: -0.057159987 | CS12: -0.014509312 | CT12: -0.0093290632 | CU12: 0.074779529 | CV12: -0.0044034271 | CW12: 0.013036669 | CX12: -0.030752638 | CY12: -0.016420596 | CZ12: -0.012324262 | DA12: 0.0056037841 | DB12: 0.022981876 | DC12: -0.033973203 | DD12: 0.069960546 | DE12: 0.024737644 | DF12: -0.01162432 | DG12: 0.047394422 | DH12: -0.061195427 | DI12: 0.029979255 | DJ12: -0.041378043 | DK12: 0.0010711986 | DL12: -0.018669833 | DM12: -0.0091434933 | DN12: -0.018541443 | DO12: 0.019030728 | DP12: 0.03258445 | DQ12: -0.074540647 | DR12: 0.017065 | DS12: -0.046024279 | DT12: 0.024813842 | DU12: -0.045787142 | DV12: -0.016751442 | DW12: 0.043725564 | DX12: -0.018099137 | DY12: 0.062728222 | DZ12: 0.02003889 | EA12: 0.051097698 | EB12: 0.030525777 | EC12: -0.014883918 | ED12: -0.023444575 | EE12: -0.02821628 | EF12: -0.029233396
A13: 20 | B13: 48 | C13: -0.0074773642 | D13: 0.1237451 | E13: -0.0055236267 | F13: -0.059986527 | G13: -0.012047404 | H13: 0.017388387 | I13: -0.032682863 | J13: 0.034549892 | K13: 0.060326139 | L13: -0.02198047 | M13: 0.0032797582 | N13: 0.043392417 | O13: 0.036273276 | P13: -0.0062776477 | Q13: 0.044218264 | R13: -0.0064899102 | S13: -0.006013803 | T13: 0.052899803 | U13: 0.054161075 | V13: -0.0022166399 | W13: 0.030968904 | X13: 0.053276458 | Y13: 0.0066833587 | Z13: 0.078424435 | AA13: -0.03211951 | AB13: -0.04667822 | AC13: 0.0667717 | AD13: -0.020440228 | AE13: 0.077071417 | AF13: -0.073281161 | AG13: -0.0099052077 | AH13: 0.024955207 | AI13: 0.018646046 | AJ13: 0.0017074508 | AK13: -0.03835939 | AL13: 0.023151429 | AM13: 0.046282444 | AN13: 0.10533024 | AO13: -0.0017088467 | AP13: 0.0065878125 | AQ13: 0.0060492888 | AR13: -0.0092504167 | AS13: 0.041313118 | AT13: 0.086422915 | AU13: 0.015695418 | AV13: -0.010958812 | AW13: -0.0040800136 | AX13: -0.032799832 | AY13: -0.014262204 | AZ13: -0.031220536 | BA13: 0.0065409376 | BB13: 0.026045979 | BC13: 0.011283767 | BD13: 0.0033444284 | BE13: -0.027391806 | BF13: 0.12165714 | BG13: 0.046566462 | BH13: 0.0084757298 | BI13: -0.021601559 | BJ13: 0.024266088 | BK13: -0.0088783959 | BL13: 0.03446004 | BM13: 0.053371769 | BN13: 0.035552713 | BO13: -0.030878716 | BP13: 0.0079520417 | BQ13: -0.0011508192 | BR13: -0.0066814175 | BS13: -0.040180514 | BT13: 0.00052107168 | BU13: 0.017706555 | BV13: -0.031440229 | BW13: 0.075714006 | BX13: 0.00074563881 | BY13: -0.030828583 | BZ13: -0.076138123 | CA13: -0.033531566 | CB13: -0.12042692 | CC13: 0.12011792 | CD13: -0.021204144 | CE13: 0.0092209843 | CF13: 0.012043667 | CG13: -0.058014968 | CH13: 0.0040295061 | CI13: 0.014533303 | CJ13: 0.003106088 | CK13: 0.065687126 | CL13: -0.072724175 | CM13: -0.010296804 | CN13: 0.026887566 | CO13: -0.035334344 | CP13: -0.06972654 | CQ13: 0.071178865 | CR13: -0.11164489 | CS13: 0.0039479583 | CT13: 0.00040854012 | CU13: 0.10709096 | CV13: -0.024319187 | CW13: 0.03630912 | CX13: -0.030582841 | CY13: -0.041201752 | CZ13: -0.0048982162 | DA13: -0.0055836769 | DB13: 0.04176157 | DC13: -0.029775566 | DD13: 0.068977059 | DE13: 0.022441996 | DF13: -0.017271632 | DG13: 0.07133576 | DH13: -0.088720708 | DI13: 0.02957042 | DJ13: -0.0070211236 | DK13: -0.023400892 | DL13: -0.022050691 | DM13: 0.011655894 | DN13: -0.012775889 | DO13: 0.044325139 | DP13: 0.048786636 | DQ13: -0.087129011 | DR13: 0.015168812 | DS13: -0.029915194 | DT13: 0.029845809 | DU13: -0.023698854 | DV13: -0.0098528048 | DW13: 0.04441779 | DX13: -0.02322961 | DY13: 0.0095046248 | DZ13: 0.030285251 | EA13: 0.062118417 | EB13: 0.057205293 | EC13: -0.021984853 | ED13: -0.05397802 | EE13: -0.03586748 | EF13: -0.044513042
A14: 50 | B14: 19 | C14: -0.033228978 | D14: 0.22230879 | E14: -0.047920746 | F14: -0.060341905 | G14: -0.05365663 | H14: -0.011508261 | I14: -0.04378736 | J14: 0.023309972 | K14: 0.050827466 | L14: -0.056271085 | M14: -0.019021714 | N14: 0.057369427 | O14: 0.037475787 | P14: 0.006541421 | Q14: 0.12410387 | R14: 0.015941187 | S14: -0.024806746 | T14: 0.06984148 | U14: 0.10426666 | V14: 0.0524213 | W14: 0.047795003 | X14: 0.053581789 | Y14: 0.055190991 | Z14: 0.038511926 | AA14: -0.03945018 | AB14: -0.070769377 | AC14: -0.0030865623 | AD14: -0.069874592 | AE14: 0.11683692 | AF14: -0.096080095 | AG14: -0.025329295 | AH14: 0.080952184 | AI14: -0.035462644 | AJ14: -0.024505575 | AK14: -0.077475339 | AL14: 0.03796919 | AM14: 0.061242166 | AN14: 0.098594667 | AO14: -0.038044353 | AP14: -0.0070551579 | AQ14: 0.00036796774 | AR14: -0.018170474 | AS14: 0.085376986 | AT14: 0.07940348 | AU14: 0.057421613 | AV14: 0.0084268421 | AW14: 0.018362932 | AX14: -0.019370213 | AY14: -0.0016905718 | AZ14: -0.06107058 | BA14: 0.017621646 | BB14: 0.101898 | BC14: -0.009820999 | BD14: 0.043327782 | BE14: -0.043787063 | BF14: 0.15382926 | BG14: 0.041374264 | BH14: 0.0053427556 | BI14: 0.041031068 | BJ14: 0.068604196 | BK14: -0.03369142 | BL14: 0.059996896 | BM14: 0.046278325 | BN14: 0.02608796 | BO14: -0.033609046 | BP14: -0.050331684 | BQ14: -0.050884482 | BR14: -0.02792943 | BS14: -0.030332724 | BT14: -0.030726476 | BU14: -0.0088548354 | BV14: -0.041282211 | BW14: 0.13089751 | BX14: -0.014335295 | BY14: -0.080401 | BZ14: -0.060034057 | CA14: -0.024465266 | CB14: -0.16446579 | CC14: 0.12059521 | CD14: 0.032926387 | CE14: -0.072156719 | CF14: 0.04287741 | CG14: -0.057320664 | CH14: 0.04887967 | CI14: 0.014701612 | CJ14: 0.028667855 | CK14: 0.053792087 | CL14: -0.13734357 | CM14: 0.03204001 | CN14: 0.023026689 | CO14: -0.078763759 | CP14: -0.099809331 | CQ14: 0.0322279 | CR14: -0.20771971 | CS14: -0.0038151053 | CT14: -0.0096618863 | CU14: 0.101545 | CV14: -0.039399684 | CW14: 0.044763884 | CX14: -0.090639227 | CY14: -0.09636113 | CZ14: -0.0103014 | DA14: -0.024304289 | DB14: 0.023561073 | DC14: -0.023632609 | DD14: 0.079205352 | DE14: 0.062526924 | DF14: -0.064180408 | DG14: 0.087324806 | DH14: -0.058742579 | DI14: 0.040659135 | DJ14: -0.0087940294 | DK14: -0.077413284 | DL14: -0.040754872 | DM14: 0.032421917 | DN14: 0.044935741 | DO14: 0.070288549 | DP14: 0.043539716 | DQ14: -0.071172565 | DR14: 0.0077946316 | DS14: -0.089437754 | DT14: 0.0077542903 | DU14: -0.11891759 | DV14: -0.045153224 | DW14: 0.098344367 | DX14: -0.027689697 | DY14: 0.047660987 | DZ14: 0.021697589 | EA14: 0.10752553 | EB14: 0.078179831 | EC14: -0.043260018 | ED14: -0.078399264 | EE14: -0.042505739 | EF14: -0.025524211
A15: 100 | B15: 10 | C15: -0.036350225 | D15: 0.3727097 | E15: -0.095344605 | F15: 0.034921437 | G15: -0.034403921 | H15: -0.0012437261 | I15: -0.058431444 | J15: 0.049961465 | K15: 0.094514798 | L15: -0.081171061 | M15: -0.0021330164 | N15: 0.10979619 | O15: 0.073757344 | P15: 0.02189657 | Q15: 0.15553684 | R15: 0.05212969 | S15: 0.08548789 | T15: 0.066800125 | U15: 0.13696806 | V15: 0.11012701 | W15: 0.050671424 | X15: 0.0784365 | Y15: 0.052028798 | Z15: 0.046719972 | AA15: -0.054081147 | AB15: -0.083700173 | AC15: 0.0043176688 | AD15: -0.081713375 | AE15: 0.21179264 | AF15: -0.13772629 | AG15: -0.044324544 | AH15: 0.13296737 | AI15: -0.024849257 | AJ15: -0.033717922 | AK15: -0.069361451 | AL15: 0.044431662 | AM15: 0.055122622 | AN15: 0.10168871 | AO15: -0.05138452 | AP15: -0.0125822 | AQ15: 0.037367127 | AR15: -0.0245503 | AS15: 0.053821179 | AT15: 0.070989813 | AU15: 0.077174077 | AV15: 0.033225 | AW15: -0.015659939 | AX15: -0.081360566 | AY15: -0.029005659 | AZ15: -0.067846329 | BA15: 0.010613515 | BB15: 0.1087885 | BC15: 0.062155144 | BD15: 0.053043274 | BE15: -0.048442721 | BF15: 0.21087209 | BG15: 0.0024895387 | BH15: 0.034441845 | BI15: 0.021159114 | BJ15: 0.13011026 | BK15: 0.045604932 | BL15: 0.059755421 | BM15: 0.048219004 | BN15: 0.063720727 | BO15: -0.027734476 | BP15: -0.0516158 | BQ15: -0.043431253 | BR15: -0.050157429 | BS15: -0.011865911 | BT15: -0.059850936 | BU15: 0.01947642 | BV15: -0.0861801 | BW15: 0.29887899 | BX15: -0.053851569 | BY15: -0.0933389 | BZ15: -0.10290647 | CA15: -0.018592021 | CB15: -0.1310916 | CC15: 0.1736496 | CD15: -0.047114468 | CE15: -0.11651657 | CF15: 0.04134943 | CG15: -0.085886022 | CH15: 0.081342608 | CI15: -0.0025109388 | CJ15: 0.087044356 | CK15: 0.095640748 | CL15: -0.16165447 | CM15: 0.074631116 | CN15: 0.042634116 | CO15: -0.10697924 | CP15: -0.12753584 | CQ15: -0.02496336 | CR15: -0.18148893 | CS15: 0.0169124 | CT15: 0.0049416704 | CU15: 0.12404993 | CV15: -0.060444 | CW15: 0.026072091 | CX15: -0.15238778 | CY15: -0.092947904 | CZ15: -0.023763335 | DA15: -0.026375835 | DB15: 0.030226618 | DC15: -0.03507515 | DD15: 0.014506726 | DE15: 0.057163635 | DF15: 0.0060545263 | DG15: 0.11309156 | DH15: -0.1296235 | DI15: 0.054108319 | DJ15: -0.060023777 | DK15: -0.072188598 | DL15: 0.0003039932 | DM15: 0.039052117 | DN15: 0.081730712 | DO15: 0.034104416 | DP15: 0.023735602 | DQ15: -0.037038689 | DR15: -0.0220354 | DS15: -0.0095715425 | DT15: 0.05271879 | DU15: -0.18864064 | DV15: -0.046727729 | DW15: 0.025538627 | DX15: -0.02154567 | DY15: -0.083673635 | DZ15: 0.036596498 | EA15: 0.1091777 | EB15: 0.08808745 | EC15: -0.076157077 | ED15: -0.11066003 | EE15: -0.04934418 | EF15: -0.0296441
A16: 107 | B16: 9 | C16: -0.03943539 | D16: 0.40819544 | E16: -0.086704171 | F16: 0.078715472 | G16: -0.0081465507 | H16: -0.00064934946 | I16: -0.057530619 | J16: 0.046709926 | K16: 0.086420892 | L16: -0.085161604 | M16: -0.013987436 | N16: 0.1202425 | O16: 0.079826861 | P16: 0.0081881795 | Q16: 0.15790307 | R16: 0.048990978 | S16: 0.10985904 | T16: 0.06721906 | U16: 0.13006247 | V16: 0.075571486 | W16: 0.10163136 | X16: 0.073678333 | Y16: 0.050278834 | Z16: 0.043057931 | AA16: -0.043487636 | AB16: -0.074985042 | AC16: -0.012765448 | AD16: -0.053136056 | AE16: 0.20962824 | AF16: -0.14791561 | AG16: -0.04377616 | AH16: 0.14840163 | AI16: -0.033383256 | AJ16: -0.048120479 | AK16: -0.037433453 | AL16: 0.048688933 | AM16: 0.066076731 | AN16: 0.1064562 | AO16: -0.041090153 | AP16: -0.0052404444 | AQ16: 0.0384662 | AR16: -0.032492222 | AS16: 0.065068225 | AT16: 0.12256404 | AU16: 0.082090272 | AV16: 0.023608556 | AW16: -0.03925293 | AX16: -0.10062133 | AY16: -0.019601854 | AZ16: -0.088150182 | BA16: 0.014923105 | BB16: 0.132474 | BC16: 0.067121466 | BD16: 0.035936712 | BE16: -0.051410994 | BF16: 0.24778686 | BG16: 0.013473282 | BH16: -0.013775614 | BI16: 0.04898994 | BJ16: 0.096566804 | BK16: 0.051371625 | BL16: 0.061173599 | BM16: 0.039497985 | BN16: 0.06130475 | BO16: -0.02189036 | BP16: -0.057748889 | BQ16: -0.023690719 | BR16: -0.026296848 | BS16: -0.032006987 | BT16: -0.046660882 | BU16: 0.05776511 | BV16: -0.094510444 | BW16: 0.31797083 | BX16: -0.066559519 | BY16: -0.11899544 | BZ16: -0.11152585 | CA16: -0.02971439 | CB16: -0.139309 | CC16: 0.044386333 | CD16: -0.060988526 | CE16: -0.13259506 | CF16: 0.052800084 | CG16: -0.061727878 | CH16: 0.050448725 | CI16: -0.0042406681 | CJ16: 0.045523551 | CK16: 0.08842269 | CL16: -0.19674044 | CM16: 0.088988628 | CN16: 0.033057515 | CO16: -0.13464021 | CP16: -0.13663169 | CQ16: -0.02033378 | CR16: -0.18928653 | CS16: 0.021808222 | CT16: 0.025557378 | CU16: 0.1354717 | CV16: -0.059453444 | CW16: 0.047341659 | CX16: -0.16226598 | CY16: -0.081280638 | CZ16: -0.032724822 | DA16: -0.029804794 | DB16: 0.04271217 | DC16: -0.042942362 | DD16: 0.03174371 | DE16: 0.0345524 | DF16: 0.0026980136 | DG16: 0.12637192 | DH16: -0.13714944 | DI16: 0.045399498 | DJ16: -0.070955052 | DK16: -0.057685769 | DL16: 0.021872874 | DM16: 0.018910374 | DN16: 0.11588673 | DO16: 0.046563866 | DP16: 0.019841949 | DQ16: -0.047070156 | DR16: -0.011178333 | DS16: 0.010423024 | DT16: 0.059112975 | DU16: -0.19010824 | DV16: -0.045728317 | DW16: 0.04091773 | DX16: -0.021947728 | DY16: -0.094984864 | DZ16: 0.012649172 | EA16: 0.13979989 | EB16: 0.1006791 | EC16: -0.068501481 | ED16: -0.11469923 | EE16: -0.059240997 | EF16: -0.034548444
A17: 120 | B17: 8 | C17: -0.038913469 | D17: 0.43958837 | E17: -0.096671109 | F17: 0.080752164 | G17: -0.10538707 | H17: 0.0079428568 | I17: -0.11372503 | J17: 0.041858395 | K17: 0.10156008 | L17: -0.042234791 | M17: 0.014659142 | N17: 0.10927783 | O17: 0.10122677 | P17: 0.013382947 | Q17: 0.16180129 | R17: 0.052057609 | S17: 0.11905439 | T17: 0.071202015 | U17: 0.14127114 | V17: 0.097259656 | W17: 0.12866725 | X17: 0.10018637 | Y17: 0.073623131 | Z17: 0.053868489 | AA17: -0.03520979 | AB17: -0.084852063 | AC17: -0.020086255 | AD17: -0.049777375 | AE17: 0.2221227 | AF17: -0.12028632 | AG17: -0.062640142 | AH17: 0.14702489 | AI17: -0.057037976 | AJ17: -0.061612619 | AK17: -0.02937589 | AL17: 0.050724406 | AM17: 0.075369368 | AN17: 0.11328712 | AO17: -0.076694528 | AP17: -0.00375925 | AQ17: 0.060527137 | AR17: -0.034996625 | AS17: 0.056323562 | AT17: 0.12707179 | AU17: 0.11569961 | AV17: 0.027563375 | AW17: -0.008421888 | AX17: -0.097619105 | AY17: -0.015478046 | AZ17: -0.070494231 | BA17: 0.0098251791 | BB17: 0.15327075 | BC17: 0.083863195 | BD17: 0.022356482 | BE17: -0.077350242 | BF17: 0.14777683 | BG17: -0.035394236 | BH17: 0.013519461 | BI17: 0.0807384 | BJ17: 0.097868244 | BK17: 0.016751327 | BL17: 0.034152447 | BM17: 0.029059011 | BN17: 0.053470181 | BO17: -0.035179615 | BP17: -0.060636875 | BQ17: -0.025601716 | BR17: -0.0096463751 | BS17: -0.020906018 | BT17: -0.05265016 | BU17: 0.071127819 | BV17: -0.10664387 | BW17: 0.20833683 | BX17: -0.08264099 | BY17: -0.095862375 | BZ17: -0.12057816 | CA17: -0.027934832 | CB17: -0.14963338 | CC17: 0.0417585 | CD17: -0.076385115 | CE17: -0.17511625 | CF17: 0.058238797 | CG17: -0.074714989 | CH17: 0.032969072 | CI17: -0.0037017834 | CJ17: 0.050742321 | CK17: 0.083955848 | CL17: -0.1368391 | CM17: 0.13456934 | CN17: 0.026718061 | CO17: -0.13741288 | CP17: -0.14815927 | CQ17: 0.051907103 | CR17: -0.19640263 | CS17: 0.011546625 | CT17: 0.01733928 | CU17: 0.15535189 | CV17: -0.067891375 | CW17: 0.063393219 | CX17: -0.12500986 | CY17: -0.075608913 | CZ17: -0.031592684 | DA17: -0.043895859 | DB17: 0.034883011 | DC17: -0.043363469 | DD17: 0.029155421 | DE17: 0.024124863 | DF17: 0.015674445 | DG17: 0.12321247 | DH17: -0.16343337 | DI17: 0.035044536 | DJ17: -0.12892506 | DK17: -0.068118111 | DL17: 0.0039297317 | DM17: 0.037227476 | DN17: 0.10647996 | DO17: 0.065250544 | DP17: -0.016518508 | DQ17: -0.072654005 | DR17: -0.0257265 | DS17: 0.0065055362 | DT17: 0.059811935 | DU17: -0.1595551 | DV17: -0.045148836 | DW17: 0.048681483 | DX17: 0.02303518 | DY17: -0.12601054 | DZ17: -0.0047910532 | EA17: 0.16457237 | EB17: 0.10728533 | EC17: -0.12151202 | ED17: -0.10329067 | EE17: -0.0642787 | EF17: -0.04098475
A18: 137 | B18: 7 | C18: -0.059146798 | D18: 0.401884 | E18: -0.10047562 | F18: 0.11938296 | G18: -0.10831637 | H18: 0.0086222278 | I18: -0.13550018 | J18: 0.043411516 | K18: 0.13564789 | L18: -0.050758207 | M18: 0.029051464 | N18: 0.14120749 | O18: 0.10367049 | P18: 0.0083280859 | Q18: 0.18897542 | R18: 0.061492238 | S18: 0.14380523 | T18: 0.05424444 | U18: 0.13249502 | V18: 0.12139146 | W18: 0.16613483 | X18: 0.12712329 | Y18: 0.10387924 | Z18: 0.089234363 | AA18: -0.041705245 | AB18: -0.0846983 | AC18: 0.0013654205 | AD18: -0.072443789 | AE18: 0.25839135 | AF18: -0.15054364 | AG18: -0.08171998 | AH18: 0.1630685 | AI18: -0.08142375 | AJ18: -0.070867218 | AK18: -0.022832885 | AL18: 0.047527764 | AM18: 0.066643405 | AN18: 0.07929464 | AO18: 0.02458428 | AP18: -0.0020157143 | AQ18: 0.076230845 | AR18: -0.061694429 | AS18: 0.085826552 | AT18: 0.16638581 | AU18: 0.13889821 | AV18: 0.035058 | AW18: -0.024538034 | AX18: -0.12606434 | AY18: -0.030189359 | AZ18: -0.051646327 | BA18: 0.00063231092 | BB18: 0.16725729 | BC18: 0.083201573 | BD18: -0.024016272 | BE18: -0.068361213 | BF18: 0.16498649 | BG18: -0.016806241 | BH18: 0.020503853 | BI18: 0.075991094 | BJ18: 0.098533857 | BK18: 0.0009810839 | BL18: 0.055787881 | BM18: 0.028081356 | BN18: 0.042191589 | BO18: -0.020227496 | BP18: -0.062462 | BQ18: -0.086459691 | BR18: -0.0057481936 | BS18: -0.032873257 | BT18: -0.061545323 | BU18: 0.080677444 | BV18: -0.11550557 | BW18: 0.2183755 | BX18: -0.074580863 | BY18: -0.062688429 | BZ18: -0.15331999 | CA18: -0.016076544 | CB18: -0.10684629 | CC18: 0.10465971 | CD18: -0.12159522 | CE18: -0.17792636 | CF18: -0.043957743 | CG18: -0.091609256 | CH18: 0.045365649 | CI18: 0.11505931 | CJ18: 0.062313678 | CK18: 0.096058032 | CL18: -0.15291394 | CM18: 0.14364854 | CN18: 0.035086254 | CO18: -0.15059751 | CP18: -0.16283911 | CQ18: 0.038242676 | CR18: -0.19372241 | CS18: 0.028129286 | CT18: -0.016272494 | CU18: 0.14456482 | CV18: -0.062944429 | CW18: 0.066558574 | CX18: -0.15307569 | CY18: -0.093178384 | CZ18: -0.091459213 | DA18: -0.04738094 | DB18: 0.045735209 | DC18: -0.036408781 | DD18: 0.041014187 | DE18: 0.038420587 | DF18: 0.028071975 | DG18: 0.11821709 | DH18: -0.19240257 | DI18: 0.018613248 | DJ18: -0.14619608 | DK18: -0.05725059 | DL18: 0.0038302741 | DM18: 0.0052506787 | DN18: 0.12510868 | DO18: 0.030199017 | DP18: -0.020604686 | DQ18: -0.065749458 | DR18: -0.010451714 | DS18: 0.025385651 | DT18: 0.022601035 | DU18: -0.16258878 | DV18: -0.070527693 | DW18: 0.081908692 | DX18: 0.068177294 | DY18: -0.1657631 | DZ18: -0.043227855 | EA18: 0.19894729 | EB18: 0.10996435 | EC18: -0.14304023 | ED18: -0.082759101 | EE18: -0.05301504 | EF18: -0.063951857
A19: 160 | B19: 6 | C19: -0.07386193 | D19: 0.40752133 | E19: -0.14058368 | F19: 0.17768866 | G19: -0.096065972 | H19: -0.012068788 | I19: -0.13465433 | J19: 0.035429585 | K19: 0.23878941 | L19: -0.02032665 | M19: -0.043690236 | N19: 0.15184358 | O19: 0.092221383 | P19: 0.023513161 | Q19: 0.19716309 | R19: 0.090299091 | S19: 0.12269188 | T19: 0.027154278 | U19: 0.13569834 | V19: 0.09268832 | W19: 0.17473476 | X19: 0.12292367 | Y19: 0.10313024 | Z19: 0.091619111 | AA19: -0.041570185 | AB19: -0.10225361 | AC19: 0.014141543 | AD19: -0.023997457 | AE19: 0.30849286 | AF19: -0.16883058 | AG19: -0.041487103 | AH19: 0.20415629 | AI19: -0.047766353 | AJ19: -0.07720271 | AK19: -0.040581523 | AL19: 0.070270946 | AM19: 0.043106012 | AN19: 0.083568294 | AO19: 0.055890126 | AP19: -0.009713 | AQ19: 0.088252757 | AR19: -0.074616833 | AS19: 0.097796955 | AT19: 0.18459366 | AU19: 0.15301463 | AV19: 0.042677667 | AW19: -0.022356168 | AX19: -0.2241238 | AY19: -0.066273243 | AZ19: -0.11561153 | BA19: -0.034363884 | BB19: 0.20180183 | BC19: 0.064055486 | BD19: -0.0032343926 | BE19: -0.051131874 | BF19: 0.14180943 | BG19: -0.016343658 | BH19: 0.0020182017 | BI19: 0.10128423 | BJ19: 0.058912217 | BK19: -0.069519037 | BL19: 0.063164534 | BM19: 0.031786265 | BN19: 0.0721851 | BO19: -0.025728961 | BP19: -0.012408667 | BQ19: -0.10965313 | BR19: 0.006675246 | BS19: 0.0034999319 | BT19: -0.082323404 | BU19: 0.075936251 | BV19: -0.10008533 | BW19: 0.30745301 | BX19: -0.054830282 | BY19: -0.027678167 | BZ19: -0.068702125 | CA19: -0.029328755 | CB19: -0.1278385 | CC19: 0.022505667 | CD19: -0.14873191 | CE19: -0.19826583 | CF19: -0.079051525 | CG19: -0.057117625 | CH19: 0.042715044 | CI19: 0.11073421 | CJ19: 0.0619405 | CK19: 0.11879726 | CL19: -0.11534778 | CM19: 0.17534764 | CN19: 0.076932655 | CO19: -0.16614656 | CP19: -0.1590326 | CQ19: 0.032394608 | CR19: -0.17630672 | CS19: 0.043775667 | CT19: -0.027940637 | CU19: 0.14660754 | CV19: -0.0761435 | CW19: 0.060515879 | CX19: -0.14815029 | CY19: -0.10789212 | CZ19: -0.057499263 | DA19: -0.058223877 | DB19: 0.035720899 | DC19: 0.0351794 | DD19: 0.0062011253 | DE19: 0.033018415 | DF19: 0.021296342 | DG19: 0.1264908 | DH19: -0.22459133 | DI19: 0.058647033 | DJ19: -0.16525047 | DK19: -0.01598429 | DL19: 0.011982786 | DM19: -0.046097902 | DN19: 0.1739283 | DO19: 0.04870552 | DP19: 0.027838014 | DQ19: -0.080374172 | DR19: -0.017545333 | DS19: 0.044918963 | DT19: 0.0050332465 | DU19: -0.19451944 | DV19: -0.071593387 | DW19: 0.060609139 | DX19: 0.094614193 | DY19: -0.15211941 | DZ19: -0.079643568 | EA19: 0.23304767 | EB19: 0.10875351 | EC19: -0.1437742 | ED19: -0.080285258 | EE19: -0.022815886 | EF19: -0.07402
A20: 192 | B20: 5 | C20: 0.011241332 | D20: 0.3820258 | E20: -0.14612491 | F20: 0.20553126 | G20: -0.11718314 | H20: 0.011583026 | I20: -0.15814956 | J20: 0.034471259 | K20: 0.2147245 | L20: -0.0089997713 | M20: -0.077718228 | N20: 0.16814359 | O20: 0.099101484 | P20: 0.043138679 | Q20: 0.21672574 | R20: 0.10925306 | S20: 0.082562611 | T20: -0.015662911 | U20: 0.14864968 | V20: 0.1035176 | W20: 0.22644366 | X20: 0.150043 | Y20: 0.12896504 | Z20: 0.10561696 | AA20: -0.021594553 | AB20: -0.084759841 | AC20: 0.047248263 | AD20: -0.026987304 | AE20: 0.16122121 | AF20: -0.22349782 | AG20: -0.032163249 | AH20: 0.21664245 | AI20: -0.083279354 | AJ20: -0.060725685 | AK20: -0.0082485151 | AL20: 0.072893452 | AM20: 0.033095981 | AN20: 0.075470194 | AO20: 0.049108295 | AP20: -0.0126056 | AQ20: -0.027452485 | AR20: -0.0132892 | AS20: 0.11209581 | AT20: 0.23912375 | AU20: 0.14307264 | AV20: 0.0714744 | AW20: -0.0068652682 | AX20: -0.20433922 | AY20: 0.082057636 | AZ20: -0.15627401 | BA20: -0.036798865 | BB20: 0.2312134 | BC20: 0.070605568 | BD20: -0.053429813 | BE20: 0.0059467971 | BF20: 0.13797126 | BG20: -0.0069261427 | BH20: -0.071606447 | BI20: 0.11425567 | BJ20: 0.049139784 | BK20: -0.10259828 | BL20: 0.069859442 | BM20: 0.047468551 | BN20: 0.085664631 | BO20: 0.038461718 | BP20: 0.0072838 | BQ20: -0.10860027 | BR20: 0.012073632 | BS20: 0.032536198 | BT20: -0.096530501 | BU20: 0.098754949 | BV20: -0.1337098 | BW20: 0.35182955 | BX20: -0.057988018 | BY20: -0.0431878 | BZ20: -0.090271404 | CA20: -0.040102728 | CB20: -0.1264954 | CC20: 0.0129148 | CD20: -0.18885951 | CE20: -0.2439638 | CF20: -0.10578489 | CG20: -0.075970241 | CH20: 0.022195229 | CI20: 0.085208202 | CJ20: 0.12344032 | CK20: 0.080589624 | CL20: -0.14931315 | CM20: 0.18905117 | CN20: -0.022159411 | CO20: -0.2285182 | CP20: -0.19203121 | CQ20: 0.023118045 | CR20: -0.19548611 | CS20: 0.0222938 | CT20: -0.018076711 | CU20: 0.14672801 | CV20: -0.0970042 | CW20: 0.067903708 | CX20: -0.14515419 | CY20: -0.10096666 | CZ20: -0.013062634 | DA20: -0.047471893 | DB20: 0.05690271 | DC20: 0.049613069 | DD20: 0.0035971848 | DE20: 0.010418722 | DF20: 0.045499958 | DG20: 0.12407331 | DH20: -0.2782996 | DI20: 0.074248336 | DJ20: -0.13655809 | DK20: -0.020765658 | DL20: 0.019465373 | DM20: 0.042864774 | DN20: 0.18323473 | DO20: 0.049820855 | DP20: 0.0098305314 | DQ20: -0.057460182 | DR20: -0.0555578 | DS20: -0.069792758 | DT20: -0.029685339 | DU20: -0.27264433 | DV20: -0.10204218 | DW20: 0.069060204 | DX20: 0.097851218 | DY20: -0.18740183 | DZ20: 0.018115127 | EA20: 0.2936912 | EB20: 0.082407142 | EC20: -0.13100615 | ED20: -0.057827564 | EE20: -0.020017587 | EF20: -0.0858
A21: 241 | B21: 4 | C21: 0.010384834 | D21: 0.126389 | E21: -0.043717555 | F21: 0.18403858 | G21: -0.14384215 | H21: -0.037844077 | I21: -0.14725561 | J21: 0.060435326 | K21: 0.20688003 | L21: -0.057226167 | M21: -0.099684593 | N21: 0.13905068 | O21: 0.12978246 | P21: 0.039891723 | Q21: 0.25731007 | R21: 0.095575311 | S21: 0.20915948 | T21: 0.014040364 | U21: 0.086278418 | V21: 0.10537077 | W21: 0.32292055 | X21: 0.207801 | Y21: 0.092729224 | Z21: 0.11420399 | AA21: 0.019491044 | AB21: -0.12983958 | AC21: 0.018827737 | AD21: 0.025933276 | AE21: 0.12810498 | AF21: -0.29514426 | AG21: -0.011046572 | AH21: 0.24035126 | AI21: -0.067729681 | AJ21: -0.078941164 | AK21: 0.018318369 | AL21: 0.065379823 | AM21: 0.068535807 | AN21: 0.11195606 | AO21: 0.085567775 | AP21: -0.01894375 | AQ21: -0.076865507 | AR21: 0.04798825 | AS21: 0.064455869 | AT21: 0.26483826 | AU21: 0.06345533 | AV21: 0.05089925 | AW21: -0.00979103 | AX21: -0.2177183 | AY21: 0.065722295 | AZ21: -0.093059394 | BA21: -0.071032182 | BB21: 0.29451325 | BC21: 0.038321148 | BD21: -0.021750863 | BE21: -0.0063505334 | BF21: 0.19911722 | BG21: 0.036635189 | BH21: -0.076321363 | BI21: 0.15387465 | BJ21: 0.031982514 | BK21: -0.082973162 | BL21: 0.08734079 | BM21: 0.040795286 | BN21: 0.1882475 | BO21: 0.063857236 | BP21: -0.00418 | BQ21: -0.072890743 | BR21: 0.012323862 | BS21: 0.065741821 | BT21: -0.092952203 | BU21: 0.13549646 | BV21: -0.01924025 | BW21: 0.18446067 | BX21: -0.088379335 | BY21: -0.01491975 | BZ21: -0.047662929 | CA21: -0.060517603 | CB21: -0.20787025 | CC21: -0.0080195 | CD21: -0.15078839 | CE21: -0.39507594 | CF21: -0.11452616 | CG21: -0.085085335 | CH21: 0.15662644 | CI21: 0.073182727 | CJ21: 0.085627757 | CK21: 0.06715963 | CL21: -0.18743312 | CM21: 0.22550299 | CN21: -0.03053889 | CO21: -0.23779198 | CP21: -0.22270006 | CQ21: 0.022912194 | CR21: -0.23905997 | CS21: 0.03090725 | CT21: -0.086072557 | CU21: 0.15891662 | CV21: -0.13162775 | CW21: 0.038345517 | CX21: -0.15696885 | CY21: -0.15245231 | CZ21: -0.013847206 | DA21: 0.0011922565 | DB21: 0.051624434 | DC21: 0.045047559 | DD21: 0.0028187944 | DE21: 0.028977737 | DF21: 0.1488089 | DG21: 0.14818493 | DH21: -0.081437 | DI21: 0.090149203 | DJ21: -0.15660572 | DK21: -0.020966062 | DL21: 0.012736992 | DM21: -0.004254564 | DN21: 0.22029564 | DO21: -0.018558809 | DP21: 0.024266155 | DQ21: -0.070422699 | DR21: -0.05355675 | DS21: -0.084605434 | DT21: -0.0052151903 | DU21: -0.33980664 | DV21: -0.15489825 | DW21: 0.12824787 | DX21: 0.11682889 | DY21: -0.22566188 | DZ21: 0.17989102 | EA21: 0.26605775 | EB21: 0.026302194 | EC21: -0.14009402 | ED21: 0.1291552 | EE21: 0.010955945 | EF21: -0.0287945
A22: 321 | B22: 3 | C22: 0.025922327 | D22: 0.14242933 | E22: -0.022230412 | F22: 0.067831061 | G22: -0.10388436 | H22: -0.22980554 | I22: -0.12349317 | J22: 0.052598589 | K22: 0.24536591 | L22: -0.10748717 | M22: -0.074100059 | N22: 0.098030861 | O22: 0.14348035 | P22: 0.042858489 | Q22: 0.27677689 | R22: 0.036628434 | S22: 0.24705663 | T22: 0.020238612 | U22: 0.11059002 | V22: 0.057024135 | W22: 0.34619349 | X22: 0.257202 | Y22: 0.047938332 | Z22: 0.075548269 | AA22: 0.0070480169 | AB22: -0.13443621 | AC22: 0.085776461 | AD22: 0.018593749 | AE22: 0.13082384 | AF22: -0.42991677 | AG22: -0.010812101 | AH22: 0.24762225 | AI22: -0.067392901 | AJ22: -0.045866129 | AK22: 0.078575769 | AL22: 0.040340967 | AM22: 0.084088903 | AN22: 0.11113281 | AO22: 0.15815288 | AP22: -0.020493333 | AQ22: -0.079426117 | AR22: 0.067924667 | AS22: 0.082810439 | AT22: 0.017728371 | AU22: 0.1099146 | AV22: 0.059647667 | AW22: 0.030149389 | AX22: 0.009875186 | AY22: 0.098456276 | AZ22: -0.2274855 | BA22: -0.045598425 | BB22: 0.36955133 | BC22: -0.13083694 | BD22: -0.022174181 | BE22: -0.022216183 | BF22: 0.19910245 | BG22: 0.046279512 | BH22: -0.12796054 | BI22: 0.087318059 | BJ22: -0.010233975 | BK22: -0.020854755 | BL22: 0.13947139 | BM22: 0.0024304832 | BN22: -0.028518806 | BO22: 0.050484429 | BP22: -0.00054 | BQ22: -0.091228191 | BR22: 0.020813609 | BS22: 0.09704759 | BT22: 0.067143215 | BU22: 0.21294877 | BV22: -0.00068066667 | BW22: 0.13217179 | BX22: -0.15293737 | BY22: 0.032350333 | BZ22: -0.047257736 | CA22: -0.027490078 | CB22: -0.25474 | CC22: -0.125105 | CD22: -0.31577166 | CE22: -0.39338734 | CF22: -0.10077036 | CG22: -0.20708533 | CH22: 0.15360628 | CI22: 0.064617323 | CJ22: 0.10337951 | CK22: 0.11092354 | CL22: -0.094997012 | CM22: 0.320432 | CN22: 0.0085467718 | CO22: -0.18528576 | CP22: -0.25940856 | CQ22: 0.017159616 | CR22: -0.24677277 | CS22: 0.024439333 | CT22: -0.12609138 | CU22: 0.16735391 | CV22: -0.18304533 | CW22: 0.022884042 | CX22: -0.054293295 | CY22: -0.16243987 | CZ22: -0.0075872464 | DA22: -0.0039917539 | DB22: 0.058383507 | DC22: 0.020724784 | DD22: 0.031710169 | DE22: -0.017756504 | DF22: 0.097071706 | DG22: 0.088121411 | DH22: -0.081455333 | DI22: 0.081105544 | DJ22: -0.15369976 | DK22: -0.023346177 | DL22: 0.0032133307 | DM22: -0.042676549 | DN22: 0.30537503 | DO22: 0.023768668 | DP22: 0.010227258 | DQ22: -0.16540417 | DR22: -0.071236 | DS22: -0.12952384 | DT22: 0.027128754 | DU22: -0.37526887 | DV22: -0.15706237 | DW22: 0.078389724 | DX22: 0.16435212 | DY22: -0.31775437 | DZ22: 0.16562625 | EA22: 0.14035633 | EB22: 0.12976595 | EC22: 0.028428812 | ED22: 0.18368199 | EE22: 0.035899357 | EF22: -0.036592667
A23: 482 | B23: 2 | C23: 0.031325685 | D23: 0.254094 | E23: -0.015061588 | F23: 0.18239608 | G23: 0.026971569 | H23: -0.26281024 | I23: -0.14815203 | J23: -0.098162291 | K23: 0.14260758 | L23: -0.23244436 | M23: -0.25844992 | N23: 0.12680001 | O23: 0.20456438 | P23: 0.010683505 | Q23: -0.059568017 | R23: 0.056211143 | S23: 0.169295 | T23: 0.00037336921 | U23: 0.093757422 | V23: -0.063357011 | W23: 0.50391933 | X23: 0.194556 | Y23: 0.0075887634 | Z23: 0.033032515 | AA23: 0.006606292 | AB23: -0.06403978 | AC23: 0.1687548 | AD23: 0.0029952916 | AE23: 0.13721199 | AF23: -0.32465933 | AG23: 0.14589389 | AH23: -0.13564892 | AI23: -0.07545017 | AJ23: 0.016962455 | AK23: 0.091199224 | AL23: 0.13143171 | AM23: 0.007769489 | AN23: 0.2423147 | AO23: 0.09078248 | AP23: 0.1652665 | AQ23: -0.089424992 | AR23: 0.146136 | AS23: -0.014706888 | AT23: 0.1095059 | AU23: 0.20359589 | AV23: -0.096756 | AW23: 0.05202691 | AX23: 0.014812779 | AY23: 0.0581396 | AZ23: -0.31598452 | BA23: 0.0096467801 | BB23: 0.5668275 | BC23: -0.30082825 | BD23: 0.094830881 | BE23: 0.071430762 | BF23: 0.21000911 | BG23: 0.074761471 | BH23: -0.20348398 | BI23: 0.13821956 | BJ23: 0.058020214 | BK23: -0.0050098635 | BL23: 0.11436629 | BM23: -0.069495462 | BN23: -0.02660347 | BO23: -0.036524942 | BP23: -0.022474 | BQ23: -0.059356425 | BR23: 0.017844321 | BS23: 0.22056709 | BT23: 0.070189264 | BU23: 0.20568774 | BV23: 0.0170205 | BW23: 0.015362515 | BX23: -0.12421952 | BY23: 0.039936 | BZ23: -0.0076697624 | CA23: -0.0756532 | CB23: -0.3161675 | CC23: -0.084545 | CD23: -0.64074658 | CE23: -0.11662461 | CF23: -0.016160835 | CG23: -0.21663724 | CH23: 0.16212257 | CI23: 0.1352222 | CJ23: 0.019875368 | CK23: 0.071856391 | CL23: -0.16404946 | CM23: 0.38673295 | CN23: 0.053005178 | CO23: -0.26845098 | CP23: -0.31136074 | CQ23: -0.02470227 | CR23: -0.15099817 | CS23: 0.069015 | CT23: -0.032850224 | CU23: 0.20210388 | CV23: -0.2018495 | CW23: -0.024186288 | CX23: -0.061859993 | CY23: -0.28171083 | CZ23: 0.061281101 | DA23: -0.030982136 | DB23: 0.015955157 | DC23: -0.11919049 | DD23: 0.092798675 | DE23: -0.060085948 | DF23: 0.19137387 | DG23: 0.15297665 | DH23: -0.139228 | DI23: 0.18491271 | DJ23: -0.12003258 | DK23: -0.047749797 | DL23: -0.026242652 | DM23: 0.010710334 | DN23: 0.26497486 | DO23: -0.084670828 | DP23: 0.047088233 | DQ23: -0.24594611 | DR23: -0.1024255 | DS23: -0.24719455 | DT23: -0.022296457 | DU23: -0.52524171 | DV23: -0.1927414 | DW23: 0.14122823 | DX23: 0.17100279 | DY23: -0.26822193 | DZ23: 0.12933302 | EA23: -0.028757 | EB23: 0.24428466 | EC23: 0.12320494 | ED23: 0.19432328 | EE23: 0.069545558 | EF23: -0.093414
A24: 964 | B24: 1 | C24: 0.027766967 | D24: 0.10061 | E24: 0.081880335 | F24: 0.20154572 | G24: 0.022622389 | H24: -0.35082219 | I24: 0.0021119332 | J24: -0.099972193 | K24: 0.050444336 | L24: -0.33375944 | M24: -0.14681934 | N24: 0.10519171 | O24: 0.23530919 | P24: 0.077736486 | Q24: -0.060964962 | R24: 0.24569737 | S24: 0.1398838 | T24: -0.12369104 | U24: 0.14851867 | V24: -0.11654032 | W24: 0.64293353 | X24: -0.000899 | Y24: 0.02939884 | Z24: 0.10584233 | AA24: 0.013547768 | AB24: -0.19533962 | AC24: 0.40174733 | AD24: 0.059922147 | AE24: 0.19314179 | AF24: -0.49538941 | AG24: 0.38005539 | AH24: -0.30212276 | AI24: -0.15191167 | AJ24: 0.020112365 | AK24: 0.11317916 | AL24: -0.054676935 | AM24: -0.018919281 | AN24: 0.22118947 | AO24: 0.1029057 | AP24: 0.164485 | AQ24: -0.047076973 | AR24: 0.170833 | AS24: -0.027956077 | AT24: 0.15076898 | AU24: 0.22984102 | AV24: -0.019522 | AW24: -0.0049875415 | AX24: -0.11149134 | AY24: 0.26743574 | AZ24: -0.60989956 | BA24: -0.053794732 | BB24: 0.690776 | BC24: -0.80321601 | BD24: 0.18559522 | BE24: 0.046064354 | BF24: -0.064370421 | BG24: 0.026835966 | BH24: -0.38625534 | BI24: -0.028151632 | BJ24: -0.060567254 | BK24: -0.010019727 | BL24: 0.10610692 | BM24: 0.08478294 | BN24: -0.019890158 | BO24: 0.16110969 | BP24: 0.031793 | BQ24: 0.013857466 | BR24: 0.042356223 | BS24: 0.12162104 | BT24: 0.055799256 | BU24: 0.22832663 | BV24: 0.203307 | BW24: 0.15102745 | BX24: -0.05804337 | BY24: -0.29034 | BZ24: -0.2588929 | CA24: -0.11522168 | CB24: -0.639699 | CC24: -0.18247 | CD24: -0.69133197 | CE24: -0.21012144 | CF24: 0.043964634 | CG24: -0.51996897 | CH24: 0.21297288 | CI24: 0.29359964 | CJ24: -0.013109485 | CK24: 0.32305927 | CL24: -0.015683748 | CM24: 0.54958711 | CN24: 0.10773877 | CO24: -0.57240961 | CP24: -0.1603442 | CQ24: -0.16018965 | CR24: -0.13778746 | CS24: -0.026858 | CT24: 0.18289659 | CU24: 0.052729045 | CV24: -0.361476 | CW24: -0.23499322 | CX24: -0.14669463 | CY24: -0.36022805 | CZ24: 0.16210691 | DA24: 0.024511204 | DB24: 0.19546067 | DC24: -0.19117576 | DD24: -0.19584472 | DE24: 0.13158559 | DF24: 0.19463806 | DG24: 0.24858898 | DH24: -0.265805 | DI24: 0.4230988 | DJ24: -0.22936987 | DK24: -0.16602173 | DL24: -0.061360513 | DM24: 0.1083161 | DN24: 0.51684794 | DO24: -0.08311429 | DP24: 0.11437343 | DQ24: -0.3590713 | DR24: -0.023392 | DS24: -0.14400697 | DT24: -0.029435726 | DU24: -0.77054331 | DV24: -0.75045655 | DW24: 0.10885709 | DX24: 0.17373733 | DY24: -0.032066536 | DZ24: -0.048904664 | EA24: -0.054917 | EB24: 0.58969792 | EC24: 0.25665138 | ED24: 0.084540093 | EE24: -0.035663983 | EF24: -0.134085
A26: 大盤 | B26: TWII | C26: -0.017446771 | D26: 0.020701061 | E26: 0.023982129 | F26: -0.006557579 | G26: 0.03184513 | H26: 0.034348533 | I26: -0.0082549328 | J26: 0.012843524 | K26: -0.051018525 | L26: 0.00087394274 | M26: 0.023389576 | N26: 0.012988972 | O26: 0.0058545887 | P26: 0.027413207 | Q26: -0.0037129361 | R26: 0.024076614 | S26: -0.012190025 | T26: -0.039749578 | U26: -0.07315545 | V26: -0.05826023 | W26: 0.00077279757 | X26: 0.044591521 | Y26: -0.02769968 | Z26: 0.0020950059 | AA26: -0.023400551 | AB26: 0.032129371 | AC26: 0.038903273 | AD26: -0.042865382 | AE26: 0.018647195 | AF26: 0.015229768 | AG26: 0.036016604 | AH26: 0.0093546114 | AI26: 0.010748251 | AJ26: 0.013357754 | AK26: -0.0053327473 | AL26: 0.0013831358 | AM26: 0.020795928 | AN26: 0.031517702 | AO26: 0.0062417165 | AP26: 0.0061452617 | AQ26: 0.016946358 | AR26: 0.03468283 | AS26: 0.0030985886 | AT26: 0.015081347 | AU26: -0.019251209 | AV26: 0.038711513 | AW26: -0.021856951 | AX26: 0.0077743007 | AY26: 0.042397247 | AZ26: -0.026308975 | BA26: 0.0095717493 | BB26: -0.024249741 | BC26: 0.020163374 | BD26: -0.0035049988 | BE26: 0.020151935 | BF26: 0.00058133623 | BG26: -0.005219701 | BH26: -0.11587176 | BI26: 0.0087252257 | BJ26: -0.016377261 | BK26: 0.020840372 | BL26: 0.044975872 | BM26: 0.023954306 | BN26: 0.030239101 | BO26: -0.043725888 | BP26: 0.02188947 | BQ26: 0.0086274303 | BR26: -0.019192954 | BS26: 0.01973513 | BT26: 0.047694337 | BU26: 0.011454817 | BV26: 0.043228621 | BW26: -0.04274743 | BX26: -0.017811292 | BY26: -0.1511531 | BZ26: 0.124224 | CA26: -0.0045572538 | CB26: 0.06021124 | CC26: 0.085992033 | CD26: -0.0058084796 | CE26: -0.006041347 | CF26: 0.0024523244 | CG26: 0.089636252 | CH26: 0.070992733 | CI26: 0.027170643 | CJ26: 0.052468428 | CK26: 0.029480661 | CL26: 0.066825081 | CM26: -0.028772229 | CN26: 0.039462516 | CO26: -0.029031087 | CP26: 0.013983883 | CQ26: -0.032276965 | CR26: 0.0031035766 | CS26: 0.025591856 | CT26: 0.044391886 | CU26: -0.030338959 | CV26: -0.0012579765 | CW26: 0.0023363565 | CX26: -0.064264145 | CY26: 0.012909779 | CZ26: -0.12547709 | DA26: 0.011690683 | DB26: 0.0063378437 | DC26: -0.11730536 | DD26: -0.036010872 | DE26: 0.1389113 | DF26: -0.051143506 | DG26: 0.076731447 | DH26: 0.015508782 | DI26: 0.023223774 | DJ26: -0.018372876 | DK26: 0.062199014 | DL26: 0.020098304 | DM26: 0.01349894 | DN26: -0.030252213 | DO26: -0.017022836 | DP26: -0.021788523 | DQ26: 0.085745625 | DR26: 0.028106744 | DS26: -0.0023031598 | DT26: 0.058471198 | DU26: 0.067658949 | DV26: 0.0050207706 | DW26: 0.037416184 | DX26: 0.084111004 | DY26: -0.036832399 | DZ26: 0.0030917028 | EA26: -0.0019576282 | EB26: 0.026459104 | EC26: -0.024752539 | ED26: 0.034115491 | EE26: 0.021061974 | EF26: -0.020277393
B28: 低 | C28: 3043 | D28: 5455 | E28: 6130 | F28: 6130 | G28: 6130 | H28: 6130 | I28: 6114 | J28: 6242 | K28: 5324 | L28: 5324 | M28: 5324 | N28: 5324 | O28: 5455 | P28: 2388 | Q28: 5455 | R28: 5455 | S28: 2388 | T28: 5455 | U28: 4413 | V28: 2388 | W28: 2028 | X28: 6291 | Y28: 3232 | Z28: 6225 | AA28: 6225 | AB28: 6225 | AC28: 9906 | AD28: 9906 | AE28: 5381 | AF28: 5455 | AG28: 6259 | AH28: 6259 | AI28: 6259 | AJ28: 6259 | AK28: 6259 | AL28: 6225 | AM28: 6225 | AN28: 6225 | AO28: 6259 | AP28: 6291 | AQ28: 6225 | AR28: 6291 | AS28: 6225 | AT28: 3064 | AU28: 3064 | AV28: 6291 | AW28: 3043 | AX28: 3064 | AY28: 8044 | AZ28: 5386 | BA28: 6225 | BB28: 6291 | BC28: 6225 | BD28: 6225 | BE28: 6225 | BF28: 6165 | BG28: 6225 | BH28: 6225 | BI28: 4303 | BJ28: 1475 | BK28: 4303 | BL28: 4303 | BM28: 4303 | BN28: 4303 | BO28: 6225 | BP28: 1475 | BQ28: 4303 | BR28: 6225 | BS28: 3085 | BT28: 3085 | BU28: 8080 | BV28: 1475 | BW28: 3085 | BX28: 3064 | BY28: 1475 | BZ28: 8080 | CA28: 8080 | CB28: 5205 | CC28: 8087 | CD28: 5310 | CE28: 5205 | CF28: 8070 | CG28: 8070 | CH28: 8070 | CI28: 8070 | CJ28: 8080 | CK28: 8070 | CL28: 8070 | CM28: 5205 | CN28: 6287 | CO28: 8070 | CP28: 6287 | CQ28: 1325 | CR28: 3043 | CS28: 5205 | CT28: 1325 | CU28: 3064 | CV28: 5205 | CW28: 6276 | CX28: 1325 | CY28: 6276 | CZ28: 6276 | DA28: 6225 | DB28: 6225 | DC28: 6225 | DD28: 2007 | DE28: 2486 | DF28: 2486 | DG28: 5475 | DH28: 1538 | DI28: 2615 | DJ28: 6104 | DK28: 6241 | DL28: 5468 | DM28: 9945 | DN28: 4402 | DO28: 4402 | DP28: 1519 | DQ28: 8933 | DR28: 5345 | DS28: 2615 | DT28: 8933 | DU28: 3085 | DV28: 3085 | DW28: 4419 | DX28: 2482 | DY28: 2482 | DZ28: 6291 | EA28: 2321 | EB28: 6235 | EC28: 9950 | ED28: 6291 | EE28: 6276 | EF28: 2321
B29: 公司名稱 | C29: 科風 | D29: 昇益 | E29: 上亞科技 | F29: 上亞科技 | G29: 上亞科技 | H29: 上亞科技 | I29: 久威 | J29: 立康 | K29: 士開 | L29: 士開 | M29: 士開 | N29: 士開 | O29: 昇益 | P29: 威盛 | Q29: 昇益 | R29: 昇益 | S29: 威盛 | T29: 昇益 | U29: 飛寶企業 | V29: 威盛 | W29: 威致 | X29: 沛亨 | Y29: 昱捷 | Z29: 天瀚 | AA29: 天瀚 | AB29: 天瀚 | AC29: 欣巴巴 | AD29: 欣巴巴 | AE29: 合正 | AF29: 昇益 | AG29: 百徽 | AH29: 百徽 | AI29: 百徽 | AJ29: 百徽 | AK29: 百徽 | AL29: 天瀚 | AM29: 天瀚 | AN29: 天瀚 | AO29: 百徽 | AP29: 沛亨 | AQ29: 天瀚 | AR29: 沛亨 | AS29: 天瀚 | AT29: 泰偉 | AU29: 泰偉 | AV29: 沛亨 | AW29: 科風 | AX29: 泰偉 | AY29: 網家 | AZ29: 青雲 | BA29: 天瀚 | BB29: 沛亨 | BC29: 天瀚 | BD29: 天瀚 | BE29: 天瀚 | BF29: 浪凡 | BG29: 天瀚 | BH29: 天瀚 | BI29: 信立 | BJ29: 業旺 | BK29: 信立 | BL29: 信立 | BM29: 信立 | BN29: 信立 | BO29: 天瀚 | BP29: 業旺 | BQ29: 信立 | BR29: 天瀚 | BS29: 新零售 | BT29: 新零售 | BU29: 印鉐 | BV29: 業旺 | BW29: 新零售 | BX29: 泰偉 | BY29: 業旺 | BZ29: 印鉐 | CA29: 印鉐 | CB29: 中茂 | CC29: 麗升能源 | CD29: 天剛 | CE29: 中茂 | CF29: 長華* | CG29: 長華* | CH29: 長華* | CI29: 長華* | CJ29: 印鉐 | CK29: 長華* | CL29: 長華* | CM29: 中茂 | CN29: 元隆 | CO29: 長華* | CP29: 元隆 | CQ29: 恒大 | CR29: 科風 | CS29: 中茂 | CT29: 恒大 | CU29: 泰偉 | CV29: 中茂 | CW29: 安鈦克 | CX29: 恒大 | CY29: 安鈦克 | CZ29: 安鈦克 | DA29: 天瀚 | DB29: 天瀚 | DC29: 天瀚 | DD29: 燁興 | DE29: 一詮 | DF29: 一詮 | DG29: 德宏 | DH29: 正峰 | DI29: 萬海 | DJ29: 創惟 | DK29: 易通展 | DL29: 凱鈺 | DM29: 潤泰新 | DN29: 郡都開發 | DO29: 郡都開發 | DP29: 華城 | DQ29: 愛地雅 | DR29: 天揚 | DS29: 萬海 | DT29: 愛地雅 | DU29: 新零售 | DV29: 新零售 | DW29: 皇家美食 | DX29: 連宇 | DY29: 連宇 | DZ29: 沛亨 | EA29: 東訊 | EB29: 華孚 | EC29: 萬國通 | ED29: 沛亨 | EE29: 安鈦克 | EF29: 東訊
B30: 高 | C30: 2540 | D30: 2330 | E30: 5364 | F30: 5364 | G30: 5364 | H30: 5364 | I30: 2323 | J30: 2323 | K30: 5364 | L30: 8941 | M30: 5364 | N30: 5364 | O30: 2323 | P30: 2408 | Q30: 2323 | R30: 2323 | S30: 2408 | T30: 2323 | U30: 2323 | V30: 2408 | W30: 5455 | X30: 2330 | Y30: 1449 | Z30: 2323 | AA30: 2323 | AB30: 2323 | AC30: 4502 | AD30: 4502 | AE30: 4502 | AF30: 4502 | AG30: 4502 | AH30: 4502 | AI30: 4502 | AJ30: 4502 | AK30: 2496 | AL30: 2323 | AM30: 2323 | AN30: 2323 | AO30: 6283 | AP30: 2330 | AQ30: 2323 | AR30: 2330 | AS30: 2323 | AT30: 2496 | AU30: 2496 | AV30: 2330 | AW30: 3252 | AX30: 2337 | AY30: 1475 | AZ30: 4303 | BA30: 3252 | BB30: 2330 | BC30: 1906 | BD30: 1906 | BE30: 1906 | BF30: 2342 | BG30: 1906 | BH30: 1906 | BI30: 3046 | BJ30: 3046 | BK30: 2388 | BL30: 1529 | BM30: 1529 | BN30: 1529 | BO30: 8085 | BP30: 2330 | BQ30: 1529 | BR30: 2409 | BS30: 1529 | BT30: 1529 | BU30: 3311 | BV30: 2330 | BW30: 5340 | BX30: 4702 | BY30: 2330 | BZ30: 5608 | CA30: 5608 | CB30: 2330 | CC30: 2330 | CD30: 1325 | CE30: 1314 | CF30: 1325 | CG30: 1325 | CH30: 1325 | CI30: 2321 | CJ30: 3252 | CK30: 6259 | CL30: 3086 | CM30: 3252 | CN30: 3252 | CO30: 2609 | CP30: 3252 | CQ30: 5475 | CR30: 2609 | CS30: 2330 | CT30: 5475 | CU30: 5475 | CV30: 2330 | CW30: 5475 | CX30: 5475 | CY30: 2364 | CZ30: 2364 | DA30: 1314 | DB30: 4414 | DC30: 1314 | DD30: 2364 | DE30: 2364 | DF30: 2364 | DG30: 2364 | DH30: 2330 | DI30: 3043 | DJ30: 3043 | DK30: 3043 | DL30: 3043 | DM30: 3043 | DN30: 3043 | DO30: 5314 | DP30: 2603 | DQ30: 5314 | DR30: 2330 | DS30: 8077 | DT30: 8077 | DU30: 5314 | DV30: 5314 | DW30: 1312 | DX30: 5314 | DY30: 5314 | DZ30: 5314 | EA30: 2330 | EB30: 6144 | EC30: 6144 | ED30: 3064 | EE30: 3064 | EF30: 2330
B31: 公司名稱 | C31: 愛山林 | D31: 台積電 | E31: 力麗店 | F31: 力麗店 | G31: 力麗店 | H31: 力麗店 | I31: 中環 | J31: 中環 | K31: 力麗店 | L31: 關中 | M31: 力麗店 | N31: 力麗店 | O31: 中環 | P31: 南亞科 | Q31: 中環 | R31: 中環 | S31: 南亞科 | T31: 中環 | U31: 中環 | V31: 南亞科 | W31: 昇益 | X31: 台積電 | Y31: 佳和 | Z31: 中環 | AA31: 中環 | AB31: 中環 | AC31: 健信 | AD31: 健信 | AE31: 健信 | AF31: 健信 | AG31: 健信 | AH31: 健信 | AI31: 健信 | AJ31: 健信 | AK31: 卓越 | AL31: 中環 | AM31: 中環 | AN31: 中環 | AO31: 淳安 | AP31: 台積電 | AQ31: 中環 | AR31: 台積電 | AS31: 中環 | AT31: 卓越 | AU31: 卓越 | AV31: 台積電 | AW31: 海灣 | AX31: 旺宏 | AY31: 業旺 | AZ31: 信立 | BA31: 海灣 | BB31: 台積電 | BC31: 寶隆 | BD31: 寶隆 | BE31: 寶隆 | BF31: 茂矽 | BG31: 寶隆 | BH31: 寶隆 | BI31: 建碁 | BJ31: 建碁 | BK31: 威盛 | BL31: 樂事綠能 | BM31: 樂事綠能 | BN31: 樂事綠能 | BO31: 福華 | BP31: 台積電 | BQ31: 樂事綠能 | BR31: 友達 | BS31: 樂事綠能 | BT31: 樂事綠能 | BU31: 閎暉 | BV31: 台積電 | BW31: 建榮 | BX31: 中美實 | BY31: 台積電 | BZ31: 四維航 | CA31: 四維航 | CB31: 台積電 | CC31: 台積電 | CD31: 恒大 | CE31: 中石化 | CF31: 恒大 | CG31: 恒大 | CH31: 恒大 | CI31: 東訊 | CJ31: 海灣 | CK31: 百徽 | CL31: 華義 | CM31: 海灣 | CN31: 海灣 | CO31: 陽明 | CP31: 海灣 | CQ31: 德宏 | CR31: 陽明 | CS31: 台積電 | CT31: 德宏 | CU31: 德宏 | CV31: 台積電 | CW31: 德宏 | CX31: 德宏 | CY31: 倫飛 | CZ31: 倫飛 | DA31: 中石化 | DB31: 如興 | DC31: 中石化 | DD31: 倫飛 | DE31: 倫飛 | DF31: 倫飛 | DG31: 倫飛 | DH31: 台積電 | DI31: 科風 | DJ31: 科風 | DK31: 科風 | DL31: 科風 | DM31: 科風 | DN31: 科風 | DO31: 世紀 | DP31: 長榮 | DQ31: 世紀 | DR31: 台積電 | DS31: 洛碁 | DT31: 洛碁 | DU31: 世紀 | DV31: 世紀 | DW31: 國喬 | DX31: 世紀 | DY31: 世紀 | DZ31: 世紀 | EA31: 台積電 | EB31: 得利影 | EC31: 得利影 | ED31: 泰偉 | EE31: 泰偉 | EF31: 台積電

Sheet 夏普比率
A1: OLS
B2: Time | C2: 2013/12 | D2: 2014/01 | E2: 2014/02 | F2: 2014/03 | G2: 2014/04 | H2: 2014/05 | I2: 2014/06 | J2: 2014/07 | K2: 2014/08 | L2: 2014/09 | M2: 2014/10 | N2: 2014/11 | O2: 2014/12 | P2: 2015/01 | Q2: 2015/02 | R2: 2015/03 | S2: 2015/04 | T2: 2015/05 | U2: 2015/06 | V2: 2015/07 | W2: 2015/08 | X2: 2015/09 | Y2: 2015/10 | Z2: 2015/11 | AA2: 2015/12 | AB2: 2016/01 | AC2: 2016/02 | AD2: 2016/03 | AE2: 2016/04 | AF2: 2016/05 | AG2: 2016/06 | AH2: 2016/07 | AI2: 2016/08 | AJ2: 2016/09 | AK2: 2016/10 | AL2: 2016/11 | AM2: 2016/12 | AN2: 2017/01 | AO2: 2017/02 | AP2: 2017/03 | AQ2: 2017/04 | AR2: 2017/05 | AS2: 2017/06 | AT2: 2017/07 | AU2: 2017/08 | AV2: 2017/09 | AW2: 2017/10 | AX2: 2017/11 | AY2: 2017/12 | AZ2: 2018/01 | BA2: 2018/02 | BB2: 2018/03 | BC2: 2018/04 | BD2: 2018/05 | BE2: 2018/06 | BF2: 2018/07 | BG2: 2018/08 | BH2: 2018/09 | BI2: 2018/10 | BJ2: 2018/11 | BK2: 2018/12 | BL2: 2019/01 | BM2: 2019/02 | BN2: 2019/03 | BO2: 2019/04 | BP2: 2019/05 | BQ2: 2019/06 | BR2: 2019/07 | BS2: 2019/08 | BT2: 2019/09 | BU2: 2019/10 | BV2: 2019/11 | BW2: 2019/12 | BX2: 2020/01 | BY2: 2020/02 | BZ2: 2020/03 | CA2: 2020/04 | CB2: 2020/05 | CC2: 2020/06 | CD2: 2020/07 | CE2: 2020/08 | CF2: 2020/09 | CG2: 2020/10 | CH2: 2020/11 | CI2: 2020/12 | CJ2: 2021/01 | CK2: 2021/02 | CL2: 2021/03 | CM2: 2021/04 | CN2: 2021/05 | CO2: 2021/06 | CP2: 2021/07 | CQ2: 2021/08 | CR2: 2021/09 | CS2: 2021/10 | CT2: 2021/11 | CU2: 2021/12 | CV2: 2022/01 | CW2: 2022/02 | CX2: 2022/03 | CY2: 2022/04 | CZ2: 2022/05 | DA2: 2022/06 | DB2: 2022/07 | DC2: 2022/08 | DD2: 2022/09 | DE2: 2022/10 | DF2: 2022/11 | DG2: 2022/12 | DH2: 2023/01 | DI2: 2023/02 | DJ2: 2023/03 | DK2: 2023/04 | DL2: 2023/05 | DM2: 2023/06 | DN2: 2023/07 | DO2: 2023/08 | DP2: 2023/09 | DQ2: 2023/10 | DR2: 2023/11 | DS2: 2023/12 | DT2: 2024/01 | DU2: 2024/02 | DV2: 2024/03 | DW2: 2024/04 | DX2: 2024/05 | DY2: 2024/06 | DZ2: 2024/07 | EA2: 2024/08 | EB2: 2024/09 | EC2: 2024/10 | ED2: 2024/11 | EE2: 2024/12 | EF2: 2025/01
